{"level":"ERROR","location":"[<lambda>:1663] data_ws","message":"Connection to remote host was lost.","timestamp":"2025-10-12 18:14:57,539+0530","service":"FyersDataSocket"}
{"level":"ERROR","location":"[<lambda>:1663] data_ws","message":"Connection to remote host was lost.","timestamp":"2025-10-12 20:41:17,572+0530","service":"FyersDataSocket"}
{"level":"ERROR","location":"[<lambda>:1663] data_ws","message":"[Errno 11001] getaddrinfo failed","timestamp":"2025-10-12 20:41:22,739+0530","service":"FyersDataSocket"}
{"level":"ERROR","location":"[symbol_to_hsmtoken:126] data_ws","message":"HTTPSConnectionPool(host='api-t1.fyers.in', port=443): Max retries exceeded with url: /data/symbol-token (Caused by NewConnectionError('<urllib3.connection.HTTPSConnection object at 0x000001F079A5B980>: Failed to establish a new connection: [Errno 11001] getaddrinfo failed'))","timestamp":"2025-10-12 21:09:10,648+0530","service":"FyersDataSocket","exception":"Traceback (most recent call last):\n  File \"E:\\paper\\paper\\venv\\Lib\\site-packages\\websocket\\_app.py\", line 428, in setSock\n    dispatcher.read(self.sock.sock, read, check)\n  File \"E:\\paper\\paper\\venv\\Lib\\site-packages\\websocket\\_app.py\", line 99, in read\n    if not read_callback():\n           ^^^^^^^^^^^^^^^\n  File \"E:\\paper\\paper\\venv\\Lib\\site-packages\\websocket\\_app.py\", line 442, in read\n    raise e\n  File \"E:\\paper\\paper\\venv\\Lib\\site-packages\\websocket\\_app.py\", line 437, in read\n    op_code, frame = self.sock.recv_data_frame(True)\n                     ^^^^^^^^^^^^^^^^^^^^^^^^^^^^^^^\n  File \"E:\\paper\\paper\\venv\\Lib\\site-packages\\websocket\\_core.py\", line 406, in recv_data_frame\n    frame = self.recv_frame()\n            ^^^^^^^^^^^^^^^^^\n  File \"E:\\paper\\paper\\venv\\Lib\\site-packages\\websocket\\_core.py\", line 445, in recv_frame\n    return self.frame_buffer.recv_frame()\n           ^^^^^^^^^^^^^^^^^^^^^^^^^^^^^^\n  File \"E:\\paper\\paper\\venv\\Lib\\site-packages\\websocket\\_abnf.py\", line 338, in recv_frame\n    self.recv_header()\n  File \"E:\\paper\\paper\\venv\\Lib\\site-packages\\websocket\\_abnf.py\", line 294, in recv_header\n    header = self.recv_strict(2)\n             ^^^^^^^^^^^^^^^^^^^\n  File \"E:\\paper\\paper\\venv\\Lib\\site-packages\\websocket\\_abnf.py\", line 373, in recv_strict\n    bytes_ = self.recv(min(16384, shortage))\n             ^^^^^^^^^^^^^^^^^^^^^^^^^^^^^^^\n  File \"E:\\paper\\paper\\venv\\Lib\\site-packages\\websocket\\_core.py\", line 529, in _recv\n    return recv(self.sock, bufsize)\n           ^^^^^^^^^^^^^^^^^^^^^^^^\n  File \"E:\\paper\\paper\\venv\\Lib\\site-packages\\websocket\\_socket.py\", line 122, in recv\n    raise WebSocketConnectionClosedException(\nwebsocket._exceptions.WebSocketConnectionClosedException: Connection to remote host was lost.\n\nDuring handling of the above exception, another exception occurred:\n\nTraceback (most recent call last):\n  File \"E:\\paper\\paper\\venv\\Lib\\site-packages\\urllib3\\connection.py\", line 174, in _new_conn\n    conn = connection.create_connection(\n           ^^^^^^^^^^^^^^^^^^^^^^^^^^^^^\n  File \"E:\\paper\\paper\\venv\\Lib\\site-packages\\urllib3\\util\\connection.py\", line 72, in create_connection\n    for res in socket.getaddrinfo(host, port, family, socket.SOCK_STREAM):\n               ^^^^^^^^^^^^^^^^^^^^^^^^^^^^^^^^^^^^^^^^^^^^^^^^^^^^^^^^^^\n  File \"C:\\Users\\hp\\AppData\\Local\\Programs\\Python\\Python312\\Lib\\socket.py\", line 963, in getaddrinfo\n    for res in _socket.getaddrinfo(host, port, family, type, proto, flags):\n               ^^^^^^^^^^^^^^^^^^^^^^^^^^^^^^^^^^^^^^^^^^^^^^^^^^^^^^^^^^^\nsocket.gaierror: [Errno 11001] getaddrinfo failed\n\nDuring handling of the above exception, another exception occurred:\n\nTraceback (most recent call last):\n  File \"E:\\paper\\paper\\venv\\Lib\\site-packages\\urllib3\\connectionpool.py\", line 716, in urlopen\n    httplib_response = self._make_request(\n                       ^^^^^^^^^^^^^^^^^^^\n  File \"E:\\paper\\paper\\venv\\Lib\\site-packages\\urllib3\\connectionpool.py\", line 404, in _make_request\n    self._validate_conn(conn)\n  File \"E:\\paper\\paper\\venv\\Lib\\site-packages\\urllib3\\connectionpool.py\", line 1061, in _validate_conn\n    conn.connect()\n  File \"E:\\paper\\paper\\venv\\Lib\\site-packages\\urllib3\\connection.py\", line 363, in connect\n    self.sock = conn = self._new_conn()\n                       ^^^^^^^^^^^^^^^^\n  File \"E:\\paper\\paper\\venv\\Lib\\site-packages\\urllib3\\connection.py\", line 186, in _new_conn\n    raise NewConnectionError(\nurllib3.exceptions.NewConnectionError: <urllib3.connection.HTTPSConnection object at 0x000001F079A5B980>: Failed to establish a new connection: [Errno 11001] getaddrinfo failed\n\nDuring handling of the above exception, another exception occurred:\n\nTraceback (most recent call last):\n  File \"E:\\paper\\paper\\venv\\Lib\\site-packages\\requests\\adapters.py\", line 486, in send\n    resp = conn.urlopen(\n           ^^^^^^^^^^^^^\n  File \"E:\\paper\\paper\\venv\\Lib\\site-packages\\urllib3\\connectionpool.py\", line 802, in urlopen\n    retries = retries.increment(\n              ^^^^^^^^^^^^^^^^^^\n  File \"E:\\paper\\paper\\venv\\Lib\\site-packages\\urllib3\\util\\retry.py\", line 594, in increment\n    raise MaxRetryError(_pool, url, error or ResponseError(cause))\nurllib3.exceptions.MaxRetryError: HTTPSConnectionPool(host='api-t1.fyers.in', port=443): Max retries exceeded with url: /data/symbol-token (Caused by NewConnectionError('<urllib3.connection.HTTPSConnection object at 0x000001F079A5B980>: Failed to establish a new connection: [Errno 11001] getaddrinfo failed'))\n\nDuring handling of the above exception, another exception occurred:\n\nTraceback (most recent call last):\n  File \"E:\\paper\\paper\\venv\\Lib\\site-packages\\fyers_apiv3\\FyersWebsocket\\data_ws.py\", line 63, in symbol_to_hsmtoken\n    response = requests.post(\n               ^^^^^^^^^^^^^^\n  File \"E:\\paper\\paper\\venv\\Lib\\site-packages\\requests\\api.py\", line 115, in post\n    return request(\"post\", url, data=data, json=json, **kwargs)\n           ^^^^^^^^^^^^^^^^^^^^^^^^^^^^^^^^^^^^^^^^^^^^^^^^^^^^\n  File \"E:\\paper\\paper\\venv\\Lib\\site-packages\\requests\\api.py\", line 59, in request\n    return session.request(method=method, url=url, **kwargs)\n           ^^^^^^^^^^^^^^^^^^^^^^^^^^^^^^^^^^^^^^^^^^^^^^^^^\n  File \"E:\\paper\\paper\\venv\\Lib\\site-packages\\requests\\sessions.py\", line 589, in request\n    resp = self.send(prep, **send_kwargs)\n           ^^^^^^^^^^^^^^^^^^^^^^^^^^^^^^\n  File \"E:\\paper\\paper\\venv\\Lib\\site-packages\\requests\\sessions.py\", line 703, in send\n    r = adapter.send(request, **kwargs)\n        ^^^^^^^^^^^^^^^^^^^^^^^^^^^^^^^\n  File \"E:\\paper\\paper\\venv\\Lib\\site-packages\\requests\\adapters.py\", line 519, in send\n    raise ConnectionError(e, request=request)\nrequests.exceptions.ConnectionError: HTTPSConnectionPool(host='api-t1.fyers.in', port=443): Max retries exceeded with url: /data/symbol-token (Caused by NewConnectionError('<urllib3.connection.HTTPSConnection object at 0x000001F079A5B980>: Failed to establish a new connection: [Errno 11001] getaddrinfo failed'))","exception_name":"ConnectionError"}
{"level":"ERROR","location":"[<lambda>:1663] data_ws","message":"[Errno 11001] getaddrinfo failed","timestamp":"2025-10-12 21:09:10,656+0530","service":"FyersDataSocket"}
{"level":"ERROR","location":"[__symbol_conversion:1374] data_ws","message":"'NoneType' object is not subscriptable","timestamp":"2025-10-12 21:09:11,291+0530","service":"FyersDataSocket","exception":"Traceback (most recent call last):\n  File \"E:\\paper\\paper\\venv\\Lib\\site-packages\\websocket\\_app.py\", line 428, in setSock\n    dispatcher.read(self.sock.sock, read, check)\n  File \"E:\\paper\\paper\\venv\\Lib\\site-packages\\websocket\\_app.py\", line 99, in read\n    if not read_callback():\n           ^^^^^^^^^^^^^^^\n  File \"E:\\paper\\paper\\venv\\Lib\\site-packages\\websocket\\_app.py\", line 442, in read\n    raise e\n  File \"E:\\paper\\paper\\venv\\Lib\\site-packages\\websocket\\_app.py\", line 437, in read\n    op_code, frame = self.sock.recv_data_frame(True)\n                     ^^^^^^^^^^^^^^^^^^^^^^^^^^^^^^^\n  File \"E:\\paper\\paper\\venv\\Lib\\site-packages\\websocket\\_core.py\", line 406, in recv_data_frame\n    frame = self.recv_frame()\n            ^^^^^^^^^^^^^^^^^\n  File \"E:\\paper\\paper\\venv\\Lib\\site-packages\\websocket\\_core.py\", line 445, in recv_frame\n    return self.frame_buffer.recv_frame()\n           ^^^^^^^^^^^^^^^^^^^^^^^^^^^^^^\n  File \"E:\\paper\\paper\\venv\\Lib\\site-packages\\websocket\\_abnf.py\", line 338, in recv_frame\n    self.recv_header()\n  File \"E:\\paper\\paper\\venv\\Lib\\site-packages\\websocket\\_abnf.py\", line 294, in recv_header\n    header = self.recv_strict(2)\n             ^^^^^^^^^^^^^^^^^^^\n  File \"E:\\paper\\paper\\venv\\Lib\\site-packages\\websocket\\_abnf.py\", line 373, in recv_strict\n    bytes_ = self.recv(min(16384, shortage))\n             ^^^^^^^^^^^^^^^^^^^^^^^^^^^^^^^\n  File \"E:\\paper\\paper\\venv\\Lib\\site-packages\\websocket\\_core.py\", line 529, in _recv\n    return recv(self.sock, bufsize)\n           ^^^^^^^^^^^^^^^^^^^^^^^^\n  File \"E:\\paper\\paper\\venv\\Lib\\site-packages\\websocket\\_socket.py\", line 122, in recv\n    raise WebSocketConnectionClosedException(\nwebsocket._exceptions.WebSocketConnectionClosedException: Connection to remote host was lost.\n\nDuring handling of the above exception, another exception occurred:\n\nTraceback (most recent call last):\n  File \"E:\\paper\\paper\\venv\\Lib\\site-packages\\fyers_apiv3\\FyersWebsocket\\data_ws.py\", line 1333, in __symbol_conversion\n    if symbol_value[3] != \"\":\n       ~~~~~~~~~~~~^^^\nTypeError: 'NoneType' object is not subscriptable","exception_name":"TypeError"}
{"level":"ERROR","location":"[symbol_to_hsmtoken:126] data_ws","message":"HTTPSConnectionPool(host='api-t1.fyers.in', port=443): Max retries exceeded with url: /data/symbol-token (Caused by NewConnectionError('<urllib3.connection.HTTPSConnection object at 0x000001F079A20F50>: Failed to establish a new connection: [Errno 11001] getaddrinfo failed'))","timestamp":"2025-10-12 21:09:12,234+0530","service":"FyersDataSocket","exception":"Traceback (most recent call last):\n  File \"E:\\paper\\paper\\venv\\Lib\\site-packages\\websocket\\_http.py\", line 155, in _get_addrinfo_list\n    addrinfo_list = socket.getaddrinfo(\n                    ^^^^^^^^^^^^^^^^^^^\n  File \"C:\\Users\\hp\\AppData\\Local\\Programs\\Python\\Python312\\Lib\\socket.py\", line 963, in getaddrinfo\n    for res in _socket.getaddrinfo(host, port, family, type, proto, flags):\n               ^^^^^^^^^^^^^^^^^^^^^^^^^^^^^^^^^^^^^^^^^^^^^^^^^^^^^^^^^^^\nsocket.gaierror: [Errno 11001] getaddrinfo failed\n\nDuring handling of the above exception, another exception occurred:\n\nTraceback (most recent call last):\n  File \"E:\\paper\\paper\\venv\\Lib\\site-packages\\websocket\\_app.py\", line 412, in setSock\n    self.sock.connect(\n  File \"E:\\paper\\paper\\venv\\Lib\\site-packages\\websocket\\_core.py\", line 249, in connect\n    self.sock, addrs = connect(url, self.sock_opt, proxy_info(**options),\n                       ^^^^^^^^^^^^^^^^^^^^^^^^^^^^^^^^^^^^^^^^^^^^^^^^^^\n  File \"E:\\paper\\paper\\venv\\Lib\\site-packages\\websocket\\_http.py\", line 122, in connect\n    addrinfo_list, need_tunnel, auth = _get_addrinfo_list(\n                                       ^^^^^^^^^^^^^^^^^^^\n  File \"E:\\paper\\paper\\venv\\Lib\\site-packages\\websocket\\_http.py\", line 167, in _get_addrinfo_list\n    raise WebSocketAddressException(e)\nwebsocket._exceptions.WebSocketAddressException: [Errno 11001] getaddrinfo failed\n\nDuring handling of the above exception, another exception occurred:\n\nTraceback (most recent call last):\n  File \"E:\\paper\\paper\\venv\\Lib\\site-packages\\urllib3\\connection.py\", line 174, in _new_conn\n    conn = connection.create_connection(\n           ^^^^^^^^^^^^^^^^^^^^^^^^^^^^^\n  File \"E:\\paper\\paper\\venv\\Lib\\site-packages\\urllib3\\util\\connection.py\", line 72, in create_connection\n    for res in socket.getaddrinfo(host, port, family, socket.SOCK_STREAM):\n               ^^^^^^^^^^^^^^^^^^^^^^^^^^^^^^^^^^^^^^^^^^^^^^^^^^^^^^^^^^\n  File \"C:\\Users\\hp\\AppData\\Local\\Programs\\Python\\Python312\\Lib\\socket.py\", line 963, in getaddrinfo\n    for res in _socket.getaddrinfo(host, port, family, type, proto, flags):\n               ^^^^^^^^^^^^^^^^^^^^^^^^^^^^^^^^^^^^^^^^^^^^^^^^^^^^^^^^^^^\nsocket.gaierror: [Errno 11001] getaddrinfo failed\n\nDuring handling of the above exception, another exception occurred:\n\nTraceback (most recent call last):\n  File \"E:\\paper\\paper\\venv\\Lib\\site-packages\\urllib3\\connectionpool.py\", line 716, in urlopen\n    httplib_response = self._make_request(\n                       ^^^^^^^^^^^^^^^^^^^\n  File \"E:\\paper\\paper\\venv\\Lib\\site-packages\\urllib3\\connectionpool.py\", line 404, in _make_request\n    self._validate_conn(conn)\n  File \"E:\\paper\\paper\\venv\\Lib\\site-packages\\urllib3\\connectionpool.py\", line 1061, in _validate_conn\n    conn.connect()\n  File \"E:\\paper\\paper\\venv\\Lib\\site-packages\\urllib3\\connection.py\", line 363, in connect\n    self.sock = conn = self._new_conn()\n                       ^^^^^^^^^^^^^^^^\n  File \"E:\\paper\\paper\\venv\\Lib\\site-packages\\urllib3\\connection.py\", line 186, in _new_conn\n    raise NewConnectionError(\nurllib3.exceptions.NewConnectionError: <urllib3.connection.HTTPSConnection object at 0x000001F079A20F50>: Failed to establish a new connection: [Errno 11001] getaddrinfo failed\n\nDuring handling of the above exception, another exception occurred:\n\nTraceback (most recent call last):\n  File \"E:\\paper\\paper\\venv\\Lib\\site-packages\\requests\\adapters.py\", line 486, in send\n    resp = conn.urlopen(\n           ^^^^^^^^^^^^^\n  File \"E:\\paper\\paper\\venv\\Lib\\site-packages\\urllib3\\connectionpool.py\", line 802, in urlopen\n    retries = retries.increment(\n              ^^^^^^^^^^^^^^^^^^\n  File \"E:\\paper\\paper\\venv\\Lib\\site-packages\\urllib3\\util\\retry.py\", line 594, in increment\n    raise MaxRetryError(_pool, url, error or ResponseError(cause))\nurllib3.exceptions.MaxRetryError: HTTPSConnectionPool(host='api-t1.fyers.in', port=443): Max retries exceeded with url: /data/symbol-token (Caused by NewConnectionError('<urllib3.connection.HTTPSConnection object at 0x000001F079A20F50>: Failed to establish a new connection: [Errno 11001] getaddrinfo failed'))\n\nDuring handling of the above exception, another exception occurred:\n\nTraceback (most recent call last):\n  File \"E:\\paper\\paper\\venv\\Lib\\site-packages\\fyers_apiv3\\FyersWebsocket\\data_ws.py\", line 63, in symbol_to_hsmtoken\n    response = requests.post(\n               ^^^^^^^^^^^^^^\n  File \"E:\\paper\\paper\\venv\\Lib\\site-packages\\requests\\api.py\", line 115, in post\n    return request(\"post\", url, data=data, json=json, **kwargs)\n           ^^^^^^^^^^^^^^^^^^^^^^^^^^^^^^^^^^^^^^^^^^^^^^^^^^^^\n  File \"E:\\paper\\paper\\venv\\Lib\\site-packages\\requests\\api.py\", line 59, in request\n    return session.request(method=method, url=url, **kwargs)\n           ^^^^^^^^^^^^^^^^^^^^^^^^^^^^^^^^^^^^^^^^^^^^^^^^^\n  File \"E:\\paper\\paper\\venv\\Lib\\site-packages\\requests\\sessions.py\", line 589, in request\n    resp = self.send(prep, **send_kwargs)\n           ^^^^^^^^^^^^^^^^^^^^^^^^^^^^^^\n  File \"E:\\paper\\paper\\venv\\Lib\\site-packages\\requests\\sessions.py\", line 703, in send\n    r = adapter.send(request, **kwargs)\n        ^^^^^^^^^^^^^^^^^^^^^^^^^^^^^^^\n  File \"E:\\paper\\paper\\venv\\Lib\\site-packages\\requests\\adapters.py\", line 519, in send\n    raise ConnectionError(e, request=request)\nrequests.exceptions.ConnectionError: HTTPSConnectionPool(host='api-t1.fyers.in', port=443): Max retries exceeded with url: /data/symbol-token (Caused by NewConnectionError('<urllib3.connection.HTTPSConnection object at 0x000001F079A20F50>: Failed to establish a new connection: [Errno 11001] getaddrinfo failed'))","exception_name":"ConnectionError"}
{"level":"ERROR","location":"[__symbol_conversion:1374] data_ws","message":"'NoneType' object is not subscriptable","timestamp":"2025-10-12 21:09:12,305+0530","service":"FyersDataSocket","exception":"Traceback (most recent call last):\n  File \"E:\\paper\\paper\\venv\\Lib\\site-packages\\websocket\\_http.py\", line 155, in _get_addrinfo_list\n    addrinfo_list = socket.getaddrinfo(\n                    ^^^^^^^^^^^^^^^^^^^\n  File \"C:\\Users\\hp\\AppData\\Local\\Programs\\Python\\Python312\\Lib\\socket.py\", line 963, in getaddrinfo\n    for res in _socket.getaddrinfo(host, port, family, type, proto, flags):\n               ^^^^^^^^^^^^^^^^^^^^^^^^^^^^^^^^^^^^^^^^^^^^^^^^^^^^^^^^^^^\nsocket.gaierror: [Errno 11001] getaddrinfo failed\n\nDuring handling of the above exception, another exception occurred:\n\nTraceback (most recent call last):\n  File \"E:\\paper\\paper\\venv\\Lib\\site-packages\\websocket\\_app.py\", line 412, in setSock\n    self.sock.connect(\n  File \"E:\\paper\\paper\\venv\\Lib\\site-packages\\websocket\\_core.py\", line 249, in connect\n    self.sock, addrs = connect(url, self.sock_opt, proxy_info(**options),\n                       ^^^^^^^^^^^^^^^^^^^^^^^^^^^^^^^^^^^^^^^^^^^^^^^^^^\n  File \"E:\\paper\\paper\\venv\\Lib\\site-packages\\websocket\\_http.py\", line 122, in connect\n    addrinfo_list, need_tunnel, auth = _get_addrinfo_list(\n                                       ^^^^^^^^^^^^^^^^^^^\n  File \"E:\\paper\\paper\\venv\\Lib\\site-packages\\websocket\\_http.py\", line 167, in _get_addrinfo_list\n    raise WebSocketAddressException(e)\nwebsocket._exceptions.WebSocketAddressException: [Errno 11001] getaddrinfo failed\n\nDuring handling of the above exception, another exception occurred:\n\nTraceback (most recent call last):\n  File \"E:\\paper\\paper\\venv\\Lib\\site-packages\\fyers_apiv3\\FyersWebsocket\\data_ws.py\", line 1333, in __symbol_conversion\n    if symbol_value[3] != \"\":\n       ~~~~~~~~~~~~^^^\nTypeError: 'NoneType' object is not subscriptable","exception_name":"TypeError"}
{"level":"ERROR","location":"[<lambda>:1663] data_ws","message":"[Errno 11001] getaddrinfo failed","timestamp":"2025-10-12 21:09:16,349+0530","service":"FyersDataSocket"}
{"level":"ERROR","location":"[symbol_to_hsmtoken:126] data_ws","message":"HTTPSConnectionPool(host='api-t1.fyers.in', port=443): Max retries exceeded with url: /data/symbol-token (Caused by NewConnectionError('<urllib3.connection.HTTPSConnection object at 0x000001F079952FF0>: Failed to establish a new connection: [Errno 11001] getaddrinfo failed'))","timestamp":"2025-10-12 21:09:18,347+0530","service":"FyersDataSocket","exception":"Traceback (most recent call last):\n  File \"E:\\paper\\paper\\venv\\Lib\\site-packages\\websocket\\_http.py\", line 155, in _get_addrinfo_list\n    addrinfo_list = socket.getaddrinfo(\n                    ^^^^^^^^^^^^^^^^^^^\n  File \"C:\\Users\\hp\\AppData\\Local\\Programs\\Python\\Python312\\Lib\\socket.py\", line 963, in getaddrinfo\n    for res in _socket.getaddrinfo(host, port, family, type, proto, flags):\n               ^^^^^^^^^^^^^^^^^^^^^^^^^^^^^^^^^^^^^^^^^^^^^^^^^^^^^^^^^^^\nsocket.gaierror: [Errno 11001] getaddrinfo failed\n\nDuring handling of the above exception, another exception occurred:\n\nTraceback (most recent call last):\n  File \"E:\\paper\\paper\\venv\\Lib\\site-packages\\websocket\\_app.py\", line 412, in setSock\n    self.sock.connect(\n  File \"E:\\paper\\paper\\venv\\Lib\\site-packages\\websocket\\_core.py\", line 249, in connect\n    self.sock, addrs = connect(url, self.sock_opt, proxy_info(**options),\n                       ^^^^^^^^^^^^^^^^^^^^^^^^^^^^^^^^^^^^^^^^^^^^^^^^^^\n  File \"E:\\paper\\paper\\venv\\Lib\\site-packages\\websocket\\_http.py\", line 122, in connect\n    addrinfo_list, need_tunnel, auth = _get_addrinfo_list(\n                                       ^^^^^^^^^^^^^^^^^^^\n  File \"E:\\paper\\paper\\venv\\Lib\\site-packages\\websocket\\_http.py\", line 167, in _get_addrinfo_list\n    raise WebSocketAddressException(e)\nwebsocket._exceptions.WebSocketAddressException: [Errno 11001] getaddrinfo failed\n\nDuring handling of the above exception, another exception occurred:\n\nTraceback (most recent call last):\n  File \"E:\\paper\\paper\\venv\\Lib\\site-packages\\urllib3\\connection.py\", line 174, in _new_conn\n    conn = connection.create_connection(\n           ^^^^^^^^^^^^^^^^^^^^^^^^^^^^^\n  File \"E:\\paper\\paper\\venv\\Lib\\site-packages\\urllib3\\util\\connection.py\", line 72, in create_connection\n    for res in socket.getaddrinfo(host, port, family, socket.SOCK_STREAM):\n               ^^^^^^^^^^^^^^^^^^^^^^^^^^^^^^^^^^^^^^^^^^^^^^^^^^^^^^^^^^\n  File \"C:\\Users\\hp\\AppData\\Local\\Programs\\Python\\Python312\\Lib\\socket.py\", line 963, in getaddrinfo\n    for res in _socket.getaddrinfo(host, port, family, type, proto, flags):\n               ^^^^^^^^^^^^^^^^^^^^^^^^^^^^^^^^^^^^^^^^^^^^^^^^^^^^^^^^^^^\nsocket.gaierror: [Errno 11001] getaddrinfo failed\n\nDuring handling of the above exception, another exception occurred:\n\nTraceback (most recent call last):\n  File \"E:\\paper\\paper\\venv\\Lib\\site-packages\\urllib3\\connectionpool.py\", line 716, in urlopen\n    httplib_response = self._make_request(\n                       ^^^^^^^^^^^^^^^^^^^\n  File \"E:\\paper\\paper\\venv\\Lib\\site-packages\\urllib3\\connectionpool.py\", line 404, in _make_request\n    self._validate_conn(conn)\n  File \"E:\\paper\\paper\\venv\\Lib\\site-packages\\urllib3\\connectionpool.py\", line 1061, in _validate_conn\n    conn.connect()\n  File \"E:\\paper\\paper\\venv\\Lib\\site-packages\\urllib3\\connection.py\", line 363, in connect\n    self.sock = conn = self._new_conn()\n                       ^^^^^^^^^^^^^^^^\n  File \"E:\\paper\\paper\\venv\\Lib\\site-packages\\urllib3\\connection.py\", line 186, in _new_conn\n    raise NewConnectionError(\nurllib3.exceptions.NewConnectionError: <urllib3.connection.HTTPSConnection object at 0x000001F079952FF0>: Failed to establish a new connection: [Errno 11001] getaddrinfo failed\n\nDuring handling of the above exception, another exception occurred:\n\nTraceback (most recent call last):\n  File \"E:\\paper\\paper\\venv\\Lib\\site-packages\\requests\\adapters.py\", line 486, in send\n    resp = conn.urlopen(\n           ^^^^^^^^^^^^^\n  File \"E:\\paper\\paper\\venv\\Lib\\site-packages\\urllib3\\connectionpool.py\", line 802, in urlopen\n    retries = retries.increment(\n              ^^^^^^^^^^^^^^^^^^\n  File \"E:\\paper\\paper\\venv\\Lib\\site-packages\\urllib3\\util\\retry.py\", line 594, in increment\n    raise MaxRetryError(_pool, url, error or ResponseError(cause))\nurllib3.exceptions.MaxRetryError: HTTPSConnectionPool(host='api-t1.fyers.in', port=443): Max retries exceeded with url: /data/symbol-token (Caused by NewConnectionError('<urllib3.connection.HTTPSConnection object at 0x000001F079952FF0>: Failed to establish a new connection: [Errno 11001] getaddrinfo failed'))\n\nDuring handling of the above exception, another exception occurred:\n\nTraceback (most recent call last):\n  File \"E:\\paper\\paper\\venv\\Lib\\site-packages\\fyers_apiv3\\FyersWebsocket\\data_ws.py\", line 63, in symbol_to_hsmtoken\n    response = requests.post(\n               ^^^^^^^^^^^^^^\n  File \"E:\\paper\\paper\\venv\\Lib\\site-packages\\requests\\api.py\", line 115, in post\n    return request(\"post\", url, data=data, json=json, **kwargs)\n           ^^^^^^^^^^^^^^^^^^^^^^^^^^^^^^^^^^^^^^^^^^^^^^^^^^^^\n  File \"E:\\paper\\paper\\venv\\Lib\\site-packages\\requests\\api.py\", line 59, in request\n    return session.request(method=method, url=url, **kwargs)\n           ^^^^^^^^^^^^^^^^^^^^^^^^^^^^^^^^^^^^^^^^^^^^^^^^^\n  File \"E:\\paper\\paper\\venv\\Lib\\site-packages\\requests\\sessions.py\", line 589, in request\n    resp = self.send(prep, **send_kwargs)\n           ^^^^^^^^^^^^^^^^^^^^^^^^^^^^^^\n  File \"E:\\paper\\paper\\venv\\Lib\\site-packages\\requests\\sessions.py\", line 703, in send\n    r = adapter.send(request, **kwargs)\n        ^^^^^^^^^^^^^^^^^^^^^^^^^^^^^^^\n  File \"E:\\paper\\paper\\venv\\Lib\\site-packages\\requests\\adapters.py\", line 519, in send\n    raise ConnectionError(e, request=request)\nrequests.exceptions.ConnectionError: HTTPSConnectionPool(host='api-t1.fyers.in', port=443): Max retries exceeded with url: /data/symbol-token (Caused by NewConnectionError('<urllib3.connection.HTTPSConnection object at 0x000001F079952FF0>: Failed to establish a new connection: [Errno 11001] getaddrinfo failed'))","exception_name":"ConnectionError"}
{"level":"ERROR","location":"[__symbol_conversion:1374] data_ws","message":"'NoneType' object is not subscriptable","timestamp":"2025-10-12 21:09:18,356+0530","service":"FyersDataSocket","exception":"Traceback (most recent call last):\n  File \"E:\\paper\\paper\\venv\\Lib\\site-packages\\websocket\\_http.py\", line 155, in _get_addrinfo_list\n    addrinfo_list = socket.getaddrinfo(\n                    ^^^^^^^^^^^^^^^^^^^\n  File \"C:\\Users\\hp\\AppData\\Local\\Programs\\Python\\Python312\\Lib\\socket.py\", line 963, in getaddrinfo\n    for res in _socket.getaddrinfo(host, port, family, type, proto, flags):\n               ^^^^^^^^^^^^^^^^^^^^^^^^^^^^^^^^^^^^^^^^^^^^^^^^^^^^^^^^^^^\nsocket.gaierror: [Errno 11001] getaddrinfo failed\n\nDuring handling of the above exception, another exception occurred:\n\nTraceback (most recent call last):\n  File \"E:\\paper\\paper\\venv\\Lib\\site-packages\\websocket\\_app.py\", line 412, in setSock\n    self.sock.connect(\n  File \"E:\\paper\\paper\\venv\\Lib\\site-packages\\websocket\\_core.py\", line 249, in connect\n    self.sock, addrs = connect(url, self.sock_opt, proxy_info(**options),\n                       ^^^^^^^^^^^^^^^^^^^^^^^^^^^^^^^^^^^^^^^^^^^^^^^^^^\n  File \"E:\\paper\\paper\\venv\\Lib\\site-packages\\websocket\\_http.py\", line 122, in connect\n    addrinfo_list, need_tunnel, auth = _get_addrinfo_list(\n                                       ^^^^^^^^^^^^^^^^^^^\n  File \"E:\\paper\\paper\\venv\\Lib\\site-packages\\websocket\\_http.py\", line 167, in _get_addrinfo_list\n    raise WebSocketAddressException(e)\nwebsocket._exceptions.WebSocketAddressException: [Errno 11001] getaddrinfo failed\n\nDuring handling of the above exception, another exception occurred:\n\nTraceback (most recent call last):\n  File \"E:\\paper\\paper\\venv\\Lib\\site-packages\\fyers_apiv3\\FyersWebsocket\\data_ws.py\", line 1333, in __symbol_conversion\n    if symbol_value[3] != \"\":\n       ~~~~~~~~~~~~^^^\nTypeError: 'NoneType' object is not subscriptable","exception_name":"TypeError"}
{"level":"ERROR","location":"[<lambda>:1663] data_ws","message":"[Errno 11001] getaddrinfo failed","timestamp":"2025-10-12 21:09:21,363+0530","service":"FyersDataSocket"}
{"level":"ERROR","location":"[symbol_to_hsmtoken:126] data_ws","message":"HTTPSConnectionPool(host='api-t1.fyers.in', port=443): Max retries exceeded with url: /data/symbol-token (Caused by NewConnectionError('<urllib3.connection.HTTPSConnection object at 0x000001F079A58D40>: Failed to establish a new connection: [Errno 11001] getaddrinfo failed'))","timestamp":"2025-10-12 21:09:23,362+0530","service":"FyersDataSocket","exception":"Traceback (most recent call last):\n  File \"E:\\paper\\paper\\venv\\Lib\\site-packages\\websocket\\_http.py\", line 155, in _get_addrinfo_list\n    addrinfo_list = socket.getaddrinfo(\n                    ^^^^^^^^^^^^^^^^^^^\n  File \"C:\\Users\\hp\\AppData\\Local\\Programs\\Python\\Python312\\Lib\\socket.py\", line 963, in getaddrinfo\n    for res in _socket.getaddrinfo(host, port, family, type, proto, flags):\n               ^^^^^^^^^^^^^^^^^^^^^^^^^^^^^^^^^^^^^^^^^^^^^^^^^^^^^^^^^^^\nsocket.gaierror: [Errno 11001] getaddrinfo failed\n\nDuring handling of the above exception, another exception occurred:\n\nTraceback (most recent call last):\n  File \"E:\\paper\\paper\\venv\\Lib\\site-packages\\websocket\\_app.py\", line 412, in setSock\n    self.sock.connect(\n  File \"E:\\paper\\paper\\venv\\Lib\\site-packages\\websocket\\_core.py\", line 249, in connect\n    self.sock, addrs = connect(url, self.sock_opt, proxy_info(**options),\n                       ^^^^^^^^^^^^^^^^^^^^^^^^^^^^^^^^^^^^^^^^^^^^^^^^^^\n  File \"E:\\paper\\paper\\venv\\Lib\\site-packages\\websocket\\_http.py\", line 122, in connect\n    addrinfo_list, need_tunnel, auth = _get_addrinfo_list(\n                                       ^^^^^^^^^^^^^^^^^^^\n  File \"E:\\paper\\paper\\venv\\Lib\\site-packages\\websocket\\_http.py\", line 167, in _get_addrinfo_list\n    raise WebSocketAddressException(e)\nwebsocket._exceptions.WebSocketAddressException: [Errno 11001] getaddrinfo failed\n\nDuring handling of the above exception, another exception occurred:\n\nTraceback (most recent call last):\n  File \"E:\\paper\\paper\\venv\\Lib\\site-packages\\urllib3\\connection.py\", line 174, in _new_conn\n    conn = connection.create_connection(\n           ^^^^^^^^^^^^^^^^^^^^^^^^^^^^^\n  File \"E:\\paper\\paper\\venv\\Lib\\site-packages\\urllib3\\util\\connection.py\", line 72, in create_connection\n    for res in socket.getaddrinfo(host, port, family, socket.SOCK_STREAM):\n               ^^^^^^^^^^^^^^^^^^^^^^^^^^^^^^^^^^^^^^^^^^^^^^^^^^^^^^^^^^\n  File \"C:\\Users\\hp\\AppData\\Local\\Programs\\Python\\Python312\\Lib\\socket.py\", line 963, in getaddrinfo\n    for res in _socket.getaddrinfo(host, port, family, type, proto, flags):\n               ^^^^^^^^^^^^^^^^^^^^^^^^^^^^^^^^^^^^^^^^^^^^^^^^^^^^^^^^^^^\nsocket.gaierror: [Errno 11001] getaddrinfo failed\n\nDuring handling of the above exception, another exception occurred:\n\nTraceback (most recent call last):\n  File \"E:\\paper\\paper\\venv\\Lib\\site-packages\\urllib3\\connectionpool.py\", line 716, in urlopen\n    httplib_response = self._make_request(\n                       ^^^^^^^^^^^^^^^^^^^\n  File \"E:\\paper\\paper\\venv\\Lib\\site-packages\\urllib3\\connectionpool.py\", line 404, in _make_request\n    self._validate_conn(conn)\n  File \"E:\\paper\\paper\\venv\\Lib\\site-packages\\urllib3\\connectionpool.py\", line 1061, in _validate_conn\n    conn.connect()\n  File \"E:\\paper\\paper\\venv\\Lib\\site-packages\\urllib3\\connection.py\", line 363, in connect\n    self.sock = conn = self._new_conn()\n                       ^^^^^^^^^^^^^^^^\n  File \"E:\\paper\\paper\\venv\\Lib\\site-packages\\urllib3\\connection.py\", line 186, in _new_conn\n    raise NewConnectionError(\nurllib3.exceptions.NewConnectionError: <urllib3.connection.HTTPSConnection object at 0x000001F079A58D40>: Failed to establish a new connection: [Errno 11001] getaddrinfo failed\n\nDuring handling of the above exception, another exception occurred:\n\nTraceback (most recent call last):\n  File \"E:\\paper\\paper\\venv\\Lib\\site-packages\\requests\\adapters.py\", line 486, in send\n    resp = conn.urlopen(\n           ^^^^^^^^^^^^^\n  File \"E:\\paper\\paper\\venv\\Lib\\site-packages\\urllib3\\connectionpool.py\", line 802, in urlopen\n    retries = retries.increment(\n              ^^^^^^^^^^^^^^^^^^\n  File \"E:\\paper\\paper\\venv\\Lib\\site-packages\\urllib3\\util\\retry.py\", line 594, in increment\n    raise MaxRetryError(_pool, url, error or ResponseError(cause))\nurllib3.exceptions.MaxRetryError: HTTPSConnectionPool(host='api-t1.fyers.in', port=443): Max retries exceeded with url: /data/symbol-token (Caused by NewConnectionError('<urllib3.connection.HTTPSConnection object at 0x000001F079A58D40>: Failed to establish a new connection: [Errno 11001] getaddrinfo failed'))\n\nDuring handling of the above exception, another exception occurred:\n\nTraceback (most recent call last):\n  File \"E:\\paper\\paper\\venv\\Lib\\site-packages\\fyers_apiv3\\FyersWebsocket\\data_ws.py\", line 63, in symbol_to_hsmtoken\n    response = requests.post(\n               ^^^^^^^^^^^^^^\n  File \"E:\\paper\\paper\\venv\\Lib\\site-packages\\requests\\api.py\", line 115, in post\n    return request(\"post\", url, data=data, json=json, **kwargs)\n           ^^^^^^^^^^^^^^^^^^^^^^^^^^^^^^^^^^^^^^^^^^^^^^^^^^^^\n  File \"E:\\paper\\paper\\venv\\Lib\\site-packages\\requests\\api.py\", line 59, in request\n    return session.request(method=method, url=url, **kwargs)\n           ^^^^^^^^^^^^^^^^^^^^^^^^^^^^^^^^^^^^^^^^^^^^^^^^^\n  File \"E:\\paper\\paper\\venv\\Lib\\site-packages\\requests\\sessions.py\", line 589, in request\n    resp = self.send(prep, **send_kwargs)\n           ^^^^^^^^^^^^^^^^^^^^^^^^^^^^^^\n  File \"E:\\paper\\paper\\venv\\Lib\\site-packages\\requests\\sessions.py\", line 703, in send\n    r = adapter.send(request, **kwargs)\n        ^^^^^^^^^^^^^^^^^^^^^^^^^^^^^^^\n  File \"E:\\paper\\paper\\venv\\Lib\\site-packages\\requests\\adapters.py\", line 519, in send\n    raise ConnectionError(e, request=request)\nrequests.exceptions.ConnectionError: HTTPSConnectionPool(host='api-t1.fyers.in', port=443): Max retries exceeded with url: /data/symbol-token (Caused by NewConnectionError('<urllib3.connection.HTTPSConnection object at 0x000001F079A58D40>: Failed to establish a new connection: [Errno 11001] getaddrinfo failed'))","exception_name":"ConnectionError"}
{"level":"ERROR","location":"[__symbol_conversion:1374] data_ws","message":"'NoneType' object is not subscriptable","timestamp":"2025-10-12 21:09:23,369+0530","service":"FyersDataSocket","exception":"Traceback (most recent call last):\n  File \"E:\\paper\\paper\\venv\\Lib\\site-packages\\websocket\\_http.py\", line 155, in _get_addrinfo_list\n    addrinfo_list = socket.getaddrinfo(\n                    ^^^^^^^^^^^^^^^^^^^\n  File \"C:\\Users\\hp\\AppData\\Local\\Programs\\Python\\Python312\\Lib\\socket.py\", line 963, in getaddrinfo\n    for res in _socket.getaddrinfo(host, port, family, type, proto, flags):\n               ^^^^^^^^^^^^^^^^^^^^^^^^^^^^^^^^^^^^^^^^^^^^^^^^^^^^^^^^^^^\nsocket.gaierror: [Errno 11001] getaddrinfo failed\n\nDuring handling of the above exception, another exception occurred:\n\nTraceback (most recent call last):\n  File \"E:\\paper\\paper\\venv\\Lib\\site-packages\\websocket\\_app.py\", line 412, in setSock\n    self.sock.connect(\n  File \"E:\\paper\\paper\\venv\\Lib\\site-packages\\websocket\\_core.py\", line 249, in connect\n    self.sock, addrs = connect(url, self.sock_opt, proxy_info(**options),\n                       ^^^^^^^^^^^^^^^^^^^^^^^^^^^^^^^^^^^^^^^^^^^^^^^^^^\n  File \"E:\\paper\\paper\\venv\\Lib\\site-packages\\websocket\\_http.py\", line 122, in connect\n    addrinfo_list, need_tunnel, auth = _get_addrinfo_list(\n                                       ^^^^^^^^^^^^^^^^^^^\n  File \"E:\\paper\\paper\\venv\\Lib\\site-packages\\websocket\\_http.py\", line 167, in _get_addrinfo_list\n    raise WebSocketAddressException(e)\nwebsocket._exceptions.WebSocketAddressException: [Errno 11001] getaddrinfo failed\n\nDuring handling of the above exception, another exception occurred:\n\nTraceback (most recent call last):\n  File \"E:\\paper\\paper\\venv\\Lib\\site-packages\\fyers_apiv3\\FyersWebsocket\\data_ws.py\", line 1333, in __symbol_conversion\n    if symbol_value[3] != \"\":\n       ~~~~~~~~~~~~^^^\nTypeError: 'NoneType' object is not subscriptable","exception_name":"TypeError"}
