{"level":"ERROR","location":"[<lambda>:1663] data_ws","message":"Connection to remote host was lost.","timestamp":"2025-10-12 18:14:57,539+0530","service":"FyersDataSocket"}
{"level":"ERROR","location":"[<lambda>:1663] data_ws","message":"Connection to remote host was lost.","timestamp":"2025-10-12 20:41:17,572+0530","service":"FyersDataSocket"}
{"level":"ERROR","location":"[<lambda>:1663] data_ws","message":"[Errno 11001] getaddrinfo failed","timestamp":"2025-10-12 20:41:22,739+0530","service":"FyersDataSocket"}
{"level":"ERROR","location":"[symbol_to_hsmtoken:126] data_ws","message":"HTTPSConnectionPool(host='api-t1.fyers.in', port=443): Max retries exceeded with url: /data/symbol-token (Caused by NewConnectionError('<urllib3.connection.HTTPSConnection object at 0x000001F079A5B980>: Failed to establish a new connection: [Errno 11001] getaddrinfo failed'))","timestamp":"2025-10-12 21:09:10,648+0530","service":"FyersDataSocket","exception":"Traceback (most recent call last):\n  File \"E:\\paper\\paper\\venv\\Lib\\site-packages\\websocket\\_app.py\", line 428, in setSock\n    dispatcher.read(self.sock.sock, read, check)\n  File \"E:\\paper\\paper\\venv\\Lib\\site-packages\\websocket\\_app.py\", line 99, in read\n    if not read_callback():\n           ^^^^^^^^^^^^^^^\n  File \"E:\\paper\\paper\\venv\\Lib\\site-packages\\websocket\\_app.py\", line 442, in read\n    raise e\n  File \"E:\\paper\\paper\\venv\\Lib\\site-packages\\websocket\\_app.py\", line 437, in read\n    op_code, frame = self.sock.recv_data_frame(True)\n                     ^^^^^^^^^^^^^^^^^^^^^^^^^^^^^^^\n  File \"E:\\paper\\paper\\venv\\Lib\\site-packages\\websocket\\_core.py\", line 406, in recv_data_frame\n    frame = self.recv_frame()\n            ^^^^^^^^^^^^^^^^^\n  File \"E:\\paper\\paper\\venv\\Lib\\site-packages\\websocket\\_core.py\", line 445, in recv_frame\n    return self.frame_buffer.recv_frame()\n           ^^^^^^^^^^^^^^^^^^^^^^^^^^^^^^\n  File \"E:\\paper\\paper\\venv\\Lib\\site-packages\\websocket\\_abnf.py\", line 338, in recv_frame\n    self.recv_header()\n  File \"E:\\paper\\paper\\venv\\Lib\\site-packages\\websocket\\_abnf.py\", line 294, in recv_header\n    header = self.recv_strict(2)\n             ^^^^^^^^^^^^^^^^^^^\n  File \"E:\\paper\\paper\\venv\\Lib\\site-packages\\websocket\\_abnf.py\", line 373, in recv_strict\n    bytes_ = self.recv(min(16384, shortage))\n             ^^^^^^^^^^^^^^^^^^^^^^^^^^^^^^^\n  File \"E:\\paper\\paper\\venv\\Lib\\site-packages\\websocket\\_core.py\", line 529, in _recv\n    return recv(self.sock, bufsize)\n           ^^^^^^^^^^^^^^^^^^^^^^^^\n  File \"E:\\paper\\paper\\venv\\Lib\\site-packages\\websocket\\_socket.py\", line 122, in recv\n    raise WebSocketConnectionClosedException(\nwebsocket._exceptions.WebSocketConnectionClosedException: Connection to remote host was lost.\n\nDuring handling of the above exception, another exception occurred:\n\nTraceback (most recent call last):\n  File \"E:\\paper\\paper\\venv\\Lib\\site-packages\\urllib3\\connection.py\", line 174, in _new_conn\n    conn = connection.create_connection(\n           ^^^^^^^^^^^^^^^^^^^^^^^^^^^^^\n  File \"E:\\paper\\paper\\venv\\Lib\\site-packages\\urllib3\\util\\connection.py\", line 72, in create_connection\n    for res in socket.getaddrinfo(host, port, family, socket.SOCK_STREAM):\n               ^^^^^^^^^^^^^^^^^^^^^^^^^^^^^^^^^^^^^^^^^^^^^^^^^^^^^^^^^^\n  File \"C:\\Users\\hp\\AppData\\Local\\Programs\\Python\\Python312\\Lib\\socket.py\", line 963, in getaddrinfo\n    for res in _socket.getaddrinfo(host, port, family, type, proto, flags):\n               ^^^^^^^^^^^^^^^^^^^^^^^^^^^^^^^^^^^^^^^^^^^^^^^^^^^^^^^^^^^\nsocket.gaierror: [Errno 11001] getaddrinfo failed\n\nDuring handling of the above exception, another exception occurred:\n\nTraceback (most recent call last):\n  File \"E:\\paper\\paper\\venv\\Lib\\site-packages\\urllib3\\connectionpool.py\", line 716, in urlopen\n    httplib_response = self._make_request(\n                       ^^^^^^^^^^^^^^^^^^^\n  File \"E:\\paper\\paper\\venv\\Lib\\site-packages\\urllib3\\connectionpool.py\", line 404, in _make_request\n    self._validate_conn(conn)\n  File \"E:\\paper\\paper\\venv\\Lib\\site-packages\\urllib3\\connectionpool.py\", line 1061, in _validate_conn\n    conn.connect()\n  File \"E:\\paper\\paper\\venv\\Lib\\site-packages\\urllib3\\connection.py\", line 363, in connect\n    self.sock = conn = self._new_conn()\n                       ^^^^^^^^^^^^^^^^\n  File \"E:\\paper\\paper\\venv\\Lib\\site-packages\\urllib3\\connection.py\", line 186, in _new_conn\n    raise NewConnectionError(\nurllib3.exceptions.NewConnectionError: <urllib3.connection.HTTPSConnection object at 0x000001F079A5B980>: Failed to establish a new connection: [Errno 11001] getaddrinfo failed\n\nDuring handling of the above exception, another exception occurred:\n\nTraceback (most recent call last):\n  File \"E:\\paper\\paper\\venv\\Lib\\site-packages\\requests\\adapters.py\", line 486, in send\n    resp = conn.urlopen(\n           ^^^^^^^^^^^^^\n  File \"E:\\paper\\paper\\venv\\Lib\\site-packages\\urllib3\\connectionpool.py\", line 802, in urlopen\n    retries = retries.increment(\n              ^^^^^^^^^^^^^^^^^^\n  File \"E:\\paper\\paper\\venv\\Lib\\site-packages\\urllib3\\util\\retry.py\", line 594, in increment\n    raise MaxRetryError(_pool, url, error or ResponseError(cause))\nurllib3.exceptions.MaxRetryError: HTTPSConnectionPool(host='api-t1.fyers.in', port=443): Max retries exceeded with url: /data/symbol-token (Caused by NewConnectionError('<urllib3.connection.HTTPSConnection object at 0x000001F079A5B980>: Failed to establish a new connection: [Errno 11001] getaddrinfo failed'))\n\nDuring handling of the above exception, another exception occurred:\n\nTraceback (most recent call last):\n  File \"E:\\paper\\paper\\venv\\Lib\\site-packages\\fyers_apiv3\\FyersWebsocket\\data_ws.py\", line 63, in symbol_to_hsmtoken\n    response = requests.post(\n               ^^^^^^^^^^^^^^\n  File \"E:\\paper\\paper\\venv\\Lib\\site-packages\\requests\\api.py\", line 115, in post\n    return request(\"post\", url, data=data, json=json, **kwargs)\n           ^^^^^^^^^^^^^^^^^^^^^^^^^^^^^^^^^^^^^^^^^^^^^^^^^^^^\n  File \"E:\\paper\\paper\\venv\\Lib\\site-packages\\requests\\api.py\", line 59, in request\n    return session.request(method=method, url=url, **kwargs)\n           ^^^^^^^^^^^^^^^^^^^^^^^^^^^^^^^^^^^^^^^^^^^^^^^^^\n  File \"E:\\paper\\paper\\venv\\Lib\\site-packages\\requests\\sessions.py\", line 589, in request\n    resp = self.send(prep, **send_kwargs)\n           ^^^^^^^^^^^^^^^^^^^^^^^^^^^^^^\n  File \"E:\\paper\\paper\\venv\\Lib\\site-packages\\requests\\sessions.py\", line 703, in send\n    r = adapter.send(request, **kwargs)\n        ^^^^^^^^^^^^^^^^^^^^^^^^^^^^^^^\n  File \"E:\\paper\\paper\\venv\\Lib\\site-packages\\requests\\adapters.py\", line 519, in send\n    raise ConnectionError(e, request=request)\nrequests.exceptions.ConnectionError: HTTPSConnectionPool(host='api-t1.fyers.in', port=443): Max retries exceeded with url: /data/symbol-token (Caused by NewConnectionError('<urllib3.connection.HTTPSConnection object at 0x000001F079A5B980>: Failed to establish a new connection: [Errno 11001] getaddrinfo failed'))","exception_name":"ConnectionError"}
{"level":"ERROR","location":"[<lambda>:1663] data_ws","message":"[Errno 11001] getaddrinfo failed","timestamp":"2025-10-12 21:09:10,656+0530","service":"FyersDataSocket"}
{"level":"ERROR","location":"[__symbol_conversion:1374] data_ws","message":"'NoneType' object is not subscriptable","timestamp":"2025-10-12 21:09:11,291+0530","service":"FyersDataSocket","exception":"Traceback (most recent call last):\n  File \"E:\\paper\\paper\\venv\\Lib\\site-packages\\websocket\\_app.py\", line 428, in setSock\n    dispatcher.read(self.sock.sock, read, check)\n  File \"E:\\paper\\paper\\venv\\Lib\\site-packages\\websocket\\_app.py\", line 99, in read\n    if not read_callback():\n           ^^^^^^^^^^^^^^^\n  File \"E:\\paper\\paper\\venv\\Lib\\site-packages\\websocket\\_app.py\", line 442, in read\n    raise e\n  File \"E:\\paper\\paper\\venv\\Lib\\site-packages\\websocket\\_app.py\", line 437, in read\n    op_code, frame = self.sock.recv_data_frame(True)\n                     ^^^^^^^^^^^^^^^^^^^^^^^^^^^^^^^\n  File \"E:\\paper\\paper\\venv\\Lib\\site-packages\\websocket\\_core.py\", line 406, in recv_data_frame\n    frame = self.recv_frame()\n            ^^^^^^^^^^^^^^^^^\n  File \"E:\\paper\\paper\\venv\\Lib\\site-packages\\websocket\\_core.py\", line 445, in recv_frame\n    return self.frame_buffer.recv_frame()\n           ^^^^^^^^^^^^^^^^^^^^^^^^^^^^^^\n  File \"E:\\paper\\paper\\venv\\Lib\\site-packages\\websocket\\_abnf.py\", line 338, in recv_frame\n    self.recv_header()\n  File \"E:\\paper\\paper\\venv\\Lib\\site-packages\\websocket\\_abnf.py\", line 294, in recv_header\n    header = self.recv_strict(2)\n             ^^^^^^^^^^^^^^^^^^^\n  File \"E:\\paper\\paper\\venv\\Lib\\site-packages\\websocket\\_abnf.py\", line 373, in recv_strict\n    bytes_ = self.recv(min(16384, shortage))\n             ^^^^^^^^^^^^^^^^^^^^^^^^^^^^^^^\n  File \"E:\\paper\\paper\\venv\\Lib\\site-packages\\websocket\\_core.py\", line 529, in _recv\n    return recv(self.sock, bufsize)\n           ^^^^^^^^^^^^^^^^^^^^^^^^\n  File \"E:\\paper\\paper\\venv\\Lib\\site-packages\\websocket\\_socket.py\", line 122, in recv\n    raise WebSocketConnectionClosedException(\nwebsocket._exceptions.WebSocketConnectionClosedException: Connection to remote host was lost.\n\nDuring handling of the above exception, another exception occurred:\n\nTraceback (most recent call last):\n  File \"E:\\paper\\paper\\venv\\Lib\\site-packages\\fyers_apiv3\\FyersWebsocket\\data_ws.py\", line 1333, in __symbol_conversion\n    if symbol_value[3] != \"\":\n       ~~~~~~~~~~~~^^^\nTypeError: 'NoneType' object is not subscriptable","exception_name":"TypeError"}
{"level":"ERROR","location":"[symbol_to_hsmtoken:126] data_ws","message":"HTTPSConnectionPool(host='api-t1.fyers.in', port=443): Max retries exceeded with url: /data/symbol-token (Caused by NewConnectionError('<urllib3.connection.HTTPSConnection object at 0x000001F079A20F50>: Failed to establish a new connection: [Errno 11001] getaddrinfo failed'))","timestamp":"2025-10-12 21:09:12,234+0530","service":"FyersDataSocket","exception":"Traceback (most recent call last):\n  File \"E:\\paper\\paper\\venv\\Lib\\site-packages\\websocket\\_http.py\", line 155, in _get_addrinfo_list\n    addrinfo_list = socket.getaddrinfo(\n                    ^^^^^^^^^^^^^^^^^^^\n  File \"C:\\Users\\hp\\AppData\\Local\\Programs\\Python\\Python312\\Lib\\socket.py\", line 963, in getaddrinfo\n    for res in _socket.getaddrinfo(host, port, family, type, proto, flags):\n               ^^^^^^^^^^^^^^^^^^^^^^^^^^^^^^^^^^^^^^^^^^^^^^^^^^^^^^^^^^^\nsocket.gaierror: [Errno 11001] getaddrinfo failed\n\nDuring handling of the above exception, another exception occurred:\n\nTraceback (most recent call last):\n  File \"E:\\paper\\paper\\venv\\Lib\\site-packages\\websocket\\_app.py\", line 412, in setSock\n    self.sock.connect(\n  File \"E:\\paper\\paper\\venv\\Lib\\site-packages\\websocket\\_core.py\", line 249, in connect\n    self.sock, addrs = connect(url, self.sock_opt, proxy_info(**options),\n                       ^^^^^^^^^^^^^^^^^^^^^^^^^^^^^^^^^^^^^^^^^^^^^^^^^^\n  File \"E:\\paper\\paper\\venv\\Lib\\site-packages\\websocket\\_http.py\", line 122, in connect\n    addrinfo_list, need_tunnel, auth = _get_addrinfo_list(\n                                       ^^^^^^^^^^^^^^^^^^^\n  File \"E:\\paper\\paper\\venv\\Lib\\site-packages\\websocket\\_http.py\", line 167, in _get_addrinfo_list\n    raise WebSocketAddressException(e)\nwebsocket._exceptions.WebSocketAddressException: [Errno 11001] getaddrinfo failed\n\nDuring handling of the above exception, another exception occurred:\n\nTraceback (most recent call last):\n  File \"E:\\paper\\paper\\venv\\Lib\\site-packages\\urllib3\\connection.py\", line 174, in _new_conn\n    conn = connection.create_connection(\n           ^^^^^^^^^^^^^^^^^^^^^^^^^^^^^\n  File \"E:\\paper\\paper\\venv\\Lib\\site-packages\\urllib3\\util\\connection.py\", line 72, in create_connection\n    for res in socket.getaddrinfo(host, port, family, socket.SOCK_STREAM):\n               ^^^^^^^^^^^^^^^^^^^^^^^^^^^^^^^^^^^^^^^^^^^^^^^^^^^^^^^^^^\n  File \"C:\\Users\\hp\\AppData\\Local\\Programs\\Python\\Python312\\Lib\\socket.py\", line 963, in getaddrinfo\n    for res in _socket.getaddrinfo(host, port, family, type, proto, flags):\n               ^^^^^^^^^^^^^^^^^^^^^^^^^^^^^^^^^^^^^^^^^^^^^^^^^^^^^^^^^^^\nsocket.gaierror: [Errno 11001] getaddrinfo failed\n\nDuring handling of the above exception, another exception occurred:\n\nTraceback (most recent call last):\n  File \"E:\\paper\\paper\\venv\\Lib\\site-packages\\urllib3\\connectionpool.py\", line 716, in urlopen\n    httplib_response = self._make_request(\n                       ^^^^^^^^^^^^^^^^^^^\n  File \"E:\\paper\\paper\\venv\\Lib\\site-packages\\urllib3\\connectionpool.py\", line 404, in _make_request\n    self._validate_conn(conn)\n  File \"E:\\paper\\paper\\venv\\Lib\\site-packages\\urllib3\\connectionpool.py\", line 1061, in _validate_conn\n    conn.connect()\n  File \"E:\\paper\\paper\\venv\\Lib\\site-packages\\urllib3\\connection.py\", line 363, in connect\n    self.sock = conn = self._new_conn()\n                       ^^^^^^^^^^^^^^^^\n  File \"E:\\paper\\paper\\venv\\Lib\\site-packages\\urllib3\\connection.py\", line 186, in _new_conn\n    raise NewConnectionError(\nurllib3.exceptions.NewConnectionError: <urllib3.connection.HTTPSConnection object at 0x000001F079A20F50>: Failed to establish a new connection: [Errno 11001] getaddrinfo failed\n\nDuring handling of the above exception, another exception occurred:\n\nTraceback (most recent call last):\n  File \"E:\\paper\\paper\\venv\\Lib\\site-packages\\requests\\adapters.py\", line 486, in send\n    resp = conn.urlopen(\n           ^^^^^^^^^^^^^\n  File \"E:\\paper\\paper\\venv\\Lib\\site-packages\\urllib3\\connectionpool.py\", line 802, in urlopen\n    retries = retries.increment(\n              ^^^^^^^^^^^^^^^^^^\n  File \"E:\\paper\\paper\\venv\\Lib\\site-packages\\urllib3\\util\\retry.py\", line 594, in increment\n    raise MaxRetryError(_pool, url, error or ResponseError(cause))\nurllib3.exceptions.MaxRetryError: HTTPSConnectionPool(host='api-t1.fyers.in', port=443): Max retries exceeded with url: /data/symbol-token (Caused by NewConnectionError('<urllib3.connection.HTTPSConnection object at 0x000001F079A20F50>: Failed to establish a new connection: [Errno 11001] getaddrinfo failed'))\n\nDuring handling of the above exception, another exception occurred:\n\nTraceback (most recent call last):\n  File \"E:\\paper\\paper\\venv\\Lib\\site-packages\\fyers_apiv3\\FyersWebsocket\\data_ws.py\", line 63, in symbol_to_hsmtoken\n    response = requests.post(\n               ^^^^^^^^^^^^^^\n  File \"E:\\paper\\paper\\venv\\Lib\\site-packages\\requests\\api.py\", line 115, in post\n    return request(\"post\", url, data=data, json=json, **kwargs)\n           ^^^^^^^^^^^^^^^^^^^^^^^^^^^^^^^^^^^^^^^^^^^^^^^^^^^^\n  File \"E:\\paper\\paper\\venv\\Lib\\site-packages\\requests\\api.py\", line 59, in request\n    return session.request(method=method, url=url, **kwargs)\n           ^^^^^^^^^^^^^^^^^^^^^^^^^^^^^^^^^^^^^^^^^^^^^^^^^\n  File \"E:\\paper\\paper\\venv\\Lib\\site-packages\\requests\\sessions.py\", line 589, in request\n    resp = self.send(prep, **send_kwargs)\n           ^^^^^^^^^^^^^^^^^^^^^^^^^^^^^^\n  File \"E:\\paper\\paper\\venv\\Lib\\site-packages\\requests\\sessions.py\", line 703, in send\n    r = adapter.send(request, **kwargs)\n        ^^^^^^^^^^^^^^^^^^^^^^^^^^^^^^^\n  File \"E:\\paper\\paper\\venv\\Lib\\site-packages\\requests\\adapters.py\", line 519, in send\n    raise ConnectionError(e, request=request)\nrequests.exceptions.ConnectionError: HTTPSConnectionPool(host='api-t1.fyers.in', port=443): Max retries exceeded with url: /data/symbol-token (Caused by NewConnectionError('<urllib3.connection.HTTPSConnection object at 0x000001F079A20F50>: Failed to establish a new connection: [Errno 11001] getaddrinfo failed'))","exception_name":"ConnectionError"}
{"level":"ERROR","location":"[__symbol_conversion:1374] data_ws","message":"'NoneType' object is not subscriptable","timestamp":"2025-10-12 21:09:12,305+0530","service":"FyersDataSocket","exception":"Traceback (most recent call last):\n  File \"E:\\paper\\paper\\venv\\Lib\\site-packages\\websocket\\_http.py\", line 155, in _get_addrinfo_list\n    addrinfo_list = socket.getaddrinfo(\n                    ^^^^^^^^^^^^^^^^^^^\n  File \"C:\\Users\\hp\\AppData\\Local\\Programs\\Python\\Python312\\Lib\\socket.py\", line 963, in getaddrinfo\n    for res in _socket.getaddrinfo(host, port, family, type, proto, flags):\n               ^^^^^^^^^^^^^^^^^^^^^^^^^^^^^^^^^^^^^^^^^^^^^^^^^^^^^^^^^^^\nsocket.gaierror: [Errno 11001] getaddrinfo failed\n\nDuring handling of the above exception, another exception occurred:\n\nTraceback (most recent call last):\n  File \"E:\\paper\\paper\\venv\\Lib\\site-packages\\websocket\\_app.py\", line 412, in setSock\n    self.sock.connect(\n  File \"E:\\paper\\paper\\venv\\Lib\\site-packages\\websocket\\_core.py\", line 249, in connect\n    self.sock, addrs = connect(url, self.sock_opt, proxy_info(**options),\n                       ^^^^^^^^^^^^^^^^^^^^^^^^^^^^^^^^^^^^^^^^^^^^^^^^^^\n  File \"E:\\paper\\paper\\venv\\Lib\\site-packages\\websocket\\_http.py\", line 122, in connect\n    addrinfo_list, need_tunnel, auth = _get_addrinfo_list(\n                                       ^^^^^^^^^^^^^^^^^^^\n  File \"E:\\paper\\paper\\venv\\Lib\\site-packages\\websocket\\_http.py\", line 167, in _get_addrinfo_list\n    raise WebSocketAddressException(e)\nwebsocket._exceptions.WebSocketAddressException: [Errno 11001] getaddrinfo failed\n\nDuring handling of the above exception, another exception occurred:\n\nTraceback (most recent call last):\n  File \"E:\\paper\\paper\\venv\\Lib\\site-packages\\fyers_apiv3\\FyersWebsocket\\data_ws.py\", line 1333, in __symbol_conversion\n    if symbol_value[3] != \"\":\n       ~~~~~~~~~~~~^^^\nTypeError: 'NoneType' object is not subscriptable","exception_name":"TypeError"}
{"level":"ERROR","location":"[<lambda>:1663] data_ws","message":"[Errno 11001] getaddrinfo failed","timestamp":"2025-10-12 21:09:16,349+0530","service":"FyersDataSocket"}
{"level":"ERROR","location":"[symbol_to_hsmtoken:126] data_ws","message":"HTTPSConnectionPool(host='api-t1.fyers.in', port=443): Max retries exceeded with url: /data/symbol-token (Caused by NewConnectionError('<urllib3.connection.HTTPSConnection object at 0x000001F079952FF0>: Failed to establish a new connection: [Errno 11001] getaddrinfo failed'))","timestamp":"2025-10-12 21:09:18,347+0530","service":"FyersDataSocket","exception":"Traceback (most recent call last):\n  File \"E:\\paper\\paper\\venv\\Lib\\site-packages\\websocket\\_http.py\", line 155, in _get_addrinfo_list\n    addrinfo_list = socket.getaddrinfo(\n                    ^^^^^^^^^^^^^^^^^^^\n  File \"C:\\Users\\hp\\AppData\\Local\\Programs\\Python\\Python312\\Lib\\socket.py\", line 963, in getaddrinfo\n    for res in _socket.getaddrinfo(host, port, family, type, proto, flags):\n               ^^^^^^^^^^^^^^^^^^^^^^^^^^^^^^^^^^^^^^^^^^^^^^^^^^^^^^^^^^^\nsocket.gaierror: [Errno 11001] getaddrinfo failed\n\nDuring handling of the above exception, another exception occurred:\n\nTraceback (most recent call last):\n  File \"E:\\paper\\paper\\venv\\Lib\\site-packages\\websocket\\_app.py\", line 412, in setSock\n    self.sock.connect(\n  File \"E:\\paper\\paper\\venv\\Lib\\site-packages\\websocket\\_core.py\", line 249, in connect\n    self.sock, addrs = connect(url, self.sock_opt, proxy_info(**options),\n                       ^^^^^^^^^^^^^^^^^^^^^^^^^^^^^^^^^^^^^^^^^^^^^^^^^^\n  File \"E:\\paper\\paper\\venv\\Lib\\site-packages\\websocket\\_http.py\", line 122, in connect\n    addrinfo_list, need_tunnel, auth = _get_addrinfo_list(\n                                       ^^^^^^^^^^^^^^^^^^^\n  File \"E:\\paper\\paper\\venv\\Lib\\site-packages\\websocket\\_http.py\", line 167, in _get_addrinfo_list\n    raise WebSocketAddressException(e)\nwebsocket._exceptions.WebSocketAddressException: [Errno 11001] getaddrinfo failed\n\nDuring handling of the above exception, another exception occurred:\n\nTraceback (most recent call last):\n  File \"E:\\paper\\paper\\venv\\Lib\\site-packages\\urllib3\\connection.py\", line 174, in _new_conn\n    conn = connection.create_connection(\n           ^^^^^^^^^^^^^^^^^^^^^^^^^^^^^\n  File \"E:\\paper\\paper\\venv\\Lib\\site-packages\\urllib3\\util\\connection.py\", line 72, in create_connection\n    for res in socket.getaddrinfo(host, port, family, socket.SOCK_STREAM):\n               ^^^^^^^^^^^^^^^^^^^^^^^^^^^^^^^^^^^^^^^^^^^^^^^^^^^^^^^^^^\n  File \"C:\\Users\\hp\\AppData\\Local\\Programs\\Python\\Python312\\Lib\\socket.py\", line 963, in getaddrinfo\n    for res in _socket.getaddrinfo(host, port, family, type, proto, flags):\n               ^^^^^^^^^^^^^^^^^^^^^^^^^^^^^^^^^^^^^^^^^^^^^^^^^^^^^^^^^^^\nsocket.gaierror: [Errno 11001] getaddrinfo failed\n\nDuring handling of the above exception, another exception occurred:\n\nTraceback (most recent call last):\n  File \"E:\\paper\\paper\\venv\\Lib\\site-packages\\urllib3\\connectionpool.py\", line 716, in urlopen\n    httplib_response = self._make_request(\n                       ^^^^^^^^^^^^^^^^^^^\n  File \"E:\\paper\\paper\\venv\\Lib\\site-packages\\urllib3\\connectionpool.py\", line 404, in _make_request\n    self._validate_conn(conn)\n  File \"E:\\paper\\paper\\venv\\Lib\\site-packages\\urllib3\\connectionpool.py\", line 1061, in _validate_conn\n    conn.connect()\n  File \"E:\\paper\\paper\\venv\\Lib\\site-packages\\urllib3\\connection.py\", line 363, in connect\n    self.sock = conn = self._new_conn()\n                       ^^^^^^^^^^^^^^^^\n  File \"E:\\paper\\paper\\venv\\Lib\\site-packages\\urllib3\\connection.py\", line 186, in _new_conn\n    raise NewConnectionError(\nurllib3.exceptions.NewConnectionError: <urllib3.connection.HTTPSConnection object at 0x000001F079952FF0>: Failed to establish a new connection: [Errno 11001] getaddrinfo failed\n\nDuring handling of the above exception, another exception occurred:\n\nTraceback (most recent call last):\n  File \"E:\\paper\\paper\\venv\\Lib\\site-packages\\requests\\adapters.py\", line 486, in send\n    resp = conn.urlopen(\n           ^^^^^^^^^^^^^\n  File \"E:\\paper\\paper\\venv\\Lib\\site-packages\\urllib3\\connectionpool.py\", line 802, in urlopen\n    retries = retries.increment(\n              ^^^^^^^^^^^^^^^^^^\n  File \"E:\\paper\\paper\\venv\\Lib\\site-packages\\urllib3\\util\\retry.py\", line 594, in increment\n    raise MaxRetryError(_pool, url, error or ResponseError(cause))\nurllib3.exceptions.MaxRetryError: HTTPSConnectionPool(host='api-t1.fyers.in', port=443): Max retries exceeded with url: /data/symbol-token (Caused by NewConnectionError('<urllib3.connection.HTTPSConnection object at 0x000001F079952FF0>: Failed to establish a new connection: [Errno 11001] getaddrinfo failed'))\n\nDuring handling of the above exception, another exception occurred:\n\nTraceback (most recent call last):\n  File \"E:\\paper\\paper\\venv\\Lib\\site-packages\\fyers_apiv3\\FyersWebsocket\\data_ws.py\", line 63, in symbol_to_hsmtoken\n    response = requests.post(\n               ^^^^^^^^^^^^^^\n  File \"E:\\paper\\paper\\venv\\Lib\\site-packages\\requests\\api.py\", line 115, in post\n    return request(\"post\", url, data=data, json=json, **kwargs)\n           ^^^^^^^^^^^^^^^^^^^^^^^^^^^^^^^^^^^^^^^^^^^^^^^^^^^^\n  File \"E:\\paper\\paper\\venv\\Lib\\site-packages\\requests\\api.py\", line 59, in request\n    return session.request(method=method, url=url, **kwargs)\n           ^^^^^^^^^^^^^^^^^^^^^^^^^^^^^^^^^^^^^^^^^^^^^^^^^\n  File \"E:\\paper\\paper\\venv\\Lib\\site-packages\\requests\\sessions.py\", line 589, in request\n    resp = self.send(prep, **send_kwargs)\n           ^^^^^^^^^^^^^^^^^^^^^^^^^^^^^^\n  File \"E:\\paper\\paper\\venv\\Lib\\site-packages\\requests\\sessions.py\", line 703, in send\n    r = adapter.send(request, **kwargs)\n        ^^^^^^^^^^^^^^^^^^^^^^^^^^^^^^^\n  File \"E:\\paper\\paper\\venv\\Lib\\site-packages\\requests\\adapters.py\", line 519, in send\n    raise ConnectionError(e, request=request)\nrequests.exceptions.ConnectionError: HTTPSConnectionPool(host='api-t1.fyers.in', port=443): Max retries exceeded with url: /data/symbol-token (Caused by NewConnectionError('<urllib3.connection.HTTPSConnection object at 0x000001F079952FF0>: Failed to establish a new connection: [Errno 11001] getaddrinfo failed'))","exception_name":"ConnectionError"}
{"level":"ERROR","location":"[__symbol_conversion:1374] data_ws","message":"'NoneType' object is not subscriptable","timestamp":"2025-10-12 21:09:18,356+0530","service":"FyersDataSocket","exception":"Traceback (most recent call last):\n  File \"E:\\paper\\paper\\venv\\Lib\\site-packages\\websocket\\_http.py\", line 155, in _get_addrinfo_list\n    addrinfo_list = socket.getaddrinfo(\n                    ^^^^^^^^^^^^^^^^^^^\n  File \"C:\\Users\\hp\\AppData\\Local\\Programs\\Python\\Python312\\Lib\\socket.py\", line 963, in getaddrinfo\n    for res in _socket.getaddrinfo(host, port, family, type, proto, flags):\n               ^^^^^^^^^^^^^^^^^^^^^^^^^^^^^^^^^^^^^^^^^^^^^^^^^^^^^^^^^^^\nsocket.gaierror: [Errno 11001] getaddrinfo failed\n\nDuring handling of the above exception, another exception occurred:\n\nTraceback (most recent call last):\n  File \"E:\\paper\\paper\\venv\\Lib\\site-packages\\websocket\\_app.py\", line 412, in setSock\n    self.sock.connect(\n  File \"E:\\paper\\paper\\venv\\Lib\\site-packages\\websocket\\_core.py\", line 249, in connect\n    self.sock, addrs = connect(url, self.sock_opt, proxy_info(**options),\n                       ^^^^^^^^^^^^^^^^^^^^^^^^^^^^^^^^^^^^^^^^^^^^^^^^^^\n  File \"E:\\paper\\paper\\venv\\Lib\\site-packages\\websocket\\_http.py\", line 122, in connect\n    addrinfo_list, need_tunnel, auth = _get_addrinfo_list(\n                                       ^^^^^^^^^^^^^^^^^^^\n  File \"E:\\paper\\paper\\venv\\Lib\\site-packages\\websocket\\_http.py\", line 167, in _get_addrinfo_list\n    raise WebSocketAddressException(e)\nwebsocket._exceptions.WebSocketAddressException: [Errno 11001] getaddrinfo failed\n\nDuring handling of the above exception, another exception occurred:\n\nTraceback (most recent call last):\n  File \"E:\\paper\\paper\\venv\\Lib\\site-packages\\fyers_apiv3\\FyersWebsocket\\data_ws.py\", line 1333, in __symbol_conversion\n    if symbol_value[3] != \"\":\n       ~~~~~~~~~~~~^^^\nTypeError: 'NoneType' object is not subscriptable","exception_name":"TypeError"}
{"level":"ERROR","location":"[<lambda>:1663] data_ws","message":"[Errno 11001] getaddrinfo failed","timestamp":"2025-10-12 21:09:21,363+0530","service":"FyersDataSocket"}
{"level":"ERROR","location":"[symbol_to_hsmtoken:126] data_ws","message":"HTTPSConnectionPool(host='api-t1.fyers.in', port=443): Max retries exceeded with url: /data/symbol-token (Caused by NewConnectionError('<urllib3.connection.HTTPSConnection object at 0x000001F079A58D40>: Failed to establish a new connection: [Errno 11001] getaddrinfo failed'))","timestamp":"2025-10-12 21:09:23,362+0530","service":"FyersDataSocket","exception":"Traceback (most recent call last):\n  File \"E:\\paper\\paper\\venv\\Lib\\site-packages\\websocket\\_http.py\", line 155, in _get_addrinfo_list\n    addrinfo_list = socket.getaddrinfo(\n                    ^^^^^^^^^^^^^^^^^^^\n  File \"C:\\Users\\hp\\AppData\\Local\\Programs\\Python\\Python312\\Lib\\socket.py\", line 963, in getaddrinfo\n    for res in _socket.getaddrinfo(host, port, family, type, proto, flags):\n               ^^^^^^^^^^^^^^^^^^^^^^^^^^^^^^^^^^^^^^^^^^^^^^^^^^^^^^^^^^^\nsocket.gaierror: [Errno 11001] getaddrinfo failed\n\nDuring handling of the above exception, another exception occurred:\n\nTraceback (most recent call last):\n  File \"E:\\paper\\paper\\venv\\Lib\\site-packages\\websocket\\_app.py\", line 412, in setSock\n    self.sock.connect(\n  File \"E:\\paper\\paper\\venv\\Lib\\site-packages\\websocket\\_core.py\", line 249, in connect\n    self.sock, addrs = connect(url, self.sock_opt, proxy_info(**options),\n                       ^^^^^^^^^^^^^^^^^^^^^^^^^^^^^^^^^^^^^^^^^^^^^^^^^^\n  File \"E:\\paper\\paper\\venv\\Lib\\site-packages\\websocket\\_http.py\", line 122, in connect\n    addrinfo_list, need_tunnel, auth = _get_addrinfo_list(\n                                       ^^^^^^^^^^^^^^^^^^^\n  File \"E:\\paper\\paper\\venv\\Lib\\site-packages\\websocket\\_http.py\", line 167, in _get_addrinfo_list\n    raise WebSocketAddressException(e)\nwebsocket._exceptions.WebSocketAddressException: [Errno 11001] getaddrinfo failed\n\nDuring handling of the above exception, another exception occurred:\n\nTraceback (most recent call last):\n  File \"E:\\paper\\paper\\venv\\Lib\\site-packages\\urllib3\\connection.py\", line 174, in _new_conn\n    conn = connection.create_connection(\n           ^^^^^^^^^^^^^^^^^^^^^^^^^^^^^\n  File \"E:\\paper\\paper\\venv\\Lib\\site-packages\\urllib3\\util\\connection.py\", line 72, in create_connection\n    for res in socket.getaddrinfo(host, port, family, socket.SOCK_STREAM):\n               ^^^^^^^^^^^^^^^^^^^^^^^^^^^^^^^^^^^^^^^^^^^^^^^^^^^^^^^^^^\n  File \"C:\\Users\\hp\\AppData\\Local\\Programs\\Python\\Python312\\Lib\\socket.py\", line 963, in getaddrinfo\n    for res in _socket.getaddrinfo(host, port, family, type, proto, flags):\n               ^^^^^^^^^^^^^^^^^^^^^^^^^^^^^^^^^^^^^^^^^^^^^^^^^^^^^^^^^^^\nsocket.gaierror: [Errno 11001] getaddrinfo failed\n\nDuring handling of the above exception, another exception occurred:\n\nTraceback (most recent call last):\n  File \"E:\\paper\\paper\\venv\\Lib\\site-packages\\urllib3\\connectionpool.py\", line 716, in urlopen\n    httplib_response = self._make_request(\n                       ^^^^^^^^^^^^^^^^^^^\n  File \"E:\\paper\\paper\\venv\\Lib\\site-packages\\urllib3\\connectionpool.py\", line 404, in _make_request\n    self._validate_conn(conn)\n  File \"E:\\paper\\paper\\venv\\Lib\\site-packages\\urllib3\\connectionpool.py\", line 1061, in _validate_conn\n    conn.connect()\n  File \"E:\\paper\\paper\\venv\\Lib\\site-packages\\urllib3\\connection.py\", line 363, in connect\n    self.sock = conn = self._new_conn()\n                       ^^^^^^^^^^^^^^^^\n  File \"E:\\paper\\paper\\venv\\Lib\\site-packages\\urllib3\\connection.py\", line 186, in _new_conn\n    raise NewConnectionError(\nurllib3.exceptions.NewConnectionError: <urllib3.connection.HTTPSConnection object at 0x000001F079A58D40>: Failed to establish a new connection: [Errno 11001] getaddrinfo failed\n\nDuring handling of the above exception, another exception occurred:\n\nTraceback (most recent call last):\n  File \"E:\\paper\\paper\\venv\\Lib\\site-packages\\requests\\adapters.py\", line 486, in send\n    resp = conn.urlopen(\n           ^^^^^^^^^^^^^\n  File \"E:\\paper\\paper\\venv\\Lib\\site-packages\\urllib3\\connectionpool.py\", line 802, in urlopen\n    retries = retries.increment(\n              ^^^^^^^^^^^^^^^^^^\n  File \"E:\\paper\\paper\\venv\\Lib\\site-packages\\urllib3\\util\\retry.py\", line 594, in increment\n    raise MaxRetryError(_pool, url, error or ResponseError(cause))\nurllib3.exceptions.MaxRetryError: HTTPSConnectionPool(host='api-t1.fyers.in', port=443): Max retries exceeded with url: /data/symbol-token (Caused by NewConnectionError('<urllib3.connection.HTTPSConnection object at 0x000001F079A58D40>: Failed to establish a new connection: [Errno 11001] getaddrinfo failed'))\n\nDuring handling of the above exception, another exception occurred:\n\nTraceback (most recent call last):\n  File \"E:\\paper\\paper\\venv\\Lib\\site-packages\\fyers_apiv3\\FyersWebsocket\\data_ws.py\", line 63, in symbol_to_hsmtoken\n    response = requests.post(\n               ^^^^^^^^^^^^^^\n  File \"E:\\paper\\paper\\venv\\Lib\\site-packages\\requests\\api.py\", line 115, in post\n    return request(\"post\", url, data=data, json=json, **kwargs)\n           ^^^^^^^^^^^^^^^^^^^^^^^^^^^^^^^^^^^^^^^^^^^^^^^^^^^^\n  File \"E:\\paper\\paper\\venv\\Lib\\site-packages\\requests\\api.py\", line 59, in request\n    return session.request(method=method, url=url, **kwargs)\n           ^^^^^^^^^^^^^^^^^^^^^^^^^^^^^^^^^^^^^^^^^^^^^^^^^\n  File \"E:\\paper\\paper\\venv\\Lib\\site-packages\\requests\\sessions.py\", line 589, in request\n    resp = self.send(prep, **send_kwargs)\n           ^^^^^^^^^^^^^^^^^^^^^^^^^^^^^^\n  File \"E:\\paper\\paper\\venv\\Lib\\site-packages\\requests\\sessions.py\", line 703, in send\n    r = adapter.send(request, **kwargs)\n        ^^^^^^^^^^^^^^^^^^^^^^^^^^^^^^^\n  File \"E:\\paper\\paper\\venv\\Lib\\site-packages\\requests\\adapters.py\", line 519, in send\n    raise ConnectionError(e, request=request)\nrequests.exceptions.ConnectionError: HTTPSConnectionPool(host='api-t1.fyers.in', port=443): Max retries exceeded with url: /data/symbol-token (Caused by NewConnectionError('<urllib3.connection.HTTPSConnection object at 0x000001F079A58D40>: Failed to establish a new connection: [Errno 11001] getaddrinfo failed'))","exception_name":"ConnectionError"}
{"level":"ERROR","location":"[__symbol_conversion:1374] data_ws","message":"'NoneType' object is not subscriptable","timestamp":"2025-10-12 21:09:23,369+0530","service":"FyersDataSocket","exception":"Traceback (most recent call last):\n  File \"E:\\paper\\paper\\venv\\Lib\\site-packages\\websocket\\_http.py\", line 155, in _get_addrinfo_list\n    addrinfo_list = socket.getaddrinfo(\n                    ^^^^^^^^^^^^^^^^^^^\n  File \"C:\\Users\\hp\\AppData\\Local\\Programs\\Python\\Python312\\Lib\\socket.py\", line 963, in getaddrinfo\n    for res in _socket.getaddrinfo(host, port, family, type, proto, flags):\n               ^^^^^^^^^^^^^^^^^^^^^^^^^^^^^^^^^^^^^^^^^^^^^^^^^^^^^^^^^^^\nsocket.gaierror: [Errno 11001] getaddrinfo failed\n\nDuring handling of the above exception, another exception occurred:\n\nTraceback (most recent call last):\n  File \"E:\\paper\\paper\\venv\\Lib\\site-packages\\websocket\\_app.py\", line 412, in setSock\n    self.sock.connect(\n  File \"E:\\paper\\paper\\venv\\Lib\\site-packages\\websocket\\_core.py\", line 249, in connect\n    self.sock, addrs = connect(url, self.sock_opt, proxy_info(**options),\n                       ^^^^^^^^^^^^^^^^^^^^^^^^^^^^^^^^^^^^^^^^^^^^^^^^^^\n  File \"E:\\paper\\paper\\venv\\Lib\\site-packages\\websocket\\_http.py\", line 122, in connect\n    addrinfo_list, need_tunnel, auth = _get_addrinfo_list(\n                                       ^^^^^^^^^^^^^^^^^^^\n  File \"E:\\paper\\paper\\venv\\Lib\\site-packages\\websocket\\_http.py\", line 167, in _get_addrinfo_list\n    raise WebSocketAddressException(e)\nwebsocket._exceptions.WebSocketAddressException: [Errno 11001] getaddrinfo failed\n\nDuring handling of the above exception, another exception occurred:\n\nTraceback (most recent call last):\n  File \"E:\\paper\\paper\\venv\\Lib\\site-packages\\fyers_apiv3\\FyersWebsocket\\data_ws.py\", line 1333, in __symbol_conversion\n    if symbol_value[3] != \"\":\n       ~~~~~~~~~~~~^^^\nTypeError: 'NoneType' object is not subscriptable","exception_name":"TypeError"}
{"level":"ERROR","location":"[__symbol_conversion:1352] data_ws","message":{"code":-300,"message":"Please provide a valid symbol","s":"error","type":"sub","invalid_symbols":["MCX:GOLD5DECFUT"]},"timestamp":"2025-10-12 23:19:00,147+0530","service":"FyersDataSocket"}
{"level":"ERROR","location":"[__symbol_conversion:1352] data_ws","message":{"code":-300,"message":"Please provide a valid symbol","s":"error","type":"sub","invalid_symbols":["MCX:GOLD05DECFUT"]},"timestamp":"2025-10-12 23:19:33,987+0530","service":"FyersDataSocket"}
{"level":"ERROR","location":"[__symbol_conversion:1352] data_ws","message":{"code":-300,"message":"Please provide a valid symbol","s":"error","type":"sub","invalid_symbols":["MCX:GOLD251205FUT"]},"timestamp":"2025-10-12 23:24:02,032+0530","service":"FyersDataSocket"}
{"level":"ERROR","location":"[__symbol_conversion:1352] data_ws","message":{"code":-300,"message":"Please provide a valid symbol","s":"error","type":"sub","invalid_symbols":["NSE:SBIN251028900CE"]},"timestamp":"2025-10-12 23:26:36,258+0530","service":"FyersDataSocket"}
{"level":"ERROR","location":"[__symbol_conversion:1352] data_ws","message":{"code":-300,"message":"Please provide a valid symbol","s":"error","type":"sub","invalid_symbols":["NSE:SBIN26OCT25CE900"]},"timestamp":"2025-10-12 23:28:52,268+0530","service":"FyersDataSocket"}
{"level":"ERROR","location":"[__symbol_conversion:1352] data_ws","message":{"code":-300,"message":"Please provide a valid symbol","s":"error","type":"sub","invalid_symbols":["NSE:SBIN25OCT28900CE"]},"timestamp":"2025-10-12 23:29:30,595+0530","service":"FyersDataSocket"}
{"level":"ERROR","location":"[__symbol_conversion:1352] data_ws","message":{"code":-300,"message":"Please provide a valid symbol","s":"error","type":"sub","invalid_symbols":["MCX:SILVERM05DECFUT"]},"timestamp":"2025-10-12 23:30:48,758+0530","service":"FyersDataSocket"}
{"level":"ERROR","location":"[__symbol_conversion:1352] data_ws","message":{"code":-300,"message":"Please provide a valid symbol","s":"error","type":"sub","invalid_symbols":["NSE:SBIN28OCT900CE"]},"timestamp":"2025-10-12 23:33:18,288+0530","service":"FyersDataSocket"}
{"level":"ERROR","location":"[<lambda>:1663] data_ws","message":"Connection to remote host was lost.","timestamp":"2025-10-13 00:09:57,330+0530","service":"FyersDataSocket"}
{"level":"ERROR","location":"[<lambda>:1663] data_ws","message":"[Errno 11001] getaddrinfo failed","timestamp":"2025-10-13 00:21:13,522+0530","service":"FyersDataSocket"}
{"level":"ERROR","location":"[__symbol_conversion:1352] data_ws","message":{"code":-300,"message":"Please provide a valid symbol","s":"error","type":"sub","invalid_symbols":["NSE:SBIN28OCT900CE"]},"timestamp":"2025-10-13 00:21:18,414+0530","service":"FyersDataSocket"}
{"level":"ERROR","location":"[__symbol_conversion:1352] data_ws","message":{"code":-300,"message":"Please provide a valid symbol","s":"error","type":"sub","invalid_symbols":["NSE:SBIN28OCT900CE"]},"timestamp":"2025-10-13 00:21:31,631+0530","service":"FyersDataSocket"}
{"level":"ERROR","location":"[access_token_to_hsmtoken:272] data_ws","message":{"type":"cn","code":-99,"message":"Token is expired","s":"error"},"timestamp":"2025-10-13 16:58:05,508+0530","service":"FyersDataSocket"}
{"level":"ERROR","location":"[access_token_to_hsmtoken:272] data_ws","message":{"type":"cn","code":-99,"message":"Token is expired","s":"error"},"timestamp":"2025-10-13 16:58:15,858+0530","service":"FyersDataSocket"}
{"level":"ERROR","location":"[access_token_to_hsmtoken:272] data_ws","message":{"type":"cn","code":-99,"message":"Token is expired","s":"error"},"timestamp":"2025-10-13 17:04:08,504+0530","service":"FyersDataSocket"}
{"level":"ERROR","location":"[access_token_to_hsmtoken:272] data_ws","message":{"type":"cn","code":-99,"message":"Token is expired","s":"error"},"timestamp":"2025-10-13 17:05:31,927+0530","service":"FyersDataSocket"}
{"level":"ERROR","location":"[access_token_to_hsmtoken:272] data_ws","message":{"type":"cn","code":-99,"message":"Token is expired","s":"error"},"timestamp":"2025-10-13 17:05:48,396+0530","service":"FyersDataSocket"}
{"level":"ERROR","location":"[__symbol_conversion:1352] data_ws","message":{"code":-300,"message":"Please provide a valid symbol","s":"error","type":"sub","invalid_symbols":["NSE:SBIN28OCT900CE"]},"timestamp":"2025-10-13 17:10:53,216+0530","service":"FyersDataSocket"}
{"level":"ERROR","location":"[__symbol_conversion:1352] data_ws","message":{"code":-300,"message":"Please provide a valid symbol","s":"error","type":"sub","invalid_symbols":["NSE:SBIN28OCT900CE"]},"timestamp":"2025-10-13 17:20:45,932+0530","service":"FyersDataSocket"}
{"level":"ERROR","location":"[<lambda>:1663] data_ws","message":"EOF occurred in violation of protocol (_ssl.c:2406)","timestamp":"2025-10-13 17:49:59,509+0530","service":"FyersDataSocket"}
{"level":"ERROR","location":"[__symbol_conversion:1352] data_ws","message":{"code":-300,"message":"Please provide a valid symbol","s":"error","type":"sub","invalid_symbols":["NSE:SBIN28OCT900CE"]},"timestamp":"2025-10-13 17:50:07,733+0530","service":"FyersDataSocket"}
{"level":"ERROR","location":"[__symbol_conversion:1352] data_ws","message":{"code":-300,"message":"Please provide a valid symbol","s":"error","type":"sub","invalid_symbols":["NSE:SBIN28OCT900CE"]},"timestamp":"2025-10-13 17:51:33,811+0530","service":"FyersDataSocket"}
{"level":"ERROR","location":"[__symbol_conversion:1352] data_ws","message":{"code":-300,"message":"Please provide a valid symbol","s":"error","type":"sub","invalid_symbols":["NSE:SBIN28OCT900CE"]},"timestamp":"2025-10-13 17:55:09,739+0530","service":"FyersDataSocket"}
{"level":"ERROR","location":"[__symbol_conversion:1352] data_ws","message":{"code":-300,"message":"Please provide a valid symbol","s":"error","type":"sub","invalid_symbols":["NSE:SBIN28OCT900CE"]},"timestamp":"2025-10-13 17:57:19,586+0530","service":"FyersDataSocket"}
{"level":"ERROR","location":"[__symbol_conversion:1352] data_ws","message":{"code":-300,"message":"Please provide a valid symbol","s":"error","type":"sub","invalid_symbols":["NSE:SBIN28OCT900CE"]},"timestamp":"2025-10-13 17:58:50,215+0530","service":"FyersDataSocket"}
{"level":"ERROR","location":"[__symbol_conversion:1352] data_ws","message":{"code":-300,"message":"Please provide a valid symbol","s":"error","type":"sub","invalid_symbols":["NSE:SBIN28OCT900CE"]},"timestamp":"2025-10-13 18:00:18,326+0530","service":"FyersDataSocket"}
{"level":"ERROR","location":"[<lambda>:1663] data_ws","message":"EOF occurred in violation of protocol (_ssl.c:2406)","timestamp":"2025-10-13 19:16:25,210+0530","service":"FyersDataSocket"}
{"level":"ERROR","location":"[__symbol_conversion:1352] data_ws","message":{"code":-300,"message":"Please provide a valid symbol","s":"error","type":"sub","invalid_symbols":["NSE:SBIN28OCT900CE"]},"timestamp":"2025-10-13 19:16:33,416+0530","service":"FyersDataSocket"}
{"level":"ERROR","location":"[<lambda>:1663] data_ws","message":"Connection to remote host was lost.","timestamp":"2025-10-13 20:43:32,978+0530","service":"FyersDataSocket"}
{"level":"ERROR","location":"[__symbol_conversion:1352] data_ws","message":{"code":-300,"message":"Please provide a valid symbol","s":"error","type":"sub","invalid_symbols":["NSE:SBIN28OCT900CE"]},"timestamp":"2025-10-13 21:54:30,765+0530","service":"FyersDataSocket"}
{"level":"ERROR","location":"[<lambda>:1663] data_ws","message":"Connection to remote host was lost.","timestamp":"2025-10-13 22:38:27,437+0530","service":"FyersDataSocket"}
{"level":"ERROR","location":"[<lambda>:1663] data_ws","message":"[Errno 11001] getaddrinfo failed","timestamp":"2025-10-13 23:01:46,839+0530","service":"FyersDataSocket"}
{"level":"ERROR","location":"[symbol_to_hsmtoken:126] data_ws","message":"HTTPSConnectionPool(host='api-t1.fyers.in', port=443): Max retries exceeded with url: /data/symbol-token (Caused by NewConnectionError('<urllib3.connection.HTTPSConnection object at 0x000001E1F5C075F0>: Failed to establish a new connection: [Errno 11001] getaddrinfo failed'))","timestamp":"2025-10-13 23:01:48,841+0530","service":"FyersDataSocket","exception":"Traceback (most recent call last):\n  File \"E:\\paper\\paper\\venv\\Lib\\site-packages\\websocket\\_app.py\", line 428, in setSock\n    dispatcher.read(self.sock.sock, read, check)\n  File \"E:\\paper\\paper\\venv\\Lib\\site-packages\\websocket\\_app.py\", line 99, in read\n    if not read_callback():\n           ^^^^^^^^^^^^^^^\n  File \"E:\\paper\\paper\\venv\\Lib\\site-packages\\websocket\\_app.py\", line 442, in read\n    raise e\n  File \"E:\\paper\\paper\\venv\\Lib\\site-packages\\websocket\\_app.py\", line 437, in read\n    op_code, frame = self.sock.recv_data_frame(True)\n                     ^^^^^^^^^^^^^^^^^^^^^^^^^^^^^^^\n  File \"E:\\paper\\paper\\venv\\Lib\\site-packages\\websocket\\_core.py\", line 406, in recv_data_frame\n    frame = self.recv_frame()\n            ^^^^^^^^^^^^^^^^^\n  File \"E:\\paper\\paper\\venv\\Lib\\site-packages\\websocket\\_core.py\", line 445, in recv_frame\n    return self.frame_buffer.recv_frame()\n           ^^^^^^^^^^^^^^^^^^^^^^^^^^^^^^\n  File \"E:\\paper\\paper\\venv\\Lib\\site-packages\\websocket\\_abnf.py\", line 338, in recv_frame\n    self.recv_header()\n  File \"E:\\paper\\paper\\venv\\Lib\\site-packages\\websocket\\_abnf.py\", line 294, in recv_header\n    header = self.recv_strict(2)\n             ^^^^^^^^^^^^^^^^^^^\n  File \"E:\\paper\\paper\\venv\\Lib\\site-packages\\websocket\\_abnf.py\", line 373, in recv_strict\n    bytes_ = self.recv(min(16384, shortage))\n             ^^^^^^^^^^^^^^^^^^^^^^^^^^^^^^^\n  File \"E:\\paper\\paper\\venv\\Lib\\site-packages\\websocket\\_core.py\", line 529, in _recv\n    return recv(self.sock, bufsize)\n           ^^^^^^^^^^^^^^^^^^^^^^^^\n  File \"E:\\paper\\paper\\venv\\Lib\\site-packages\\websocket\\_socket.py\", line 122, in recv\n    raise WebSocketConnectionClosedException(\nwebsocket._exceptions.WebSocketConnectionClosedException: Connection to remote host was lost.\n\nDuring handling of the above exception, another exception occurred:\n\nTraceback (most recent call last):\n  File \"E:\\paper\\paper\\venv\\Lib\\site-packages\\urllib3\\connection.py\", line 174, in _new_conn\n    conn = connection.create_connection(\n           ^^^^^^^^^^^^^^^^^^^^^^^^^^^^^\n  File \"E:\\paper\\paper\\venv\\Lib\\site-packages\\urllib3\\util\\connection.py\", line 72, in create_connection\n    for res in socket.getaddrinfo(host, port, family, socket.SOCK_STREAM):\n               ^^^^^^^^^^^^^^^^^^^^^^^^^^^^^^^^^^^^^^^^^^^^^^^^^^^^^^^^^^\n  File \"C:\\Users\\hp\\AppData\\Local\\Programs\\Python\\Python312\\Lib\\socket.py\", line 963, in getaddrinfo\n    for res in _socket.getaddrinfo(host, port, family, type, proto, flags):\n               ^^^^^^^^^^^^^^^^^^^^^^^^^^^^^^^^^^^^^^^^^^^^^^^^^^^^^^^^^^^\nsocket.gaierror: [Errno 11001] getaddrinfo failed\n\nDuring handling of the above exception, another exception occurred:\n\nTraceback (most recent call last):\n  File \"E:\\paper\\paper\\venv\\Lib\\site-packages\\urllib3\\connectionpool.py\", line 716, in urlopen\n    httplib_response = self._make_request(\n                       ^^^^^^^^^^^^^^^^^^^\n  File \"E:\\paper\\paper\\venv\\Lib\\site-packages\\urllib3\\connectionpool.py\", line 404, in _make_request\n    self._validate_conn(conn)\n  File \"E:\\paper\\paper\\venv\\Lib\\site-packages\\urllib3\\connectionpool.py\", line 1061, in _validate_conn\n    conn.connect()\n  File \"E:\\paper\\paper\\venv\\Lib\\site-packages\\urllib3\\connection.py\", line 363, in connect\n    self.sock = conn = self._new_conn()\n                       ^^^^^^^^^^^^^^^^\n  File \"E:\\paper\\paper\\venv\\Lib\\site-packages\\urllib3\\connection.py\", line 186, in _new_conn\n    raise NewConnectionError(\nurllib3.exceptions.NewConnectionError: <urllib3.connection.HTTPSConnection object at 0x000001E1F5C075F0>: Failed to establish a new connection: [Errno 11001] getaddrinfo failed\n\nDuring handling of the above exception, another exception occurred:\n\nTraceback (most recent call last):\n  File \"E:\\paper\\paper\\venv\\Lib\\site-packages\\requests\\adapters.py\", line 486, in send\n    resp = conn.urlopen(\n           ^^^^^^^^^^^^^\n  File \"E:\\paper\\paper\\venv\\Lib\\site-packages\\urllib3\\connectionpool.py\", line 802, in urlopen\n    retries = retries.increment(\n              ^^^^^^^^^^^^^^^^^^\n  File \"E:\\paper\\paper\\venv\\Lib\\site-packages\\urllib3\\util\\retry.py\", line 594, in increment\n    raise MaxRetryError(_pool, url, error or ResponseError(cause))\nurllib3.exceptions.MaxRetryError: HTTPSConnectionPool(host='api-t1.fyers.in', port=443): Max retries exceeded with url: /data/symbol-token (Caused by NewConnectionError('<urllib3.connection.HTTPSConnection object at 0x000001E1F5C075F0>: Failed to establish a new connection: [Errno 11001] getaddrinfo failed'))\n\nDuring handling of the above exception, another exception occurred:\n\nTraceback (most recent call last):\n  File \"E:\\paper\\paper\\venv\\Lib\\site-packages\\fyers_apiv3\\FyersWebsocket\\data_ws.py\", line 63, in symbol_to_hsmtoken\n    response = requests.post(\n               ^^^^^^^^^^^^^^\n  File \"E:\\paper\\paper\\venv\\Lib\\site-packages\\requests\\api.py\", line 115, in post\n    return request(\"post\", url, data=data, json=json, **kwargs)\n           ^^^^^^^^^^^^^^^^^^^^^^^^^^^^^^^^^^^^^^^^^^^^^^^^^^^^\n  File \"E:\\paper\\paper\\venv\\Lib\\site-packages\\requests\\api.py\", line 59, in request\n    return session.request(method=method, url=url, **kwargs)\n           ^^^^^^^^^^^^^^^^^^^^^^^^^^^^^^^^^^^^^^^^^^^^^^^^^\n  File \"E:\\paper\\paper\\venv\\Lib\\site-packages\\requests\\sessions.py\", line 589, in request\n    resp = self.send(prep, **send_kwargs)\n           ^^^^^^^^^^^^^^^^^^^^^^^^^^^^^^\n  File \"E:\\paper\\paper\\venv\\Lib\\site-packages\\requests\\sessions.py\", line 703, in send\n    r = adapter.send(request, **kwargs)\n        ^^^^^^^^^^^^^^^^^^^^^^^^^^^^^^^\n  File \"E:\\paper\\paper\\venv\\Lib\\site-packages\\requests\\adapters.py\", line 519, in send\n    raise ConnectionError(e, request=request)\nrequests.exceptions.ConnectionError: HTTPSConnectionPool(host='api-t1.fyers.in', port=443): Max retries exceeded with url: /data/symbol-token (Caused by NewConnectionError('<urllib3.connection.HTTPSConnection object at 0x000001E1F5C075F0>: Failed to establish a new connection: [Errno 11001] getaddrinfo failed'))","exception_name":"ConnectionError"}
{"level":"ERROR","location":"[__symbol_conversion:1374] data_ws","message":"'NoneType' object is not subscriptable","timestamp":"2025-10-13 23:01:49,921+0530","service":"FyersDataSocket","exception":"Traceback (most recent call last):\n  File \"E:\\paper\\paper\\venv\\Lib\\site-packages\\websocket\\_app.py\", line 428, in setSock\n    dispatcher.read(self.sock.sock, read, check)\n  File \"E:\\paper\\paper\\venv\\Lib\\site-packages\\websocket\\_app.py\", line 99, in read\n    if not read_callback():\n           ^^^^^^^^^^^^^^^\n  File \"E:\\paper\\paper\\venv\\Lib\\site-packages\\websocket\\_app.py\", line 442, in read\n    raise e\n  File \"E:\\paper\\paper\\venv\\Lib\\site-packages\\websocket\\_app.py\", line 437, in read\n    op_code, frame = self.sock.recv_data_frame(True)\n                     ^^^^^^^^^^^^^^^^^^^^^^^^^^^^^^^\n  File \"E:\\paper\\paper\\venv\\Lib\\site-packages\\websocket\\_core.py\", line 406, in recv_data_frame\n    frame = self.recv_frame()\n            ^^^^^^^^^^^^^^^^^\n  File \"E:\\paper\\paper\\venv\\Lib\\site-packages\\websocket\\_core.py\", line 445, in recv_frame\n    return self.frame_buffer.recv_frame()\n           ^^^^^^^^^^^^^^^^^^^^^^^^^^^^^^\n  File \"E:\\paper\\paper\\venv\\Lib\\site-packages\\websocket\\_abnf.py\", line 338, in recv_frame\n    self.recv_header()\n  File \"E:\\paper\\paper\\venv\\Lib\\site-packages\\websocket\\_abnf.py\", line 294, in recv_header\n    header = self.recv_strict(2)\n             ^^^^^^^^^^^^^^^^^^^\n  File \"E:\\paper\\paper\\venv\\Lib\\site-packages\\websocket\\_abnf.py\", line 373, in recv_strict\n    bytes_ = self.recv(min(16384, shortage))\n             ^^^^^^^^^^^^^^^^^^^^^^^^^^^^^^^\n  File \"E:\\paper\\paper\\venv\\Lib\\site-packages\\websocket\\_core.py\", line 529, in _recv\n    return recv(self.sock, bufsize)\n           ^^^^^^^^^^^^^^^^^^^^^^^^\n  File \"E:\\paper\\paper\\venv\\Lib\\site-packages\\websocket\\_socket.py\", line 122, in recv\n    raise WebSocketConnectionClosedException(\nwebsocket._exceptions.WebSocketConnectionClosedException: Connection to remote host was lost.\n\nDuring handling of the above exception, another exception occurred:\n\nTraceback (most recent call last):\n  File \"E:\\paper\\paper\\venv\\Lib\\site-packages\\fyers_apiv3\\FyersWebsocket\\data_ws.py\", line 1333, in __symbol_conversion\n    if symbol_value[3] != \"\":\n       ~~~~~~~~~~~~^^^\nTypeError: 'NoneType' object is not subscriptable","exception_name":"TypeError"}
{"level":"ERROR","location":"[__symbol_conversion:1352] data_ws","message":{"code":-300,"message":"Please provide a valid symbol","s":"error","type":"sub","invalid_symbols":["NSE:SBIN28OCT900CE"]},"timestamp":"2025-10-13 23:02:04,599+0530","service":"FyersDataSocket"}
{"level":"ERROR","location":"[__symbol_conversion:1352] data_ws","message":{"code":-300,"message":"Please provide a valid symbol","s":"error","type":"sub","invalid_symbols":["NSE:SBIN28OCT900CE"]},"timestamp":"2025-10-13 23:10:46,570+0530","service":"FyersDataSocket"}
{"level":"ERROR","location":"[__symbol_conversion:1352] data_ws","message":{"code":-300,"message":"Please provide a valid symbol","s":"error","type":"sub","invalid_symbols":["NSE:SBIN28OCT900CE"]},"timestamp":"2025-10-13 23:25:31,467+0530","service":"FyersDataSocket"}
{"level":"ERROR","location":"[<lambda>:1663] data_ws","message":"Connection to remote host was lost.","timestamp":"2025-10-14 01:00:14,809+0530","service":"FyersDataSocket"}
{"level":"ERROR","location":"[symbol_to_hsmtoken:126] data_ws","message":"('Connection aborted.', ConnectionAbortedError(10053, 'An established connection was aborted by the software in your host machine', None, 10053, None))","timestamp":"2025-10-14 01:00:22,659+0530","service":"FyersDataSocket","exception":"Traceback (most recent call last):\n  File \"E:\\paper\\paper\\venv\\Lib\\site-packages\\websocket\\_app.py\", line 428, in setSock\n    dispatcher.read(self.sock.sock, read, check)\n  File \"E:\\paper\\paper\\venv\\Lib\\site-packages\\websocket\\_app.py\", line 99, in read\n    if not read_callback():\n           ^^^^^^^^^^^^^^^\n  File \"E:\\paper\\paper\\venv\\Lib\\site-packages\\websocket\\_app.py\", line 442, in read\n    raise e\n  File \"E:\\paper\\paper\\venv\\Lib\\site-packages\\websocket\\_app.py\", line 437, in read\n    op_code, frame = self.sock.recv_data_frame(True)\n                     ^^^^^^^^^^^^^^^^^^^^^^^^^^^^^^^\n  File \"E:\\paper\\paper\\venv\\Lib\\site-packages\\websocket\\_core.py\", line 406, in recv_data_frame\n    frame = self.recv_frame()\n            ^^^^^^^^^^^^^^^^^\n  File \"E:\\paper\\paper\\venv\\Lib\\site-packages\\websocket\\_core.py\", line 445, in recv_frame\n    return self.frame_buffer.recv_frame()\n           ^^^^^^^^^^^^^^^^^^^^^^^^^^^^^^\n  File \"E:\\paper\\paper\\venv\\Lib\\site-packages\\websocket\\_abnf.py\", line 338, in recv_frame\n    self.recv_header()\n  File \"E:\\paper\\paper\\venv\\Lib\\site-packages\\websocket\\_abnf.py\", line 294, in recv_header\n    header = self.recv_strict(2)\n             ^^^^^^^^^^^^^^^^^^^\n  File \"E:\\paper\\paper\\venv\\Lib\\site-packages\\websocket\\_abnf.py\", line 373, in recv_strict\n    bytes_ = self.recv(min(16384, shortage))\n             ^^^^^^^^^^^^^^^^^^^^^^^^^^^^^^^\n  File \"E:\\paper\\paper\\venv\\Lib\\site-packages\\websocket\\_core.py\", line 529, in _recv\n    return recv(self.sock, bufsize)\n           ^^^^^^^^^^^^^^^^^^^^^^^^\n  File \"E:\\paper\\paper\\venv\\Lib\\site-packages\\websocket\\_socket.py\", line 122, in recv\n    raise WebSocketConnectionClosedException(\nwebsocket._exceptions.WebSocketConnectionClosedException: Connection to remote host was lost.\n\nDuring handling of the above exception, another exception occurred:\n\nTraceback (most recent call last):\n  File \"E:\\paper\\paper\\venv\\Lib\\site-packages\\urllib3\\connectionpool.py\", line 716, in urlopen\n    httplib_response = self._make_request(\n                       ^^^^^^^^^^^^^^^^^^^\n  File \"E:\\paper\\paper\\venv\\Lib\\site-packages\\urllib3\\connectionpool.py\", line 404, in _make_request\n    self._validate_conn(conn)\n  File \"E:\\paper\\paper\\venv\\Lib\\site-packages\\urllib3\\connectionpool.py\", line 1061, in _validate_conn\n    conn.connect()\n  File \"E:\\paper\\paper\\venv\\Lib\\site-packages\\urllib3\\connection.py\", line 419, in connect\n    self.sock = ssl_wrap_socket(\n                ^^^^^^^^^^^^^^^^\n  File \"E:\\paper\\paper\\venv\\Lib\\site-packages\\urllib3\\util\\ssl_.py\", line 458, in ssl_wrap_socket\n    ssl_sock = _ssl_wrap_socket_impl(\n               ^^^^^^^^^^^^^^^^^^^^^^\n  File \"E:\\paper\\paper\\venv\\Lib\\site-packages\\urllib3\\util\\ssl_.py\", line 502, in _ssl_wrap_socket_impl\n    return ssl_context.wrap_socket(sock, server_hostname=server_hostname)\n           ^^^^^^^^^^^^^^^^^^^^^^^^^^^^^^^^^^^^^^^^^^^^^^^^^^^^^^^^^^^^^^\n  File \"C:\\Users\\hp\\AppData\\Local\\Programs\\Python\\Python312\\Lib\\ssl.py\", line 455, in wrap_socket\n    return self.sslsocket_class._create(\n           ^^^^^^^^^^^^^^^^^^^^^^^^^^^^^\n  File \"C:\\Users\\hp\\AppData\\Local\\Programs\\Python\\Python312\\Lib\\ssl.py\", line 1046, in _create\n    self.do_handshake()\n  File \"C:\\Users\\hp\\AppData\\Local\\Programs\\Python\\Python312\\Lib\\ssl.py\", line 1321, in do_handshake\n    self._sslobj.do_handshake()\nConnectionAbortedError: [WinError 10053] An established connection was aborted by the software in your host machine\n\nDuring handling of the above exception, another exception occurred:\n\nTraceback (most recent call last):\n  File \"E:\\paper\\paper\\venv\\Lib\\site-packages\\requests\\adapters.py\", line 486, in send\n    resp = conn.urlopen(\n           ^^^^^^^^^^^^^\n  File \"E:\\paper\\paper\\venv\\Lib\\site-packages\\urllib3\\connectionpool.py\", line 802, in urlopen\n    retries = retries.increment(\n              ^^^^^^^^^^^^^^^^^^\n  File \"E:\\paper\\paper\\venv\\Lib\\site-packages\\urllib3\\util\\retry.py\", line 552, in increment\n    raise six.reraise(type(error), error, _stacktrace)\n          ^^^^^^^^^^^^^^^^^^^^^^^^^^^^^^^^^^^^^^^^^^^^\n  File \"E:\\paper\\paper\\venv\\Lib\\site-packages\\urllib3\\packages\\six.py\", line 769, in reraise\n    raise value.with_traceback(tb)\n  File \"E:\\paper\\paper\\venv\\Lib\\site-packages\\urllib3\\connectionpool.py\", line 716, in urlopen\n    httplib_response = self._make_request(\n                       ^^^^^^^^^^^^^^^^^^^\n  File \"E:\\paper\\paper\\venv\\Lib\\site-packages\\urllib3\\connectionpool.py\", line 404, in _make_request\n    self._validate_conn(conn)\n  File \"E:\\paper\\paper\\venv\\Lib\\site-packages\\urllib3\\connectionpool.py\", line 1061, in _validate_conn\n    conn.connect()\n  File \"E:\\paper\\paper\\venv\\Lib\\site-packages\\urllib3\\connection.py\", line 419, in connect\n    self.sock = ssl_wrap_socket(\n                ^^^^^^^^^^^^^^^^\n  File \"E:\\paper\\paper\\venv\\Lib\\site-packages\\urllib3\\util\\ssl_.py\", line 458, in ssl_wrap_socket\n    ssl_sock = _ssl_wrap_socket_impl(\n               ^^^^^^^^^^^^^^^^^^^^^^\n  File \"E:\\paper\\paper\\venv\\Lib\\site-packages\\urllib3\\util\\ssl_.py\", line 502, in _ssl_wrap_socket_impl\n    return ssl_context.wrap_socket(sock, server_hostname=server_hostname)\n           ^^^^^^^^^^^^^^^^^^^^^^^^^^^^^^^^^^^^^^^^^^^^^^^^^^^^^^^^^^^^^^\n  File \"C:\\Users\\hp\\AppData\\Local\\Programs\\Python\\Python312\\Lib\\ssl.py\", line 455, in wrap_socket\n    return self.sslsocket_class._create(\n           ^^^^^^^^^^^^^^^^^^^^^^^^^^^^^\n  File \"C:\\Users\\hp\\AppData\\Local\\Programs\\Python\\Python312\\Lib\\ssl.py\", line 1046, in _create\n    self.do_handshake()\n  File \"C:\\Users\\hp\\AppData\\Local\\Programs\\Python\\Python312\\Lib\\ssl.py\", line 1321, in do_handshake\n    self._sslobj.do_handshake()\nurllib3.exceptions.ProtocolError: ('Connection aborted.', ConnectionAbortedError(10053, 'An established connection was aborted by the software in your host machine', None, 10053, None))\n\nDuring handling of the above exception, another exception occurred:\n\nTraceback (most recent call last):\n  File \"E:\\paper\\paper\\venv\\Lib\\site-packages\\fyers_apiv3\\FyersWebsocket\\data_ws.py\", line 63, in symbol_to_hsmtoken\n    response = requests.post(\n               ^^^^^^^^^^^^^^\n  File \"E:\\paper\\paper\\venv\\Lib\\site-packages\\requests\\api.py\", line 115, in post\n    return request(\"post\", url, data=data, json=json, **kwargs)\n           ^^^^^^^^^^^^^^^^^^^^^^^^^^^^^^^^^^^^^^^^^^^^^^^^^^^^\n  File \"E:\\paper\\paper\\venv\\Lib\\site-packages\\requests\\api.py\", line 59, in request\n    return session.request(method=method, url=url, **kwargs)\n           ^^^^^^^^^^^^^^^^^^^^^^^^^^^^^^^^^^^^^^^^^^^^^^^^^\n  File \"E:\\paper\\paper\\venv\\Lib\\site-packages\\requests\\sessions.py\", line 589, in request\n    resp = self.send(prep, **send_kwargs)\n           ^^^^^^^^^^^^^^^^^^^^^^^^^^^^^^\n  File \"E:\\paper\\paper\\venv\\Lib\\site-packages\\requests\\sessions.py\", line 703, in send\n    r = adapter.send(request, **kwargs)\n        ^^^^^^^^^^^^^^^^^^^^^^^^^^^^^^^\n  File \"E:\\paper\\paper\\venv\\Lib\\site-packages\\requests\\adapters.py\", line 501, in send\n    raise ConnectionError(err, request=request)\nrequests.exceptions.ConnectionError: ('Connection aborted.', ConnectionAbortedError(10053, 'An established connection was aborted by the software in your host machine', None, 10053, None))","exception_name":"ConnectionError"}
{"level":"ERROR","location":"[__symbol_conversion:1374] data_ws","message":"'NoneType' object is not subscriptable","timestamp":"2025-10-14 01:00:22,721+0530","service":"FyersDataSocket","exception":"Traceback (most recent call last):\n  File \"E:\\paper\\paper\\venv\\Lib\\site-packages\\websocket\\_app.py\", line 428, in setSock\n    dispatcher.read(self.sock.sock, read, check)\n  File \"E:\\paper\\paper\\venv\\Lib\\site-packages\\websocket\\_app.py\", line 99, in read\n    if not read_callback():\n           ^^^^^^^^^^^^^^^\n  File \"E:\\paper\\paper\\venv\\Lib\\site-packages\\websocket\\_app.py\", line 442, in read\n    raise e\n  File \"E:\\paper\\paper\\venv\\Lib\\site-packages\\websocket\\_app.py\", line 437, in read\n    op_code, frame = self.sock.recv_data_frame(True)\n                     ^^^^^^^^^^^^^^^^^^^^^^^^^^^^^^^\n  File \"E:\\paper\\paper\\venv\\Lib\\site-packages\\websocket\\_core.py\", line 406, in recv_data_frame\n    frame = self.recv_frame()\n            ^^^^^^^^^^^^^^^^^\n  File \"E:\\paper\\paper\\venv\\Lib\\site-packages\\websocket\\_core.py\", line 445, in recv_frame\n    return self.frame_buffer.recv_frame()\n           ^^^^^^^^^^^^^^^^^^^^^^^^^^^^^^\n  File \"E:\\paper\\paper\\venv\\Lib\\site-packages\\websocket\\_abnf.py\", line 338, in recv_frame\n    self.recv_header()\n  File \"E:\\paper\\paper\\venv\\Lib\\site-packages\\websocket\\_abnf.py\", line 294, in recv_header\n    header = self.recv_strict(2)\n             ^^^^^^^^^^^^^^^^^^^\n  File \"E:\\paper\\paper\\venv\\Lib\\site-packages\\websocket\\_abnf.py\", line 373, in recv_strict\n    bytes_ = self.recv(min(16384, shortage))\n             ^^^^^^^^^^^^^^^^^^^^^^^^^^^^^^^\n  File \"E:\\paper\\paper\\venv\\Lib\\site-packages\\websocket\\_core.py\", line 529, in _recv\n    return recv(self.sock, bufsize)\n           ^^^^^^^^^^^^^^^^^^^^^^^^\n  File \"E:\\paper\\paper\\venv\\Lib\\site-packages\\websocket\\_socket.py\", line 122, in recv\n    raise WebSocketConnectionClosedException(\nwebsocket._exceptions.WebSocketConnectionClosedException: Connection to remote host was lost.\n\nDuring handling of the above exception, another exception occurred:\n\nTraceback (most recent call last):\n  File \"E:\\paper\\paper\\venv\\Lib\\site-packages\\fyers_apiv3\\FyersWebsocket\\data_ws.py\", line 1333, in __symbol_conversion\n    if symbol_value[3] != \"\":\n       ~~~~~~~~~~~~^^^\nTypeError: 'NoneType' object is not subscriptable","exception_name":"TypeError"}
{"level":"ERROR","location":"[<lambda>:1663] data_ws","message":"Connection to remote host was lost.","timestamp":"2025-10-14 01:33:03,757+0530","service":"FyersDataSocket"}
{"level":"ERROR","location":"[__symbol_conversion:1352] data_ws","message":{"code":-300,"message":"Please provide a valid symbol","s":"error","type":"sub","invalid_symbols":["NSE:SBIN28OCT900CE"]},"timestamp":"2025-10-14 01:33:11,099+0530","service":"FyersDataSocket"}
{"level":"ERROR","location":"[__symbol_conversion:1352] data_ws","message":{"code":-300,"message":"Please provide a valid symbol","s":"error","type":"sub","invalid_symbols":["NSE:SBIN28OCT900CE"]},"timestamp":"2025-10-14 01:37:27,186+0530","service":"FyersDataSocket"}
{"level":"ERROR","location":"[__symbol_conversion:1352] data_ws","message":{"code":-300,"message":"Please provide a valid symbol","s":"error","type":"sub","invalid_symbols":["NSE:SBIN28OCT900CE"]},"timestamp":"2025-10-14 02:01:12,665+0530","service":"FyersDataSocket"}
{"level":"ERROR","location":"[__symbol_conversion:1352] data_ws","message":{"code":-300,"message":"Please provide a valid symbol","s":"error","type":"sub","invalid_symbols":["NSE:SBIN28OCT900CE"]},"timestamp":"2025-10-14 02:13:02,104+0530","service":"FyersDataSocket"}
{"level":"ERROR","location":"[__symbol_conversion:1352] data_ws","message":{"code":-300,"message":"Please provide a valid symbol","s":"error","type":"sub","invalid_symbols":["NSE:SBIN28OCT900CE"]},"timestamp":"2025-10-14 02:15:55,791+0530","service":"FyersDataSocket"}
{"level":"ERROR","location":"[__symbol_conversion:1352] data_ws","message":{"code":-300,"message":"Please provide a valid symbol","s":"error","type":"sub","invalid_symbols":["NSE:SBIN28OCT900CE"]},"timestamp":"2025-10-14 02:19:11,489+0530","service":"FyersDataSocket"}
{"level":"ERROR","location":"[__symbol_conversion:1352] data_ws","message":{"code":-300,"message":"Please provide a valid symbol","s":"error","type":"sub","invalid_symbols":["NSE:SBIN28OCT900CE"]},"timestamp":"2025-10-14 02:21:01,595+0530","service":"FyersDataSocket"}
{"level":"ERROR","location":"[<lambda>:1663] data_ws","message":"EOF occurred in violation of protocol (_ssl.c:2406)","timestamp":"2025-10-14 02:40:34,545+0530","service":"FyersDataSocket"}
{"level":"ERROR","location":"[__symbol_conversion:1352] data_ws","message":{"code":-300,"message":"Please provide a valid symbol","s":"error","type":"sub","invalid_symbols":["NSE:SBIN28OCT900CE"]},"timestamp":"2025-10-14 02:40:42,132+0530","service":"FyersDataSocket"}
{"level":"ERROR","location":"[__symbol_conversion:1352] data_ws","message":{"code":-300,"message":"Please provide a valid symbol","s":"error","type":"sub","invalid_symbols":["NSE:SBIN28OCT900CE"]},"timestamp":"2025-10-14 22:27:32,496+0530","service":"FyersDataSocket"}
{"level":"ERROR","location":"[__symbol_conversion:1352] data_ws","message":{"code":-300,"message":"Please provide a valid symbol","s":"error","type":"sub","invalid_symbols":["NSE:SBIN28OCT900CE"]},"timestamp":"2025-10-14 22:56:01,631+0530","service":"FyersDataSocket"}
{"level":"ERROR","location":"[__symbol_conversion:1352] data_ws","message":{"code":-300,"message":"Please provide a valid symbol","s":"error","type":"sub","invalid_symbols":["NSE:SBIN28OCT900CE"]},"timestamp":"2025-10-14 23:15:41,529+0530","service":"FyersDataSocket"}
{"level":"ERROR","location":"[__symbol_conversion:1352] data_ws","message":{"code":-300,"message":"Please provide a valid symbol","s":"error","type":"sub","invalid_symbols":["NSE:SBIN28OCT900CE"]},"timestamp":"2025-10-14 23:24:37,657+0530","service":"FyersDataSocket"}
{"level":"ERROR","location":"[__symbol_conversion:1352] data_ws","message":{"code":-300,"message":"Please provide a valid symbol","s":"error","type":"sub","invalid_symbols":["NSE:SBIN28OCT900CE"]},"timestamp":"2025-10-14 23:33:08,067+0530","service":"FyersDataSocket"}
{"level":"ERROR","location":"[__symbol_conversion:1352] data_ws","message":{"code":-300,"message":"Please provide a valid symbol","s":"error","type":"sub","invalid_symbols":["NSE:SBIN28OCT900CE"]},"timestamp":"2025-10-14 23:38:59,391+0530","service":"FyersDataSocket"}
{"level":"ERROR","location":"[__symbol_conversion:1352] data_ws","message":{"code":-300,"message":"Please provide a valid symbol","s":"error","type":"sub","invalid_symbols":["NSE:SBIN28OCT900CE"]},"timestamp":"2025-10-15 02:30:28,453+0530","service":"FyersDataSocket"}
{"level":"ERROR","location":"[__symbol_conversion:1352] data_ws","message":{"code":-300,"message":"Please provide a valid symbol","s":"error","type":"sub","invalid_symbols":["NSE:RELIANCE24SEPFUT"]},"timestamp":"2025-10-15 02:31:26,897+0530","service":"FyersDataSocket"}
{"level":"ERROR","location":"[__symbol_conversion:1352] data_ws","message":{"code":-300,"message":"Please provide a valid symbol","s":"error","type":"sub","invalid_symbols":["NSE:ADANIPOWER25DECFUT"]},"timestamp":"2025-10-15 03:03:58,698+0530","service":"FyersDataSocket"}
{"level":"ERROR","location":"[__symbol_conversion:1352] data_ws","message":{"code":-300,"message":"Please provide a valid symbol","s":"error","type":"sub","invalid_symbols":["NSE:TATACOMM25DECFUT","NSE:UBL25DECFUT","NSE:BERGEPAINT25DECFUT","NSE:ABBOTINDIA25DECFUT","NSE:GUJGASLTD25DECFUT","NSE:IGL25DECFUT","NSE:SOBHA25DECFUT","NSE:TATACHEM25DECFUT","NSE:DEEPAKNTR25DECFUT","NSE:CANFINHOME25DECFUT","NSE:JSWINFRA25DECFUT","NSE:IRB25DECFUT","NSE:SJVN25DECFUT","NSE:BLUEDART25DECFUT","NSE:ABFRL25DECFUT","NSE:FLUOROCHEM25DECFUT","NSE:ESCORTS25DECFUT","NSE:COROMANDEL25DECFUT","NSE:ATUL25DECFUT","NSE:GLAND25DECFUT","NSE:METROPOLIS25DECFUT","NSE:MEDANTA25DECFUT","NSE:RAIN25DECFUT","NSE:ASTERDM25DECFUT","NSE:SUNTV25DECFUT","NSE:ZEEL25DECFUT","NSE:PVRINOX25DECFUT","NSE:BALRAMCHIN25DECFUT","NSE:RAJESHEXPO25DECFUT","NSE:ACC25DECFUT","NSE:JKCEMENT25DECFUT"]},"timestamp":"2025-10-15 03:05:29,091+0530","service":"FyersDataSocket"}
{"level":"ERROR","location":"[__symbol_conversion:1352] data_ws","message":{"code":-300,"message":"Please provide a valid symbol","s":"error","type":"sub","invalid_symbols":["NSE:ACC25DECFUT"]},"timestamp":"2025-10-15 03:12:11,410+0530","service":"FyersDataSocket"}
{"level":"ERROR","location":"[__symbol_conversion:1352] data_ws","message":{"code":-300,"message":"Please provide a valid symbol","s":"error","type":"sub","invalid_symbols":["NSE:NIFTY25DEC49000CE"]},"timestamp":"2025-10-15 03:14:52,730+0530","service":"FyersDataSocket"}
{"level":"ERROR","location":"[__symbol_conversion:1352] data_ws","message":{"code":-300,"message":"Please provide a valid symbol","s":"error","type":"sub","invalid_symbols":["NSE:NIFTY25OCT49000CE"]},"timestamp":"2025-10-15 03:15:43,610+0530","service":"FyersDataSocket"}
{"level":"ERROR","location":"[__symbol_conversion:1352] data_ws","message":{"code":-300,"message":"Please provide a valid symbol","s":"error","type":"sub","invalid_symbols":["NSE:NIFTY20OCT49000CE"]},"timestamp":"2025-10-15 03:16:25,914+0530","service":"FyersDataSocket"}
{"level":"ERROR","location":"[__symbol_conversion:1352] data_ws","message":{"code":-300,"message":"Please provide a valid symbol","s":"error","type":"sub","invalid_symbols":["NSE:NIFTY28OCT49000CE"]},"timestamp":"2025-10-15 03:17:20,374+0530","service":"FyersDataSocket"}
{"level":"ERROR","location":"[__symbol_conversion:1352] data_ws","message":{"code":-300,"message":"Please provide a valid symbol","s":"error","type":"sub","invalid_symbols":["NSE:BANKNIFTY28OCT49000CE"]},"timestamp":"2025-10-15 03:19:02,861+0530","service":"FyersDataSocket"}
{"level":"ERROR","location":"[__symbol_conversion:1352] data_ws","message":{"code":-300,"message":"Please provide a valid symbol","s":"error","type":"sub","invalid_symbols":["NSE:FINNIFTY25OCT12000CE","NSE:FINNIFTY25OCT12500CE","NSE:FINNIFTY25OCT13000CE","NSE:FINNIFTY25OCT12000PE","NSE:FINNIFTY25OCT12500PE","NSE:FINNIFTY25OCT13000PE","NSE:RELIANCE25OCT2800CE","NSE:RELIANCE25OCT2900CE","NSE:RELIANCE25OCT3000CE","NSE:RELIANCE25OCT3100CE","NSE:RELIANCE25OCT2800PE","NSE:RELIANCE25OCT2900PE","NSE:RELIANCE25OCT3000PE","NSE:RELIANCE25OCT3100PE","NSE:HDFCBANK25OCT1600CE","NSE:HDFCBANK25OCT1650CE","NSE:HDFCBANK25OCT1700CE","NSE:HDFCBANK25OCT1600PE","NSE:HDFCBANK25OCT1650PE","NSE:HDFCBANK25OCT1700PE","NSE:BAJFINANCE25OCT7000CE","NSE:BAJFINANCE25OCT7500CE","NSE:BAJFINANCE25OCT8000CE","NSE:BAJFINANCE25OCT7000PE","NSE:BAJFINANCE25OCT7500PE","NSE:BAJFINANCE25OCT8000PE","NSE:RELIANCE25NOV3000CE","NSE:RELIANCE25NOV3200CE","NSE:RELIANCE25NOV3000PE","NSE:HDFCBANK25NOV1700CE","NSE:HDFCBANK25NOV1800CE","NSE:HDFCBANK25NOV1700PE","NSE:WIPRO25OCT400CE","NSE:WIPRO25OCT450CE","NSE:WIPRO25OCT500CE","NSE:WIPRO25OCT400PE","NSE:WIPRO25OCT450PE","NSE:WIPRO25OCT500PE"]},"timestamp":"2025-10-15 03:33:43,449+0530","service":"FyersDataSocket"}
{"level":"ERROR","location":"[__symbol_conversion:1352] data_ws","message":{"code":-300,"message":"Please provide a valid symbol","s":"error","type":"sub","invalid_symbols":["NSE:TATAMOTORS25OCT650CE","NSE:TATAMOTORS25OCT650PE"]},"timestamp":"2025-10-15 19:47:54,707+0530","service":"FyersDataSocket"}
{"level":"ERROR","location":"[<lambda>:1663] data_ws","message":"Connection to remote host was lost.","timestamp":"2025-10-15 19:59:53,057+0530","service":"FyersDataSocket"}
{"level":"ERROR","location":"[__symbol_conversion:1352] data_ws","message":{"code":-300,"message":"Please provide a valid symbol","s":"error","type":"sub","invalid_symbols":["NSE:TATAMOTORS25OCT650CE","NSE:TATAMOTORS25OCT650PE"]},"timestamp":"2025-10-15 20:00:01,039+0530","service":"FyersDataSocket"}
{"level":"ERROR","location":"[__symbol_conversion:1352] data_ws","message":{"code":-300,"message":"Please provide a valid symbol","s":"error","type":"sub","invalid_symbols":["NSE:TATAMOTORS25OCT650CE","NSE:TATAMOTORS25OCT650PE"]},"timestamp":"2025-10-15 20:01:41,069+0530","service":"FyersDataSocket"}
{"level":"ERROR","location":"[__symbol_conversion:1352] data_ws","message":{"code":-300,"message":"Please provide a valid symbol","s":"error","type":"sub","invalid_symbols":["NSE:TATAMOTORS25OCT650CE","NSE:TATAMOTORS25OCT650PE"]},"timestamp":"2025-10-15 20:02:48,280+0530","service":"FyersDataSocket"}
{"level":"ERROR","location":"[__symbol_conversion:1352] data_ws","message":{"code":-300,"message":"Please provide a valid symbol","s":"error","type":"sub","invalid_symbols":["NSE:TATAMOTORS25OCT650CE","NSE:TATAMOTORS25OCT650PE"]},"timestamp":"2025-10-15 20:03:39,777+0530","service":"FyersDataSocket"}
{"level":"ERROR","location":"[__symbol_conversion:1352] data_ws","message":{"code":-300,"message":"Please provide a valid symbol","s":"error","type":"sub","invalid_symbols":["NSE:TATAMOTORS25OCT650CE","NSE:TATAMOTORS25OCT650PE"]},"timestamp":"2025-10-15 20:04:47,613+0530","service":"FyersDataSocket"}
{"level":"ERROR","location":"[<lambda>:1663] data_ws","message":"Connection to remote host was lost.","timestamp":"2025-10-15 21:21:05,192+0530","service":"FyersDataSocket"}
{"level":"ERROR","location":"[__symbol_conversion:1352] data_ws","message":{"code":-300,"message":"Please provide a valid symbol","s":"error","type":"sub","invalid_symbols":["NSE:TATAMOTORS25OCT650CE","NSE:TATAMOTORS25OCT650PE"]},"timestamp":"2025-10-15 21:21:12,634+0530","service":"FyersDataSocket"}
{"level":"ERROR","location":"[__symbol_conversion:1352] data_ws","message":{"code":-300,"message":"Please provide a valid symbol","s":"error","type":"sub","invalid_symbols":["NSE:TATAMOTORS25OCT650CE","NSE:TATAMOTORS25OCT650PE"]},"timestamp":"2025-10-15 21:21:39,893+0530","service":"FyersDataSocket"}
{"level":"ERROR","location":"[__symbol_conversion:1352] data_ws","message":{"code":-300,"message":"Please provide a valid symbol","s":"error","type":"sub","invalid_symbols":["NSE:TATAMOTORS25OCT650CE","NSE:TATAMOTORS25OCT650PE"]},"timestamp":"2025-10-15 22:02:13,152+0530","service":"FyersDataSocket"}
{"level":"ERROR","location":"[__symbol_conversion:1352] data_ws","message":{"code":-300,"message":"Please provide a valid symbol","s":"error","type":"sub","invalid_symbols":["NSE:TATAMOTORS25OCT650CE","NSE:TATAMOTORS25OCT650PE"]},"timestamp":"2025-10-15 22:16:17,621+0530","service":"FyersDataSocket"}
{"level":"ERROR","location":"[__symbol_conversion:1352] data_ws","message":{"code":-300,"message":"Please provide a valid symbol","s":"error","type":"sub","invalid_symbols":["NSE:TATAMOTORS25OCT650CE","NSE:TATAMOTORS25OCT650PE"]},"timestamp":"2025-10-15 22:22:17,235+0530","service":"FyersDataSocket"}
{"level":"ERROR","location":"[__symbol_conversion:1352] data_ws","message":{"code":-300,"message":"Please provide a valid symbol","s":"error","type":"sub","invalid_symbols":["NSE:TATAMOTORS25OCT650CE","NSE:TATAMOTORS25OCT650PE"]},"timestamp":"2025-10-15 22:30:44,356+0530","service":"FyersDataSocket"}
{"level":"ERROR","location":"[__symbol_conversion:1352] data_ws","message":{"code":-300,"message":"Please provide a valid symbol","s":"error","type":"sub","invalid_symbols":["NSE:TATAMOTORS25OCT650CE","NSE:TATAMOTORS25OCT650PE"]},"timestamp":"2025-10-15 22:40:15,953+0530","service":"FyersDataSocket"}
{"level":"ERROR","location":"[__symbol_conversion:1352] data_ws","message":{"code":-300,"message":"Please provide a valid symbol","s":"error","type":"sub","invalid_symbols":["NSE:TATAMOTORS25OCT650CE","NSE:TATAMOTORS25OCT650PE"]},"timestamp":"2025-10-15 22:45:36,297+0530","service":"FyersDataSocket"}
{"level":"ERROR","location":"[__symbol_conversion:1352] data_ws","message":{"code":-300,"message":"Please provide a valid symbol","s":"error","type":"sub","invalid_symbols":["NSE:TATAMOTORS25OCT650CE","NSE:TATAMOTORS25OCT650PE"]},"timestamp":"2025-10-15 22:50:38,764+0530","service":"FyersDataSocket"}
{"level":"ERROR","location":"[__symbol_conversion:1352] data_ws","message":{"code":-300,"message":"Please provide a valid symbol","s":"error","type":"sub","invalid_symbols":["NSE:TATAMOTORS25OCT650CE","NSE:TATAMOTORS25OCT650PE"]},"timestamp":"2025-10-15 23:29:51,223+0530","service":"FyersDataSocket"}
{"level":"ERROR","location":"[__symbol_conversion:1352] data_ws","message":{"code":-300,"message":"Please provide a valid symbol","s":"error","type":"sub","invalid_symbols":["NSE:TATAMOTORS25OCT650CE","NSE:TATAMOTORS25OCT650PE"]},"timestamp":"2025-10-15 23:30:46,098+0530","service":"FyersDataSocket"}
{"level":"ERROR","location":"[__symbol_conversion:1352] data_ws","message":{"code":-300,"message":"Please provide a valid symbol","s":"error","type":"sub","invalid_symbols":["NSE:TATAMOTORS25OCT650CE","NSE:TATAMOTORS25OCT650PE"]},"timestamp":"2025-10-15 23:47:05,195+0530","service":"FyersDataSocket"}
{"level":"ERROR","location":"[__symbol_conversion:1352] data_ws","message":{"code":-300,"message":"Please provide a valid symbol","s":"error","type":"sub","invalid_symbols":["NSE:TATAMOTORS25OCT650CE","NSE:TATAMOTORS25OCT650PE"]},"timestamp":"2025-10-15 23:48:20,547+0530","service":"FyersDataSocket"}
{"level":"ERROR","location":"[__symbol_conversion:1352] data_ws","message":{"code":-300,"message":"Please provide a valid symbol","s":"error","type":"sub","invalid_symbols":["NSE:TATAMOTORS25OCT650CE","NSE:TATAMOTORS25OCT650PE"]},"timestamp":"2025-10-16 00:32:20,492+0530","service":"FyersDataSocket"}
{"level":"ERROR","location":"[__symbol_conversion:1352] data_ws","message":{"code":-300,"message":"Please provide a valid symbol","s":"error","type":"sub","invalid_symbols":["NSE:TATAMOTORS25OCT650CE","NSE:TATAMOTORS25OCT650PE"]},"timestamp":"2025-10-16 00:34:41,610+0530","service":"FyersDataSocket"}
{"level":"ERROR","location":"[<lambda>:1663] data_ws","message":"Connection to remote host was lost.","timestamp":"2025-10-16 03:06:59,383+0530","service":"FyersDataSocket"}
{"level":"ERROR","location":"[__symbol_conversion:1352] data_ws","message":{"code":-300,"message":"Please provide a valid symbol","s":"error","type":"sub","invalid_symbols":["NSE:TATAMOTORS25OCT650CE","NSE:TATAMOTORS25OCT650PE"]},"timestamp":"2025-10-16 03:07:08,825+0530","service":"FyersDataSocket"}
{"level":"ERROR","location":"[<lambda>:1663] data_ws","message":"Connection to remote host was lost.","timestamp":"2025-10-16 04:06:35,005+0530","service":"FyersDataSocket"}
{"level":"ERROR","location":"[__symbol_conversion:1352] data_ws","message":{"code":-300,"message":"Please provide a valid symbol","s":"error","type":"sub","invalid_symbols":["NSE:TATAMOTORS25OCT650CE","NSE:TATAMOTORS25OCT650PE"]},"timestamp":"2025-10-16 04:06:46,166+0530","service":"FyersDataSocket"}
{"level":"ERROR","location":"[__symbol_conversion:1352] data_ws","message":{"code":-300,"message":"Please provide a valid symbol","s":"error","type":"sub","invalid_symbols":["NSE:TATAMOTORS25OCT650CE","NSE:TATAMOTORS25OCT650PE"]},"timestamp":"2025-10-16 11:20:54,853+0530","service":"FyersDataSocket"}
{"level":"ERROR","location":"[__symbol_conversion:1352] data_ws","message":{"code":-300,"message":"Please provide a valid symbol","s":"error","type":"sub","invalid_symbols":["NSE:TATAMOTORS25OCT650CE","NSE:TATAMOTORS25OCT650PE"]},"timestamp":"2025-10-16 11:34:54,419+0530","service":"FyersDataSocket"}
{"level":"ERROR","location":"[__symbol_conversion:1352] data_ws","message":{"code":-300,"message":"Please provide a valid symbol","s":"error","type":"sub","invalid_symbols":["NSE:TATAMOTORS25OCT650CE","NSE:TATAMOTORS25OCT650PE"]},"timestamp":"2025-10-16 11:38:58,020+0530","service":"FyersDataSocket"}
{"level":"ERROR","location":"[__symbol_conversion:1352] data_ws","message":{"code":-300,"message":"Please provide a valid symbol","s":"error","type":"sub","invalid_symbols":["NSE:TATAMOTORS25OCT650CE","NSE:TATAMOTORS25OCT650PE"]},"timestamp":"2025-10-16 11:46:27,655+0530","service":"FyersDataSocket"}
{"level":"ERROR","location":"[__symbol_conversion:1352] data_ws","message":{"code":-300,"message":"Please provide a valid symbol","s":"error","type":"sub","invalid_symbols":["NSE:TATAMOTORS25OCT650CE","NSE:TATAMOTORS25OCT650PE"]},"timestamp":"2025-10-16 11:51:36,107+0530","service":"FyersDataSocket"}
{"level":"ERROR","location":"[__symbol_conversion:1352] data_ws","message":{"code":-300,"message":"Please provide a valid symbol","s":"error","type":"sub","invalid_symbols":["NSE:TATAMOTORS25OCT650CE","NSE:TATAMOTORS25OCT650PE"]},"timestamp":"2025-10-16 11:58:37,581+0530","service":"FyersDataSocket"}
{"level":"ERROR","location":"[__symbol_conversion:1352] data_ws","message":{"code":-300,"message":"Please provide a valid symbol","s":"error","type":"sub","invalid_symbols":["NSE:TATAMOTORS25OCT650CE","NSE:TATAMOTORS25OCT650PE"]},"timestamp":"2025-10-16 12:00:42,924+0530","service":"FyersDataSocket"}
{"level":"ERROR","location":"[__symbol_conversion:1352] data_ws","message":{"code":-300,"message":"Please provide a valid symbol","s":"error","type":"sub","invalid_symbols":["NSE:TATAMOTORS25OCT650CE","NSE:TATAMOTORS25OCT650PE"]},"timestamp":"2025-10-16 12:04:57,561+0530","service":"FyersDataSocket"}
{"level":"ERROR","location":"[__symbol_conversion:1352] data_ws","message":{"code":-300,"message":"Please provide a valid symbol","s":"error","type":"sub","invalid_symbols":["NSE:TATAMOTORS25OCT650CE","NSE:TATAMOTORS25OCT650PE"]},"timestamp":"2025-10-16 12:18:15,636+0530","service":"FyersDataSocket"}
{"level":"ERROR","location":"[__symbol_conversion:1352] data_ws","message":{"code":-300,"message":"Please provide a valid symbol","s":"error","type":"sub","invalid_symbols":["NSE:TATAMOTORS25OCT650CE","NSE:TATAMOTORS25OCT650PE"]},"timestamp":"2025-10-16 13:49:18,314+0530","service":"FyersDataSocket"}
{"level":"ERROR","location":"[__symbol_conversion:1352] data_ws","message":{"code":-300,"message":"Please provide a valid symbol","s":"error","type":"sub","invalid_symbols":["NSE:TATAMOTORS25OCT650CE","NSE:TATAMOTORS25OCT650PE"]},"timestamp":"2025-10-16 13:59:34,948+0530","service":"FyersDataSocket"}
{"level":"ERROR","location":"[__symbol_conversion:1352] data_ws","message":{"code":-300,"message":"Please provide a valid symbol","s":"error","type":"sub","invalid_symbols":["NSE:TATAMOTORS25OCT650CE","NSE:TATAMOTORS25OCT650PE"]},"timestamp":"2025-10-16 14:24:04,277+0530","service":"FyersDataSocket"}
{"level":"ERROR","location":"[__symbol_conversion:1352] data_ws","message":{"code":-300,"message":"Please provide a valid symbol","s":"error","type":"sub","invalid_symbols":["NSE:TATAMOTORS25OCT650CE","NSE:TATAMOTORS25OCT650PE"]},"timestamp":"2025-10-16 14:24:26,602+0530","service":"FyersDataSocket"}
{"level":"ERROR","location":"[__symbol_conversion:1352] data_ws","message":{"code":-300,"message":"Please provide a valid symbol","s":"error","type":"sub","invalid_symbols":["NSE:TATAMOTORS25OCT650CE","NSE:TATAMOTORS25OCT650PE"]},"timestamp":"2025-10-16 14:27:55,233+0530","service":"FyersDataSocket"}
{"level":"ERROR","location":"[__symbol_conversion:1352] data_ws","message":{"code":-300,"message":"Please provide a valid symbol","s":"error","type":"sub","invalid_symbols":["NSE:TATAMOTORS25OCT650CE","NSE:TATAMOTORS25OCT650PE"]},"timestamp":"2025-10-16 14:29:20,625+0530","service":"FyersDataSocket"}
{"level":"ERROR","location":"[__symbol_conversion:1352] data_ws","message":{"code":-300,"message":"Please provide a valid symbol","s":"error","type":"sub","invalid_symbols":["NSE:TATAMOTORS25OCT650CE","NSE:TATAMOTORS25OCT650PE"]},"timestamp":"2025-10-16 19:05:13,556+0530","service":"FyersDataSocket"}
{"level":"ERROR","location":"[__symbol_conversion:1352] data_ws","message":{"code":-300,"message":"Please provide a valid symbol","s":"error","type":"sub","invalid_symbols":["NSE:TATAMOTORS25OCT650CE","NSE:TATAMOTORS25OCT650PE"]},"timestamp":"2025-10-16 19:07:47,447+0530","service":"FyersDataSocket"}
{"level":"ERROR","location":"[__symbol_conversion:1352] data_ws","message":{"code":-300,"message":"Please provide a valid symbol","s":"error","type":"sub","invalid_symbols":["NSE:TATAMOTORS25OCT650CE","NSE:TATAMOTORS25OCT650PE"]},"timestamp":"2025-10-16 19:13:55,358+0530","service":"FyersDataSocket"}
{"level":"ERROR","location":"[__symbol_conversion:1352] data_ws","message":{"code":-300,"message":"Please provide a valid symbol","s":"error","type":"sub","invalid_symbols":["NSE:TATAMOTORS25OCT650CE","NSE:TATAMOTORS25OCT650PE"]},"timestamp":"2025-10-16 20:13:25,629+0530","service":"FyersDataSocket"}
{"level":"ERROR","location":"[__symbol_conversion:1352] data_ws","message":{"code":-300,"message":"Please provide a valid symbol","s":"error","type":"sub","invalid_symbols":["NSE:TATAMOTORS25OCT650CE","NSE:TATAMOTORS25OCT650PE"]},"timestamp":"2025-10-16 20:17:20,870+0530","service":"FyersDataSocket"}
{"level":"ERROR","location":"[__symbol_conversion:1352] data_ws","message":{"code":-300,"message":"Please provide a valid symbol","s":"error","type":"sub","invalid_symbols":["NSE:TATAMOTORS25OCT650CE","NSE:TATAMOTORS25OCT650PE"]},"timestamp":"2025-10-16 20:19:39,492+0530","service":"FyersDataSocket"}
{"level":"ERROR","location":"[__symbol_conversion:1352] data_ws","message":{"code":-300,"message":"Please provide a valid symbol","s":"error","type":"sub","invalid_symbols":["NSE:TATAMOTORS25OCT650CE","NSE:TATAMOTORS25OCT650PE"]},"timestamp":"2025-10-16 20:21:04,019+0530","service":"FyersDataSocket"}
{"level":"ERROR","location":"[__symbol_conversion:1352] data_ws","message":{"code":-300,"message":"Please provide a valid symbol","s":"error","type":"sub","invalid_symbols":["NSE:TATAMOTORS25OCT650CE","NSE:TATAMOTORS25OCT650PE"]},"timestamp":"2025-10-16 20:22:44,576+0530","service":"FyersDataSocket"}
{"level":"ERROR","location":"[<lambda>:1663] data_ws","message":"Connection to remote host was lost.","timestamp":"2025-10-16 21:41:52,985+0530","service":"FyersDataSocket"}
{"level":"ERROR","location":"[__symbol_conversion:1352] data_ws","message":{"code":-300,"message":"Please provide a valid symbol","s":"error","type":"sub","invalid_symbols":["NSE:TATAMOTORS25OCT650CE","NSE:TATAMOTORS25OCT650PE"]},"timestamp":"2025-10-16 21:42:00,576+0530","service":"FyersDataSocket"}
{"level":"ERROR","location":"[__symbol_conversion:1352] data_ws","message":{"code":-300,"message":"Please provide a valid symbol","s":"error","type":"sub","invalid_symbols":["NSE:TATAMOTORS25OCT650CE","NSE:TATAMOTORS25OCT650PE"]},"timestamp":"2025-10-16 21:42:22,952+0530","service":"FyersDataSocket"}
{"level":"ERROR","location":"[__symbol_conversion:1352] data_ws","message":{"code":-300,"message":"Please provide a valid symbol","s":"error","type":"sub","invalid_symbols":["NSE:TATAMOTORS25OCT650CE","NSE:TATAMOTORS25OCT650PE"]},"timestamp":"2025-10-16 21:44:04,670+0530","service":"FyersDataSocket"}
{"level":"ERROR","location":"[__symbol_conversion:1352] data_ws","message":{"code":-300,"message":"Please provide a valid symbol","s":"error","type":"sub","invalid_symbols":["NSE:TATAMOTORS25OCT650CE","NSE:TATAMOTORS25OCT650PE"]},"timestamp":"2025-10-16 21:46:46,702+0530","service":"FyersDataSocket"}
{"level":"ERROR","location":"[__symbol_conversion:1352] data_ws","message":{"code":-300,"message":"Please provide a valid symbol","s":"error","type":"sub","invalid_symbols":["NSE:TATAMOTORS25OCT650CE","NSE:TATAMOTORS25OCT650PE"]},"timestamp":"2025-10-16 21:55:18,950+0530","service":"FyersDataSocket"}
{"level":"ERROR","location":"[__symbol_conversion:1352] data_ws","message":{"code":-300,"message":"Please provide a valid symbol","s":"error","type":"sub","invalid_symbols":["NSE:TATAMOTORS25OCT650CE","NSE:TATAMOTORS25OCT650PE"]},"timestamp":"2025-10-16 21:58:05,675+0530","service":"FyersDataSocket"}
{"level":"ERROR","location":"[__symbol_conversion:1352] data_ws","message":{"code":-300,"message":"Please provide a valid symbol","s":"error","type":"sub","invalid_symbols":["NSE:TATAMOTORS25OCT650CE","NSE:TATAMOTORS25OCT650PE"]},"timestamp":"2025-10-16 21:58:42,302+0530","service":"FyersDataSocket"}
{"level":"ERROR","location":"[__symbol_conversion:1352] data_ws","message":{"code":-300,"message":"Please provide a valid symbol","s":"error","type":"sub","invalid_symbols":["NSE:TATAMOTORS25OCT650CE","NSE:TATAMOTORS25OCT650PE"]},"timestamp":"2025-10-16 22:01:48,845+0530","service":"FyersDataSocket"}
{"level":"ERROR","location":"[__symbol_conversion:1352] data_ws","message":{"code":-300,"message":"Please provide a valid symbol","s":"error","type":"sub","invalid_symbols":["NSE:TATAMOTORS25OCT650CE","NSE:TATAMOTORS25OCT650PE"]},"timestamp":"2025-10-16 22:02:36,197+0530","service":"FyersDataSocket"}
{"level":"ERROR","location":"[__symbol_conversion:1352] data_ws","message":{"code":-300,"message":"Please provide a valid symbol","s":"error","type":"sub","invalid_symbols":["NSE:TATAMOTORS25OCT650CE","NSE:TATAMOTORS25OCT650PE"]},"timestamp":"2025-10-16 22:16:39,575+0530","service":"FyersDataSocket"}
{"level":"ERROR","location":"[__symbol_conversion:1352] data_ws","message":{"code":-300,"message":"Please provide a valid symbol","s":"error","type":"sub","invalid_symbols":["NSE:TATAMOTORS25OCT650CE","NSE:TATAMOTORS25OCT650PE"]},"timestamp":"2025-10-16 22:17:17,573+0530","service":"FyersDataSocket"}
{"level":"ERROR","location":"[__symbol_conversion:1352] data_ws","message":{"code":-300,"message":"Please provide a valid symbol","s":"error","type":"sub","invalid_symbols":["NSE:TATAMOTORS25OCT650CE","NSE:TATAMOTORS25OCT650PE"]},"timestamp":"2025-10-17 01:09:59,123+0530","service":"FyersDataSocket"}
{"level":"ERROR","location":"[__symbol_conversion:1352] data_ws","message":{"code":-300,"message":"Please provide a valid symbol","s":"error","type":"sub","invalid_symbols":["NSE:TATAMOTORS25OCT650CE","NSE:TATAMOTORS25OCT650PE"]},"timestamp":"2025-10-17 01:25:29,847+0530","service":"FyersDataSocket"}
{"level":"ERROR","location":"[__symbol_conversion:1352] data_ws","message":{"code":-300,"message":"Please provide a valid symbol","s":"error","type":"sub","invalid_symbols":["NSE:TATAMOTORS25OCT650CE","NSE:TATAMOTORS25OCT650PE"]},"timestamp":"2025-10-17 01:28:17,875+0530","service":"FyersDataSocket"}
{"level":"ERROR","location":"[__symbol_conversion:1352] data_ws","message":{"code":-300,"message":"Please provide a valid symbol","s":"error","type":"sub","invalid_symbols":["NSE:TATAMOTORS25OCT650CE","NSE:TATAMOTORS25OCT650PE"]},"timestamp":"2025-10-17 01:31:08,024+0530","service":"FyersDataSocket"}
{"level":"ERROR","location":"[__symbol_conversion:1352] data_ws","message":{"code":-300,"message":"Please provide a valid symbol","s":"error","type":"sub","invalid_symbols":["NSE:TATAMOTORS25OCT650CE","NSE:TATAMOTORS25OCT650PE"]},"timestamp":"2025-10-17 01:34:33,411+0530","service":"FyersDataSocket"}
{"level":"ERROR","location":"[__symbol_conversion:1352] data_ws","message":{"code":-300,"message":"Please provide a valid symbol","s":"error","type":"sub","invalid_symbols":["NSE:TATAMOTORS25OCT650CE","NSE:TATAMOTORS25OCT650PE"]},"timestamp":"2025-10-17 01:40:32,672+0530","service":"FyersDataSocket"}
{"level":"ERROR","location":"[__symbol_conversion:1352] data_ws","message":{"code":-300,"message":"Please provide a valid symbol","s":"error","type":"sub","invalid_symbols":["NSE:TATAMOTORS25OCT650CE","NSE:TATAMOTORS25OCT650PE"]},"timestamp":"2025-10-17 01:43:09,226+0530","service":"FyersDataSocket"}
{"level":"ERROR","location":"[__symbol_conversion:1352] data_ws","message":{"code":-300,"message":"Please provide a valid symbol","s":"error","type":"sub","invalid_symbols":["NSE:TATAMOTORS25OCT650CE","NSE:TATAMOTORS25OCT650PE"]},"timestamp":"2025-10-17 01:52:25,765+0530","service":"FyersDataSocket"}
{"level":"ERROR","location":"[__symbol_conversion:1352] data_ws","message":{"code":-300,"message":"Please provide a valid symbol","s":"error","type":"sub","invalid_symbols":["NSE:TATAMOTORS25OCT650CE","NSE:TATAMOTORS25OCT650PE"]},"timestamp":"2025-10-17 01:54:07,619+0530","service":"FyersDataSocket"}
{"level":"ERROR","location":"[__symbol_conversion:1352] data_ws","message":{"code":-300,"message":"Please provide a valid symbol","s":"error","type":"sub","invalid_symbols":["NSE:TATAMOTORS25OCT650CE","NSE:TATAMOTORS25OCT650PE"]},"timestamp":"2025-10-17 01:56:09,917+0530","service":"FyersDataSocket"}
{"level":"ERROR","location":"[__symbol_conversion:1352] data_ws","message":{"code":-300,"message":"Please provide a valid symbol","s":"error","type":"sub","invalid_symbols":["NSE:TATAMOTORS25OCT650CE","NSE:TATAMOTORS25OCT650PE"]},"timestamp":"2025-10-17 01:58:09,221+0530","service":"FyersDataSocket"}
{"level":"ERROR","location":"[__symbol_conversion:1352] data_ws","message":{"code":-300,"message":"Please provide a valid symbol","s":"error","type":"sub","invalid_symbols":["NSE:TATAMOTORS25OCT650CE","NSE:TATAMOTORS25OCT650PE"]},"timestamp":"2025-10-17 02:06:33,216+0530","service":"FyersDataSocket"}
{"level":"ERROR","location":"[__symbol_conversion:1352] data_ws","message":{"code":-300,"message":"Please provide a valid symbol","s":"error","type":"sub","invalid_symbols":["NSE:TATAMOTORS25OCT650CE","NSE:TATAMOTORS25OCT650PE"]},"timestamp":"2025-10-17 02:08:52,815+0530","service":"FyersDataSocket"}
{"level":"ERROR","location":"[__symbol_conversion:1352] data_ws","message":{"code":-300,"message":"Please provide a valid symbol","s":"error","type":"sub","invalid_symbols":["NSE:TATAMOTORS25OCT650CE","NSE:TATAMOTORS25OCT650PE"]},"timestamp":"2025-10-17 02:11:19,134+0530","service":"FyersDataSocket"}
{"level":"ERROR","location":"[__symbol_conversion:1352] data_ws","message":{"code":-300,"message":"Please provide a valid symbol","s":"error","type":"sub","invalid_symbols":["NSE:TATAMOTORS25OCT650CE","NSE:TATAMOTORS25OCT650PE"]},"timestamp":"2025-10-17 02:21:23,831+0530","service":"FyersDataSocket"}
{"level":"ERROR","location":"[__symbol_conversion:1352] data_ws","message":{"code":-300,"message":"Please provide a valid symbol","s":"error","type":"sub","invalid_symbols":["NSE:TATAMOTORS25OCT650CE","NSE:TATAMOTORS25OCT650PE"]},"timestamp":"2025-10-17 02:23:21,913+0530","service":"FyersDataSocket"}
{"level":"ERROR","location":"[__symbol_conversion:1352] data_ws","message":{"code":-300,"message":"Please provide a valid symbol","s":"error","type":"sub","invalid_symbols":["NSE:TATAMOTORS25OCT650CE","NSE:TATAMOTORS25OCT650PE"]},"timestamp":"2025-10-17 02:24:44,813+0530","service":"FyersDataSocket"}
{"level":"ERROR","location":"[__symbol_conversion:1352] data_ws","message":{"code":-300,"message":"Please provide a valid symbol","s":"error","type":"sub","invalid_symbols":["NSE:TATAMOTORS25OCT650CE","NSE:TATAMOTORS25OCT650PE"]},"timestamp":"2025-10-17 02:28:26,275+0530","service":"FyersDataSocket"}
{"level":"ERROR","location":"[__symbol_conversion:1352] data_ws","message":{"code":-300,"message":"Please provide a valid symbol","s":"error","type":"sub","invalid_symbols":["NSE:TATAMOTORS25OCT650CE","NSE:TATAMOTORS25OCT650PE","MCX:SILVERMIC"]},"timestamp":"2025-10-17 02:35:57,722+0530","service":"FyersDataSocket"}
{"level":"ERROR","location":"[__symbol_conversion:1352] data_ws","message":{"code":-300,"message":"Please provide a valid symbol","s":"error","type":"sub","invalid_symbols":["NSE:TATAMOTORS25OCT650CE","NSE:TATAMOTORS25OCT650PE","MCX:SILVERMIC"]},"timestamp":"2025-10-17 02:37:05,268+0530","service":"FyersDataSocket"}
{"level":"ERROR","location":"[__symbol_conversion:1352] data_ws","message":{"code":-300,"message":"Please provide a valid symbol","s":"error","type":"sub","invalid_symbols":["NSE:TATAMOTORS25OCT650CE","NSE:TATAMOTORS25OCT650PE","MCX:ZINC"]},"timestamp":"2025-10-17 02:37:46,779+0530","service":"FyersDataSocket"}
{"level":"ERROR","location":"[__symbol_conversion:1352] data_ws","message":{"code":-300,"message":"Please provide a valid symbol","s":"error","type":"sub","invalid_symbols":["NSE:TATAMOTORS25OCT650CE","NSE:TATAMOTORS25OCT650PE","MCX:SILVERMIC","MCX:GOLDPETAL","MCX:CRUDEOIL","MCX:NATURALGAS","MCX:COPPER","MCX:ALUMINIUM","MCX:LEAD","MCX:NICKEL"]},"timestamp":"2025-10-17 02:43:39,460+0530","service":"FyersDataSocket"}
{"level":"ERROR","location":"[__symbol_conversion:1352] data_ws","message":{"code":-300,"message":"Please provide a valid symbol","s":"error","type":"sub","invalid_symbols":["NSE:TATAMOTORS25OCT650CE","NSE:TATAMOTORS25OCT650PE","MCX:SILVERMIC","MCX:GOLDPETAL","MCX:CRUDEOIL","MCX:NATURALGAS","MCX:COPPER","MCX:ALUMINIUM","MCX:LEAD","MCX:NICKEL"]},"timestamp":"2025-10-17 02:45:06,579+0530","service":"FyersDataSocket"}
{"level":"ERROR","location":"[__symbol_conversion:1352] data_ws","message":{"code":-300,"message":"Please provide a valid symbol","s":"error","type":"sub","invalid_symbols":["NSE:TATAMOTORS25OCT650CE","NSE:TATAMOTORS25OCT650PE","MCX:SILVER25OCTFUT","MCX:GOLDPETAL","MCX:CRUDEOIL","MCX:NATURALGAS","MCX:COPPER","MCX:ALUMINIUM","MCX:LEAD","MCX:NICKEL"]},"timestamp":"2025-10-17 02:46:21,392+0530","service":"FyersDataSocket"}
{"level":"ERROR","location":"[__symbol_conversion:1352] data_ws","message":{"code":-300,"message":"Please provide a valid symbol","s":"error","type":"sub","invalid_symbols":["NSE:TATAMOTORS25OCT650CE","NSE:TATAMOTORS25OCT650PE"]},"timestamp":"2025-10-17 02:50:17,345+0530","service":"FyersDataSocket"}
{"level":"ERROR","location":"[__symbol_conversion:1352] data_ws","message":{"code":-300,"message":"Please provide a valid symbol","s":"error","type":"sub","invalid_symbols":["NSE:TATAMOTORS25OCT650CE","NSE:TATAMOTORS25OCT650PE"]},"timestamp":"2025-10-17 08:24:52,628+0530","service":"FyersDataSocket"}
{"level":"ERROR","location":"[__symbol_conversion:1352] data_ws","message":{"code":-300,"message":"Please provide a valid symbol","s":"error","type":"sub","invalid_symbols":["NSE:TATAMOTORS25OCT650CE","NSE:TATAMOTORS25OCT650PE"]},"timestamp":"2025-10-17 21:39:44,439+0530","service":"FyersDataSocket"}
{"level":"ERROR","location":"[<lambda>:1663] data_ws","message":"Connection to remote host was lost.","timestamp":"2025-10-17 22:19:42,286+0530","service":"FyersDataSocket"}
{"level":"ERROR","location":"[symbol_to_hsmtoken:126] data_ws","message":"HTTPSConnectionPool(host='api-t1.fyers.in', port=443): Max retries exceeded with url: /data/symbol-token (Caused by NewConnectionError('<urllib3.connection.HTTPSConnection object at 0x000001FF7B89A7B0>: Failed to establish a new connection: [Errno 11001] getaddrinfo failed'))","timestamp":"2025-10-17 22:19:49,312+0530","service":"FyersDataSocket","exception":"Traceback (most recent call last):\n  File \"E:\\paper\\paper\\venv\\Lib\\site-packages\\websocket\\_app.py\", line 428, in setSock\n    dispatcher.read(self.sock.sock, read, check)\n  File \"E:\\paper\\paper\\venv\\Lib\\site-packages\\websocket\\_app.py\", line 99, in read\n    if not read_callback():\n           ^^^^^^^^^^^^^^^\n  File \"E:\\paper\\paper\\venv\\Lib\\site-packages\\websocket\\_app.py\", line 442, in read\n    raise e\n  File \"E:\\paper\\paper\\venv\\Lib\\site-packages\\websocket\\_app.py\", line 437, in read\n    op_code, frame = self.sock.recv_data_frame(True)\n                     ^^^^^^^^^^^^^^^^^^^^^^^^^^^^^^^\n  File \"E:\\paper\\paper\\venv\\Lib\\site-packages\\websocket\\_core.py\", line 406, in recv_data_frame\n    frame = self.recv_frame()\n            ^^^^^^^^^^^^^^^^^\n  File \"E:\\paper\\paper\\venv\\Lib\\site-packages\\websocket\\_core.py\", line 445, in recv_frame\n    return self.frame_buffer.recv_frame()\n           ^^^^^^^^^^^^^^^^^^^^^^^^^^^^^^\n  File \"E:\\paper\\paper\\venv\\Lib\\site-packages\\websocket\\_abnf.py\", line 338, in recv_frame\n    self.recv_header()\n  File \"E:\\paper\\paper\\venv\\Lib\\site-packages\\websocket\\_abnf.py\", line 294, in recv_header\n    header = self.recv_strict(2)\n             ^^^^^^^^^^^^^^^^^^^\n  File \"E:\\paper\\paper\\venv\\Lib\\site-packages\\websocket\\_abnf.py\", line 373, in recv_strict\n    bytes_ = self.recv(min(16384, shortage))\n             ^^^^^^^^^^^^^^^^^^^^^^^^^^^^^^^\n  File \"E:\\paper\\paper\\venv\\Lib\\site-packages\\websocket\\_core.py\", line 529, in _recv\n    return recv(self.sock, bufsize)\n           ^^^^^^^^^^^^^^^^^^^^^^^^\n  File \"E:\\paper\\paper\\venv\\Lib\\site-packages\\websocket\\_socket.py\", line 122, in recv\n    raise WebSocketConnectionClosedException(\nwebsocket._exceptions.WebSocketConnectionClosedException: Connection to remote host was lost.\n\nDuring handling of the above exception, another exception occurred:\n\nTraceback (most recent call last):\n  File \"E:\\paper\\paper\\venv\\Lib\\site-packages\\urllib3\\connection.py\", line 174, in _new_conn\n    conn = connection.create_connection(\n           ^^^^^^^^^^^^^^^^^^^^^^^^^^^^^\n  File \"E:\\paper\\paper\\venv\\Lib\\site-packages\\urllib3\\util\\connection.py\", line 72, in create_connection\n    for res in socket.getaddrinfo(host, port, family, socket.SOCK_STREAM):\n               ^^^^^^^^^^^^^^^^^^^^^^^^^^^^^^^^^^^^^^^^^^^^^^^^^^^^^^^^^^\n  File \"C:\\Users\\hp\\AppData\\Local\\Programs\\Python\\Python312\\Lib\\socket.py\", line 963, in getaddrinfo\n    for res in _socket.getaddrinfo(host, port, family, type, proto, flags):\n               ^^^^^^^^^^^^^^^^^^^^^^^^^^^^^^^^^^^^^^^^^^^^^^^^^^^^^^^^^^^\nsocket.gaierror: [Errno 11001] getaddrinfo failed\n\nDuring handling of the above exception, another exception occurred:\n\nTraceback (most recent call last):\n  File \"E:\\paper\\paper\\venv\\Lib\\site-packages\\urllib3\\connectionpool.py\", line 716, in urlopen\n    httplib_response = self._make_request(\n                       ^^^^^^^^^^^^^^^^^^^\n  File \"E:\\paper\\paper\\venv\\Lib\\site-packages\\urllib3\\connectionpool.py\", line 404, in _make_request\n    self._validate_conn(conn)\n  File \"E:\\paper\\paper\\venv\\Lib\\site-packages\\urllib3\\connectionpool.py\", line 1061, in _validate_conn\n    conn.connect()\n  File \"E:\\paper\\paper\\venv\\Lib\\site-packages\\urllib3\\connection.py\", line 363, in connect\n    self.sock = conn = self._new_conn()\n                       ^^^^^^^^^^^^^^^^\n  File \"E:\\paper\\paper\\venv\\Lib\\site-packages\\urllib3\\connection.py\", line 186, in _new_conn\n    raise NewConnectionError(\nurllib3.exceptions.NewConnectionError: <urllib3.connection.HTTPSConnection object at 0x000001FF7B89A7B0>: Failed to establish a new connection: [Errno 11001] getaddrinfo failed\n\nDuring handling of the above exception, another exception occurred:\n\nTraceback (most recent call last):\n  File \"E:\\paper\\paper\\venv\\Lib\\site-packages\\requests\\adapters.py\", line 486, in send\n    resp = conn.urlopen(\n           ^^^^^^^^^^^^^\n  File \"E:\\paper\\paper\\venv\\Lib\\site-packages\\urllib3\\connectionpool.py\", line 802, in urlopen\n    retries = retries.increment(\n              ^^^^^^^^^^^^^^^^^^\n  File \"E:\\paper\\paper\\venv\\Lib\\site-packages\\urllib3\\util\\retry.py\", line 594, in increment\n    raise MaxRetryError(_pool, url, error or ResponseError(cause))\nurllib3.exceptions.MaxRetryError: HTTPSConnectionPool(host='api-t1.fyers.in', port=443): Max retries exceeded with url: /data/symbol-token (Caused by NewConnectionError('<urllib3.connection.HTTPSConnection object at 0x000001FF7B89A7B0>: Failed to establish a new connection: [Errno 11001] getaddrinfo failed'))\n\nDuring handling of the above exception, another exception occurred:\n\nTraceback (most recent call last):\n  File \"E:\\paper\\paper\\venv\\Lib\\site-packages\\fyers_apiv3\\FyersWebsocket\\data_ws.py\", line 63, in symbol_to_hsmtoken\n    response = requests.post(\n               ^^^^^^^^^^^^^^\n  File \"E:\\paper\\paper\\venv\\Lib\\site-packages\\requests\\api.py\", line 115, in post\n    return request(\"post\", url, data=data, json=json, **kwargs)\n           ^^^^^^^^^^^^^^^^^^^^^^^^^^^^^^^^^^^^^^^^^^^^^^^^^^^^\n  File \"E:\\paper\\paper\\venv\\Lib\\site-packages\\requests\\api.py\", line 59, in request\n    return session.request(method=method, url=url, **kwargs)\n           ^^^^^^^^^^^^^^^^^^^^^^^^^^^^^^^^^^^^^^^^^^^^^^^^^\n  File \"E:\\paper\\paper\\venv\\Lib\\site-packages\\requests\\sessions.py\", line 589, in request\n    resp = self.send(prep, **send_kwargs)\n           ^^^^^^^^^^^^^^^^^^^^^^^^^^^^^^\n  File \"E:\\paper\\paper\\venv\\Lib\\site-packages\\requests\\sessions.py\", line 703, in send\n    r = adapter.send(request, **kwargs)\n        ^^^^^^^^^^^^^^^^^^^^^^^^^^^^^^^\n  File \"E:\\paper\\paper\\venv\\Lib\\site-packages\\requests\\adapters.py\", line 519, in send\n    raise ConnectionError(e, request=request)\nrequests.exceptions.ConnectionError: HTTPSConnectionPool(host='api-t1.fyers.in', port=443): Max retries exceeded with url: /data/symbol-token (Caused by NewConnectionError('<urllib3.connection.HTTPSConnection object at 0x000001FF7B89A7B0>: Failed to establish a new connection: [Errno 11001] getaddrinfo failed'))","exception_name":"ConnectionError"}
{"level":"ERROR","location":"[__symbol_conversion:1374] data_ws","message":"'NoneType' object is not subscriptable","timestamp":"2025-10-17 23:59:02,058+0530","service":"FyersDataSocket","exception":"Traceback (most recent call last):\n  File \"E:\\paper\\paper\\venv\\Lib\\site-packages\\websocket\\_app.py\", line 428, in setSock\n    dispatcher.read(self.sock.sock, read, check)\n  File \"E:\\paper\\paper\\venv\\Lib\\site-packages\\websocket\\_app.py\", line 99, in read\n    if not read_callback():\n           ^^^^^^^^^^^^^^^\n  File \"E:\\paper\\paper\\venv\\Lib\\site-packages\\websocket\\_app.py\", line 442, in read\n    raise e\n  File \"E:\\paper\\paper\\venv\\Lib\\site-packages\\websocket\\_app.py\", line 437, in read\n    op_code, frame = self.sock.recv_data_frame(True)\n                     ^^^^^^^^^^^^^^^^^^^^^^^^^^^^^^^\n  File \"E:\\paper\\paper\\venv\\Lib\\site-packages\\websocket\\_core.py\", line 406, in recv_data_frame\n    frame = self.recv_frame()\n            ^^^^^^^^^^^^^^^^^\n  File \"E:\\paper\\paper\\venv\\Lib\\site-packages\\websocket\\_core.py\", line 445, in recv_frame\n    return self.frame_buffer.recv_frame()\n           ^^^^^^^^^^^^^^^^^^^^^^^^^^^^^^\n  File \"E:\\paper\\paper\\venv\\Lib\\site-packages\\websocket\\_abnf.py\", line 338, in recv_frame\n    self.recv_header()\n  File \"E:\\paper\\paper\\venv\\Lib\\site-packages\\websocket\\_abnf.py\", line 294, in recv_header\n    header = self.recv_strict(2)\n             ^^^^^^^^^^^^^^^^^^^\n  File \"E:\\paper\\paper\\venv\\Lib\\site-packages\\websocket\\_abnf.py\", line 373, in recv_strict\n    bytes_ = self.recv(min(16384, shortage))\n             ^^^^^^^^^^^^^^^^^^^^^^^^^^^^^^^\n  File \"E:\\paper\\paper\\venv\\Lib\\site-packages\\websocket\\_core.py\", line 529, in _recv\n    return recv(self.sock, bufsize)\n           ^^^^^^^^^^^^^^^^^^^^^^^^\n  File \"E:\\paper\\paper\\venv\\Lib\\site-packages\\websocket\\_socket.py\", line 122, in recv\n    raise WebSocketConnectionClosedException(\nwebsocket._exceptions.WebSocketConnectionClosedException: Connection to remote host was lost.\n\nDuring handling of the above exception, another exception occurred:\n\nTraceback (most recent call last):\n  File \"E:\\paper\\paper\\venv\\Lib\\site-packages\\fyers_apiv3\\FyersWebsocket\\data_ws.py\", line 1333, in __symbol_conversion\n    if symbol_value[3] != \"\":\n       ~~~~~~~~~~~~^^^\nTypeError: 'NoneType' object is not subscriptable","exception_name":"TypeError"}
{"level":"ERROR","location":"[<lambda>:1663] data_ws","message":"Connection to remote host was lost.","timestamp":"2025-10-17 23:59:09,834+0530","service":"FyersDataSocket"}
{"level":"ERROR","location":"[__symbol_conversion:1352] data_ws","message":{"code":-300,"message":"Please provide a valid symbol","s":"error","type":"sub","invalid_symbols":["NSE:TATAMOTORS25OCT650CE","NSE:TATAMOTORS25OCT650PE"]},"timestamp":"2025-10-17 23:59:17,462+0530","service":"FyersDataSocket"}
{"level":"ERROR","location":"[<lambda>:1663] data_ws","message":"Connection to remote host was lost.","timestamp":"2025-10-18 00:01:49,927+0530","service":"FyersDataSocket"}
{"level":"ERROR","location":"[__symbol_conversion:1352] data_ws","message":{"code":-300,"message":"Please provide a valid symbol","s":"error","type":"sub","invalid_symbols":["NSE:TATAMOTORS25OCT650CE","NSE:TATAMOTORS25OCT650PE"]},"timestamp":"2025-10-18 00:01:57,344+0530","service":"FyersDataSocket"}
{"level":"ERROR","location":"[<lambda>:1663] data_ws","message":"EOF occurred in violation of protocol (_ssl.c:2406)","timestamp":"2025-10-18 00:53:38,298+0530","service":"FyersDataSocket"}
{"level":"ERROR","location":"[__symbol_conversion:1352] data_ws","message":{"code":-300,"message":"Please provide a valid symbol","s":"error","type":"sub","invalid_symbols":["NSE:TATAMOTORS25OCT650CE","NSE:TATAMOTORS25OCT650PE"]},"timestamp":"2025-10-18 00:53:45,844+0530","service":"FyersDataSocket"}
{"level":"ERROR","location":"[<lambda>:1663] data_ws","message":"Connection to remote host was lost.","timestamp":"2025-10-18 02:13:20,764+0530","service":"FyersDataSocket"}
{"level":"ERROR","location":"[__symbol_conversion:1352] data_ws","message":{"code":-300,"message":"Please provide a valid symbol","s":"error","type":"sub","invalid_symbols":["NSE:TATAMOTORS25OCT650CE","NSE:TATAMOTORS25OCT650PE"]},"timestamp":"2025-10-18 02:13:28,364+0530","service":"FyersDataSocket"}
{"level":"ERROR","location":"[<lambda>:1663] data_ws","message":"EOF occurred in violation of protocol (_ssl.c:2406)","timestamp":"2025-10-18 02:48:56,939+0530","service":"FyersDataSocket"}
{"level":"ERROR","location":"[__symbol_conversion:1352] data_ws","message":{"code":-300,"message":"Please provide a valid symbol","s":"error","type":"sub","invalid_symbols":["NSE:TATAMOTORS25OCT650CE","NSE:TATAMOTORS25OCT650PE"]},"timestamp":"2025-10-18 02:49:04,419+0530","service":"FyersDataSocket"}
{"level":"ERROR","location":"[<lambda>:1663] data_ws","message":"Connection to remote host was lost.","timestamp":"2025-10-18 03:20:18,333+0530","service":"FyersDataSocket"}
{"level":"ERROR","location":"[access_token_to_hsmtoken:272] data_ws","message":{"type":"cn","code":-99,"message":"Token is expired","s":"error"},"timestamp":"2025-10-18 06:42:02,072+0530","service":"FyersDataSocket"}
{"level":"ERROR","location":"[__symbol_conversion:1334] data_ws","message":{"code":-300,"message":"Please provide valid token","s":"error","type":"sub"},"timestamp":"2025-10-18 06:42:05,489+0530","service":"FyersDataSocket"}
{"level":"ERROR","location":"[access_token_to_hsmtoken:272] data_ws","message":{"type":"cn","code":-99,"message":"Token is expired","s":"error"},"timestamp":"2025-10-18 11:23:18,831+0530","service":"FyersDataSocket"}
{"level":"ERROR","location":"[access_token_to_hsmtoken:272] data_ws","message":{"type":"cn","code":-99,"message":"Token is expired","s":"error"},"timestamp":"2025-10-18 12:17:24,498+0530","service":"FyersDataSocket"}
{"level":"ERROR","location":"[__symbol_conversion:1352] data_ws","message":{"code":-300,"message":"Please provide a valid symbol","s":"error","type":"sub","invalid_symbols":["NSE:TATAMOTORS25OCT650CE","NSE:TATAMOTORS25OCT650PE","MCX:GOLD15NOVFUT","MCX:GOLD15DECFUT","MCX:GOLD15JANFUT","MCX:SILVER15NOVFUT","MCX:SILVER15DECFUT","MCX:SILVER15JANFUT","MCX:CRUDEOIL15NOVFUT","MCX:CRUDEOIL15DECFUT","MCX:CRUDEOIL15JANFUT"]},"timestamp":"2025-10-18 12:21:23,742+0530","service":"FyersDataSocket"}
{"level":"ERROR","location":"[__symbol_conversion:1352] data_ws","message":{"code":-300,"message":"Please provide a valid symbol","s":"error","type":"sub","invalid_symbols":["NSE:TATAMOTORS25OCT650CE","NSE:TATAMOTORS25OCT650PE","MCX:GOLD16NOVFUT","MCX:GOLD16DECFUT","MCX:GOLD16JANFUT","MCX:SILVER15NOVFUT","MCX:SILVER15DECFUT","MCX:SILVER15JANFUT","MCX:CRUDEOIL15NOVFUT","MCX:CRUDEOIL15DECFUT","MCX:CRUDEOIL15JANFUT"]},"timestamp":"2025-10-18 12:25:24,878+0530","service":"FyersDataSocket"}
{"level":"ERROR","location":"[__symbol_conversion:1352] data_ws","message":{"code":-300,"message":"Please provide a valid symbol","s":"error","type":"sub","invalid_symbols":["NSE:TATAMOTORS25OCT650CE","NSE:TATAMOTORS25OCT650PE","MCX:GOLD24NOVFUT","MCX:GOLD16DECFUT","MCX:GOLD16JANFUT","MCX:SILVER15NOVFUT","MCX:SILVER15DECFUT","MCX:SILVER15JANFUT","MCX:CRUDEOIL15NOVFUT","MCX:CRUDEOIL15DECFUT","MCX:CRUDEOIL15JANFUT"]},"timestamp":"2025-10-18 12:26:43,997+0530","service":"FyersDataSocket"}
{"level":"ERROR","location":"[__symbol_conversion:1352] data_ws","message":{"code":-300,"message":"Please provide a valid symbol","s":"error","type":"sub","invalid_symbols":["NSE:TATAMOTORS25OCT650CE","NSE:TATAMOTORS25OCT650PE","MCX:GOLD18OCTFUT","MCX:GOLD16DECFUT","MCX:GOLD16JANFUT","MCX:SILVER15NOVFUT","MCX:SILVER15DECFUT","MCX:SILVER15JANFUT","MCX:CRUDEOIL15NOVFUT","MCX:CRUDEOIL15DECFUT","MCX:CRUDEOIL15JANFUT"]},"timestamp":"2025-10-18 12:31:07,567+0530","service":"FyersDataSocket"}
{"level":"ERROR","location":"[__symbol_conversion:1352] data_ws","message":{"code":-300,"message":"Please provide a valid symbol","s":"error","type":"sub","invalid_symbols":["NSE:TATAMOTORS25OCT650CE","NSE:TATAMOTORS25OCT650PE","MCX:GOLD05DECFUT","MCX:GOLD05DECFUT","MCX:GOLD05DECFUT","MCX:SILVER15NOVFUT","MCX:SILVER15DECFUT","MCX:SILVER15JANFUT","MCX:CRUDEOIL15NOVFUT","MCX:CRUDEOIL15DECFUT","MCX:CRUDEOIL15JANFUT"]},"timestamp":"2025-10-18 12:32:56,219+0530","service":"FyersDataSocket"}
{"level":"ERROR","location":"[__symbol_conversion:1352] data_ws","message":{"code":-300,"message":"Please provide a valid symbol","s":"error","type":"sub","invalid_symbols":["NSE:TATAMOTORS25OCT650CE","NSE:TATAMOTORS25OCT650PE","MCX:GOLD31OCTFUT","MCX:GOLD05DECFUT","MCX:SILVER15NOVFUT","MCX:SILVER15DECFUT","MCX:SILVER15JANFUT","MCX:CRUDEOIL15NOVFUT","MCX:CRUDEOIL15DECFUT","MCX:CRUDEOIL15JANFUT"]},"timestamp":"2025-10-18 12:34:45,597+0530","service":"FyersDataSocket"}
{"level":"ERROR","location":"[__symbol_conversion:1352] data_ws","message":{"code":-300,"message":"Please provide a valid symbol","s":"error","type":"sub","invalid_symbols":["MCX:GOLD25JANFUT","MCX:GOLD25FEBFUT","MCX:GOLDM25JANFUT","MCX:GOLDM25FEBFUT","MCX:SILVER25JANFUT","MCX:SILVER25FEBFUT","MCX:SILVERM25DECFUT","MCX:SILVERM25JANFUT","MCX:SILVERM25FEBFUT","MCX:COPPER25JANFUT","MCX:ZINC25JANFUT","MCX:LEAD25JANFUT","MCX:NICKEL25JANFUT","MCX:ALUMINIUM25JANFUT","MCX:CRUDEOIL25JANFUT","MCX:NATURALGAS25JANFUT","MCX:COTTON25JANFUT","MCX:MENTHAOIL25JANFUT","MCX:CPO25DECFUT","MCX:CPO25JANFUT","MCX:GOLD25DEC60000CE","MCX:GOLD25DEC61000CE","MCX:GOLD25DEC62000CE","MCX:GOLD25DEC63000CE","MCX:GOLD25DEC64000CE","MCX:GOLD25DEC65000CE","MCX:GOLD25DEC60000PE","MCX:GOLD25DEC61000PE","MCX:GOLD25DEC62000PE","MCX:GOLD25DEC63000PE","MCX:GOLD25DEC64000PE","MCX:GOLD25DEC65000PE","MCX:SILVER25DEC80000CE","MCX:SILVER25DEC82000CE","MCX:SILVER25DEC84000CE","MCX:SILVER25DEC86000CE","MCX:SILVER25DEC88000CE","MCX:SILVER25DEC90000CE","MCX:SILVER25DEC80000PE","MCX:SILVER25DEC82000PE","MCX:SILVER25DEC84000PE","MCX:SILVER25DEC86000PE","MCX:SILVER25DEC88000PE","MCX:SILVER25DEC90000PE","MCX:NATURALGAS25DEC200CE","MCX:NATURALGAS25DEC220CE","MCX:NATURALGAS25DEC240CE","MCX:NATURALGAS25DEC260CE","MCX:NATURALGAS25DEC200PE","MCX:NATURALGAS25DEC220PE","MCX:NATURALGAS25DEC240PE","MCX:NATURALGAS25DEC260PE","MCX:COPPER25DEC800CE","MCX:COPPER25DEC820CE","MCX:COPPER25DEC840CE","MCX:COPPER25DEC860CE","MCX:COPPER25DEC800PE","MCX:COPPER25DEC820PE","MCX:COPPER25DEC840PE","MCX:COPPER25DEC860PE"]},"timestamp":"2025-10-18 12:56:11,114+0530","service":"FyersDataSocket"}
{"level":"ERROR","location":"[__symbol_conversion:1352] data_ws","message":{"code":-300,"message":"Please provide a valid symbol","s":"error","type":"sub","invalid_symbols":["MCX:GOLD25JANFUT","MCX:GOLD25FEBFUT","MCX:GOLDM25JANFUT","MCX:GOLDM25FEBFUT","MCX:SILVER25JANFUT","MCX:SILVER25FEBFUT","MCX:SILVERM25DECFUT","MCX:SILVERM25JANFUT","MCX:SILVERM25FEBFUT","MCX:COPPER25JANFUT","MCX:ZINC25JANFUT","MCX:LEAD25JANFUT","MCX:NICKEL25JANFUT","MCX:ALUMINIUM25JANFUT","MCX:CRUDEOIL25JANFUT","MCX:NATURALGAS25JANFUT","MCX:COTTON25JANFUT","MCX:MENTHAOIL25JANFUT","MCX:CPO25DECFUT","MCX:CPO25JANFUT","MCX:GOLD31OCT60000CE","MCX:GOLD31OCT61000CE","MCX:GOLD31OCT62000CE","MCX:GOLD31OCT63000CE","MCX:GOLD31OCT64000CE","MCX:GOLD31OCT65000CE","MCX:GOLD31OCT60000PE","MCX:GOLD31OCT61000PE","MCX:GOLD31OCT62000PE","MCX:GOLD31OCT63000PE","MCX:GOLD31OCT64000PE","MCX:GOLD31OCT65000PE","MCX:SILVER25DEC80000CE","MCX:SILVER25DEC82000CE","MCX:SILVER25DEC84000CE","MCX:SILVER25DEC86000CE","MCX:SILVER25DEC88000CE","MCX:SILVER25DEC90000CE","MCX:SILVER25DEC80000PE","MCX:SILVER25DEC82000PE","MCX:SILVER25DEC84000PE","MCX:SILVER25DEC86000PE","MCX:SILVER25DEC88000PE","MCX:SILVER25DEC90000PE","MCX:NATURALGAS25DEC200CE","MCX:NATURALGAS25DEC220CE","MCX:NATURALGAS25DEC240CE","MCX:NATURALGAS25DEC260CE","MCX:NATURALGAS25DEC200PE","MCX:NATURALGAS25DEC220PE","MCX:NATURALGAS25DEC240PE","MCX:NATURALGAS25DEC260PE","MCX:COPPER25DEC800CE","MCX:COPPER25DEC820CE","MCX:COPPER25DEC840CE","MCX:COPPER25DEC860CE","MCX:COPPER25DEC800PE","MCX:COPPER25DEC820PE","MCX:COPPER25DEC840PE","MCX:COPPER25DEC860PE"]},"timestamp":"2025-10-18 12:58:33,951+0530","service":"FyersDataSocket"}
{"level":"ERROR","location":"[__symbol_conversion:1352] data_ws","message":{"code":-300,"message":"Please provide a valid symbol","s":"error","type":"sub","invalid_symbols":["MCX:GOLD05DECFUT","MCX:GOLD05FEBFUT","MCX:GOLD05JANFUT","MCX:GOLDM25JANFUT","MCX:GOLDM25FEBFUT","MCX:SILVER25JANFUT","MCX:SILVER25FEBFUT","MCX:SILVERM25DECFUT","MCX:SILVERM25JANFUT","MCX:SILVERM25FEBFUT","MCX:COPPER25JANFUT","MCX:ZINC25JANFUT","MCX:LEAD25JANFUT","MCX:NICKEL25JANFUT","MCX:ALUMINIUM25JANFUT","MCX:CRUDEOIL25JANFUT","MCX:NATURALGAS25JANFUT","MCX:COTTON25JANFUT","MCX:MENTHAOIL25JANFUT","MCX:CPO25DECFUT","MCX:CPO25JANFUT","MCX:GOLD31OCT60000CE","MCX:GOLD31OCT61000CE","MCX:GOLD31OCT62000CE","MCX:GOLD31OCT63000CE","MCX:GOLD31OCT64000CE","MCX:GOLD31OCT65000CE","MCX:GOLD31OCT60000PE","MCX:GOLD31OCT61000PE","MCX:GOLD31OCT62000PE","MCX:GOLD31OCT63000PE","MCX:GOLD31OCT64000PE","MCX:GOLD31OCT65000PE","MCX:SILVER25DEC80000CE","MCX:SILVER25DEC82000CE","MCX:SILVER25DEC84000CE","MCX:SILVER25DEC86000CE","MCX:SILVER25DEC88000CE","MCX:SILVER25DEC90000CE","MCX:SILVER25DEC80000PE","MCX:SILVER25DEC82000PE","MCX:SILVER25DEC84000PE","MCX:SILVER25DEC86000PE","MCX:SILVER25DEC88000PE","MCX:SILVER25DEC90000PE","MCX:NATURALGAS25DEC200CE","MCX:NATURALGAS25DEC220CE","MCX:NATURALGAS25DEC240CE","MCX:NATURALGAS25DEC260CE","MCX:NATURALGAS25DEC200PE","MCX:NATURALGAS25DEC220PE","MCX:NATURALGAS25DEC240PE","MCX:NATURALGAS25DEC260PE","MCX:COPPER25DEC800CE","MCX:COPPER25DEC820CE","MCX:COPPER25DEC840CE","MCX:COPPER25DEC860CE","MCX:COPPER25DEC800PE","MCX:COPPER25DEC820PE","MCX:COPPER25DEC840PE","MCX:COPPER25DEC860PE"]},"timestamp":"2025-10-18 13:01:27,112+0530","service":"FyersDataSocket"}
{"level":"ERROR","location":"[__symbol_conversion:1352] data_ws","message":{"code":-300,"message":"Please provide a valid symbol","s":"error","type":"sub","invalid_symbols":["MCX:GOLD25JANFUT","MCX:GOLD25FEBFUT","MCX:GOLDM25JANFUT","MCX:GOLDM25FEBFUT","MCX:SILVER25JANFUT","MCX:SILVER25FEBFUT","MCX:SILVERM25DECFUT","MCX:SILVERM25JANFUT","MCX:SILVERM25FEBFUT","MCX:COPPER25JANFUT","MCX:ZINC25JANFUT","MCX:LEAD25JANFUT","MCX:NICKEL25JANFUT","MCX:ALUMINIUM25JANFUT","MCX:CRUDEOIL25JANFUT","MCX:NATURALGAS25JANFUT","MCX:COTTON25JANFUT","MCX:MENTHAOIL25JANFUT","MCX:CPO25DECFUT","MCX:CPO25JANFUT","MCX:GOLD31OCT60000CE","MCX:GOLD31OCT61000CE","MCX:GOLD31OCT62000CE","MCX:GOLD31OCT63000CE","MCX:GOLD31OCT64000CE","MCX:GOLD31OCT65000CE","MCX:GOLD31OCT60000PE","MCX:GOLD31OCT61000PE","MCX:GOLD31OCT62000PE","MCX:GOLD31OCT63000PE","MCX:GOLD31OCT64000PE","MCX:GOLD31OCT65000PE","MCX:SILVER25DEC80000CE","MCX:SILVER25DEC82000CE","MCX:SILVER25DEC84000CE","MCX:SILVER25DEC86000CE","MCX:SILVER25DEC88000CE","MCX:SILVER25DEC90000CE","MCX:SILVER25DEC80000PE","MCX:SILVER25DEC82000PE","MCX:SILVER25DEC84000PE","MCX:SILVER25DEC86000PE","MCX:SILVER25DEC88000PE","MCX:SILVER25DEC90000PE","MCX:NATURALGAS25DEC200CE","MCX:NATURALGAS25DEC220CE","MCX:NATURALGAS25DEC240CE","MCX:NATURALGAS25DEC260CE","MCX:NATURALGAS25DEC200PE","MCX:NATURALGAS25DEC220PE","MCX:NATURALGAS25DEC240PE","MCX:NATURALGAS25DEC260PE","MCX:COPPER25DEC800CE","MCX:COPPER25DEC820CE","MCX:COPPER25DEC840CE","MCX:COPPER25DEC860CE","MCX:COPPER25DEC800PE","MCX:COPPER25DEC820PE","MCX:COPPER25DEC840PE","MCX:COPPER25DEC860PE"]},"timestamp":"2025-10-18 13:04:40,394+0530","service":"FyersDataSocket"}
{"level":"ERROR","location":"[__symbol_conversion:1352] data_ws","message":{"code":-300,"message":"Please provide a valid symbol","s":"error","type":"sub","invalid_symbols":["MCX:GOLD25NOVFUT","MCX:GOLD25FEBFUT","MCX:GOLDM25JANFUT","MCX:GOLDM25FEBFUT","MCX:SILVER25JANFUT","MCX:SILVER25FEBFUT","MCX:SILVERM25DECFUT","MCX:SILVERM25JANFUT","MCX:SILVERM25FEBFUT","MCX:COPPER25JANFUT","MCX:ZINC25JANFUT","MCX:LEAD25JANFUT","MCX:NICKEL25JANFUT","MCX:ALUMINIUM25JANFUT","MCX:CRUDEOIL25JANFUT","MCX:NATURALGAS25JANFUT","MCX:COTTON25JANFUT","MCX:MENTHAOIL25JANFUT","MCX:CPO25DECFUT","MCX:CPO25JANFUT","MCX:GOLD31OCT60000CE","MCX:GOLD31OCT61000CE","MCX:GOLD31OCT62000CE","MCX:GOLD31OCT63000CE","MCX:GOLD31OCT64000CE","MCX:GOLD31OCT65000CE","MCX:GOLD31OCT60000PE","MCX:GOLD31OCT61000PE","MCX:GOLD31OCT62000PE","MCX:GOLD31OCT63000PE","MCX:GOLD31OCT64000PE","MCX:GOLD31OCT65000PE","MCX:SILVER25DEC80000CE","MCX:SILVER25DEC82000CE","MCX:SILVER25DEC84000CE","MCX:SILVER25DEC86000CE","MCX:SILVER25DEC88000CE","MCX:SILVER25DEC90000CE","MCX:SILVER25DEC80000PE","MCX:SILVER25DEC82000PE","MCX:SILVER25DEC84000PE","MCX:SILVER25DEC86000PE","MCX:SILVER25DEC88000PE","MCX:SILVER25DEC90000PE","MCX:NATURALGAS25DEC200CE","MCX:NATURALGAS25DEC220CE","MCX:NATURALGAS25DEC240CE","MCX:NATURALGAS25DEC260CE","MCX:NATURALGAS25DEC200PE","MCX:NATURALGAS25DEC220PE","MCX:NATURALGAS25DEC240PE","MCX:NATURALGAS25DEC260PE","MCX:COPPER25DEC800CE","MCX:COPPER25DEC820CE","MCX:COPPER25DEC840CE","MCX:COPPER25DEC860CE","MCX:COPPER25DEC800PE","MCX:COPPER25DEC820PE","MCX:COPPER25DEC840PE","MCX:COPPER25DEC860PE"]},"timestamp":"2025-10-18 13:06:27,585+0530","service":"FyersDataSocket"}
{"level":"ERROR","location":"[__symbol_conversion:1352] data_ws","message":{"code":-300,"message":"Please provide a valid symbol","s":"error","type":"sub","invalid_symbols":["MCX:SILVERM25DECFUT","MCX:CPO25DECFUT","MCX:GOLD31OCT60000CE","MCX:GOLD31OCT61000CE","MCX:GOLD31OCT62000CE","MCX:GOLD31OCT63000CE","MCX:GOLD31OCT64000CE","MCX:GOLD31OCT65000CE","MCX:GOLD31OCT60000PE","MCX:GOLD31OCT61000PE","MCX:GOLD31OCT62000PE","MCX:GOLD31OCT63000PE","MCX:GOLD31OCT64000PE","MCX:GOLD31OCT65000PE","MCX:SILVER25DEC80000CE","MCX:NATURALGAS25DEC260PE"]},"timestamp":"2025-10-18 13:33:19,716+0530","service":"FyersDataSocket"}
{"level":"ERROR","location":"[__symbol_conversion:1352] data_ws","message":{"code":-300,"message":"Please provide a valid symbol","s":"error","type":"sub","invalid_symbols":["MCX:SILVERM28NOVFUT","MCX:CPO25DECFUT","MCX:GOLD31OCT130000CE","MCX:GOLD31OCT132000CE","MCX:GOLD31OCT131000CE","MCX:GOLD31OCT134000CE","MCX:GOLD31OCT129000CE","MCX:GOLD31OCT128000CE","MCX:GOLD31OCT120000PE","MCX:GOLD31OCT1250000PE","MCX:GOLD31OCT130000PE","MCX:GOLD31OCT129000PE","MCX:GOLD31OCT128000PE","MCX:GOLD31OCT123000PE","MCX:SILVER25DEC80000CE"]},"timestamp":"2025-10-18 13:42:03,181+0530","service":"FyersDataSocket"}
{"level":"ERROR","location":"[__symbol_conversion:1352] data_ws","message":{"code":-300,"message":"Please provide a valid symbol","s":"error","type":"sub","invalid_symbols":["MCX:SILVERM28NOVFUT","MCX:CPO25DECFUT","MCX:GOLD31OCT130000CE","MCX:GOLD31OCT132000CE","MCX:GOLD31OCT131000CE","MCX:GOLD31OCT134000CE","MCX:GOLD31OCT129000CE","MCX:GOLD31OCT128000CE","MCX:GOLD31OCT120000PE","MCX:GOLD31OCT1250000PE","MCX:GOLD31OCT130000PE","MCX:GOLD31OCT129000PE","MCX:GOLD31OCT128000PE","MCX:GOLD31OCT123000PE","MCX:SILVER25DEC80000CE"]},"timestamp":"2025-10-18 13:50:09,709+0530","service":"FyersDataSocket"}
{"level":"ERROR","location":"[__symbol_conversion:1352] data_ws","message":{"code":-300,"message":"Please provide a valid symbol","s":"error","type":"sub","invalid_symbols":["MCX:SILVERM28NOVFUT","MCX:CPO25DECFUT","MCX:GOLD30OCT130000CE","MCX:GOLD30OCT132000CE","MCX:GOLD31OCT131000CE","MCX:GOLD31OCT134000CE","MCX:GOLD31OCT129000CE","MCX:GOLD31OCT128000CE","MCX:GOLD31OCT120000PE","MCX:GOLD31OCT1250000PE","MCX:GOLD31OCT130000PE","MCX:GOLD31OCT129000PE","MCX:GOLD31OCT128000PE","MCX:GOLD31OCT123000PE","MCX:SILVER25DEC80000CE"]},"timestamp":"2025-10-18 13:51:20,503+0530","service":"FyersDataSocket"}
{"level":"ERROR","location":"[__symbol_conversion:1352] data_ws","message":{"code":-300,"message":"Please provide a valid symbol","s":"error","type":"sub","invalid_symbols":["MCX:SILVERM28NOVFUT","MCX:CPO25DECFUT","MCX:GOLD31OCT13000CE","MCX:GOLD31OCT132000CE","MCX:GOLD31OCT131000CE","MCX:GOLD31OCT134000CE","MCX:GOLD31OCT129000CE","MCX:GOLD31OCT128000CE","MCX:GOLD31OCT120000PE","MCX:GOLD31OCT1250000PE","MCX:GOLD31OCT130000PE","MCX:GOLD31OCT129000PE","MCX:GOLD31OCT128000PE","MCX:GOLD31OCT123000PE","MCX:SILVER25DEC80000CE"]},"timestamp":"2025-10-18 13:52:16,890+0530","service":"FyersDataSocket"}
{"level":"ERROR","location":"[__symbol_conversion:1352] data_ws","message":{"code":-300,"message":"Please provide a valid symbol","s":"error","type":"sub","invalid_symbols":["MCX:SILVERM28NOVFUT","MCX:CPO25DECFUT","MCX:GOLD31OCT130000CE","MCX:GOLD31OCT132000CE","MCX:GOLD31OCT131000CE","MCX:GOLD31OCT134000CE","MCX:GOLD31OCT129000CE","MCX:GOLD31OCT128000CE","MCX:GOLD31OCT120000PE","MCX:GOLD31OCT1250000PE","MCX:GOLD31OCT130000PE","MCX:GOLD31OCT129000PE","MCX:GOLD31OCT128000PE","MCX:GOLD31OCT123000PE","MCX:SILVER25DEC80000CE"]},"timestamp":"2025-10-18 13:53:10,519+0530","service":"FyersDataSocket"}
{"level":"ERROR","location":"[__symbol_conversion:1352] data_ws","message":{"code":-300,"message":"Please provide a valid symbol","s":"error","type":"sub","invalid_symbols":["MCX:SILVERM28NOVFUT","MCX:CPO25DECFUT","MCX:GOLD31OCT132000CE","MCX:GOLD31OCT131000CE","MCX:GOLD31OCT134000CE","MCX:GOLD31OCT129000CE","MCX:GOLD31OCT128000CE","MCX:GOLD31OCT120000PE","MCX:GOLD31OCT1250000PE","MCX:GOLD31OCT130000PE","MCX:GOLD31OCT129000PE","MCX:GOLD31OCT128000PE","MCX:GOLD31OCT123000PE","MCX:SILVER25DEC80000CE"]},"timestamp":"2025-10-18 13:54:19,612+0530","service":"FyersDataSocket"}
{"level":"ERROR","location":"[__symbol_conversion:1352] data_ws","message":{"code":-300,"message":"Please provide a valid symbol","s":"error","type":"sub","invalid_symbols":["MCX:SILVERM28NOVFUT","MCX:CPO25DECFUT","MCX:GOLD25DEC1250000PE"]},"timestamp":"2025-10-18 13:55:52,205+0530","service":"FyersDataSocket"}
{"level":"ERROR","location":"[__symbol_conversion:1352] data_ws","message":{"code":-300,"message":"Please provide a valid symbol","s":"error","type":"sub","invalid_symbols":["MCX:SILVERM28NOVFUT"]},"timestamp":"2025-10-18 14:00:42,407+0530","service":"FyersDataSocket"}
{"level":"ERROR","location":"[__symbol_conversion:1352] data_ws","message":{"code":-300,"message":"Please provide a valid symbol","s":"error","type":"sub","invalid_symbols":["MCX:SILVERMIC25DECFUT"]},"timestamp":"2025-10-18 14:01:24,193+0530","service":"FyersDataSocket"}
{"level":"ERROR","location":"[<lambda>:1663] data_ws","message":"Connection to remote host was lost.","timestamp":"2025-10-19 23:14:43,096+0530","service":"FyersDataSocket"}
{"level":"ERROR","location":"[<lambda>:1663] data_ws","message":"[Errno 11001] getaddrinfo failed","timestamp":"2025-10-19 23:14:48,163+0530","service":"FyersDataSocket"}
{"level":"ERROR","location":"[symbol_to_hsmtoken:126] data_ws","message":"HTTPSConnectionPool(host='api-t1.fyers.in', port=443): Max retries exceeded with url: /data/symbol-token (Caused by NewConnectionError('<urllib3.connection.HTTPSConnection object at 0x0000027B4E74D6D0>: Failed to establish a new connection: [Errno 11001] getaddrinfo failed'))","timestamp":"2025-10-19 23:14:50,164+0530","service":"FyersDataSocket","exception":"Traceback (most recent call last):\n  File \"E:\\paper\\paper\\venv\\Lib\\site-packages\\websocket\\_app.py\", line 428, in setSock\n    dispatcher.read(self.sock.sock, read, check)\n  File \"E:\\paper\\paper\\venv\\Lib\\site-packages\\websocket\\_app.py\", line 99, in read\n    if not read_callback():\n           ^^^^^^^^^^^^^^^\n  File \"E:\\paper\\paper\\venv\\Lib\\site-packages\\websocket\\_app.py\", line 442, in read\n    raise e\n  File \"E:\\paper\\paper\\venv\\Lib\\site-packages\\websocket\\_app.py\", line 437, in read\n    op_code, frame = self.sock.recv_data_frame(True)\n                     ^^^^^^^^^^^^^^^^^^^^^^^^^^^^^^^\n  File \"E:\\paper\\paper\\venv\\Lib\\site-packages\\websocket\\_core.py\", line 406, in recv_data_frame\n    frame = self.recv_frame()\n            ^^^^^^^^^^^^^^^^^\n  File \"E:\\paper\\paper\\venv\\Lib\\site-packages\\websocket\\_core.py\", line 445, in recv_frame\n    return self.frame_buffer.recv_frame()\n           ^^^^^^^^^^^^^^^^^^^^^^^^^^^^^^\n  File \"E:\\paper\\paper\\venv\\Lib\\site-packages\\websocket\\_abnf.py\", line 338, in recv_frame\n    self.recv_header()\n  File \"E:\\paper\\paper\\venv\\Lib\\site-packages\\websocket\\_abnf.py\", line 294, in recv_header\n    header = self.recv_strict(2)\n             ^^^^^^^^^^^^^^^^^^^\n  File \"E:\\paper\\paper\\venv\\Lib\\site-packages\\websocket\\_abnf.py\", line 373, in recv_strict\n    bytes_ = self.recv(min(16384, shortage))\n             ^^^^^^^^^^^^^^^^^^^^^^^^^^^^^^^\n  File \"E:\\paper\\paper\\venv\\Lib\\site-packages\\websocket\\_core.py\", line 529, in _recv\n    return recv(self.sock, bufsize)\n           ^^^^^^^^^^^^^^^^^^^^^^^^\n  File \"E:\\paper\\paper\\venv\\Lib\\site-packages\\websocket\\_socket.py\", line 122, in recv\n    raise WebSocketConnectionClosedException(\nwebsocket._exceptions.WebSocketConnectionClosedException: Connection to remote host was lost.\n\nDuring handling of the above exception, another exception occurred:\n\nTraceback (most recent call last):\n  File \"E:\\paper\\paper\\venv\\Lib\\site-packages\\urllib3\\connection.py\", line 174, in _new_conn\n    conn = connection.create_connection(\n           ^^^^^^^^^^^^^^^^^^^^^^^^^^^^^\n  File \"E:\\paper\\paper\\venv\\Lib\\site-packages\\urllib3\\util\\connection.py\", line 72, in create_connection\n    for res in socket.getaddrinfo(host, port, family, socket.SOCK_STREAM):\n               ^^^^^^^^^^^^^^^^^^^^^^^^^^^^^^^^^^^^^^^^^^^^^^^^^^^^^^^^^^\n  File \"C:\\Users\\hp\\AppData\\Local\\Programs\\Python\\Python312\\Lib\\socket.py\", line 963, in getaddrinfo\n    for res in _socket.getaddrinfo(host, port, family, type, proto, flags):\n               ^^^^^^^^^^^^^^^^^^^^^^^^^^^^^^^^^^^^^^^^^^^^^^^^^^^^^^^^^^^\nsocket.gaierror: [Errno 11001] getaddrinfo failed\n\nDuring handling of the above exception, another exception occurred:\n\nTraceback (most recent call last):\n  File \"E:\\paper\\paper\\venv\\Lib\\site-packages\\urllib3\\connectionpool.py\", line 716, in urlopen\n    httplib_response = self._make_request(\n                       ^^^^^^^^^^^^^^^^^^^\n  File \"E:\\paper\\paper\\venv\\Lib\\site-packages\\urllib3\\connectionpool.py\", line 404, in _make_request\n    self._validate_conn(conn)\n  File \"E:\\paper\\paper\\venv\\Lib\\site-packages\\urllib3\\connectionpool.py\", line 1061, in _validate_conn\n    conn.connect()\n  File \"E:\\paper\\paper\\venv\\Lib\\site-packages\\urllib3\\connection.py\", line 363, in connect\n    self.sock = conn = self._new_conn()\n                       ^^^^^^^^^^^^^^^^\n  File \"E:\\paper\\paper\\venv\\Lib\\site-packages\\urllib3\\connection.py\", line 186, in _new_conn\n    raise NewConnectionError(\nurllib3.exceptions.NewConnectionError: <urllib3.connection.HTTPSConnection object at 0x0000027B4E74D6D0>: Failed to establish a new connection: [Errno 11001] getaddrinfo failed\n\nDuring handling of the above exception, another exception occurred:\n\nTraceback (most recent call last):\n  File \"E:\\paper\\paper\\venv\\Lib\\site-packages\\requests\\adapters.py\", line 486, in send\n    resp = conn.urlopen(\n           ^^^^^^^^^^^^^\n  File \"E:\\paper\\paper\\venv\\Lib\\site-packages\\urllib3\\connectionpool.py\", line 802, in urlopen\n    retries = retries.increment(\n              ^^^^^^^^^^^^^^^^^^\n  File \"E:\\paper\\paper\\venv\\Lib\\site-packages\\urllib3\\util\\retry.py\", line 594, in increment\n    raise MaxRetryError(_pool, url, error or ResponseError(cause))\nurllib3.exceptions.MaxRetryError: HTTPSConnectionPool(host='api-t1.fyers.in', port=443): Max retries exceeded with url: /data/symbol-token (Caused by NewConnectionError('<urllib3.connection.HTTPSConnection object at 0x0000027B4E74D6D0>: Failed to establish a new connection: [Errno 11001] getaddrinfo failed'))\n\nDuring handling of the above exception, another exception occurred:\n\nTraceback (most recent call last):\n  File \"E:\\paper\\paper\\venv\\Lib\\site-packages\\fyers_apiv3\\FyersWebsocket\\data_ws.py\", line 63, in symbol_to_hsmtoken\n    response = requests.post(\n               ^^^^^^^^^^^^^^\n  File \"E:\\paper\\paper\\venv\\Lib\\site-packages\\requests\\api.py\", line 115, in post\n    return request(\"post\", url, data=data, json=json, **kwargs)\n           ^^^^^^^^^^^^^^^^^^^^^^^^^^^^^^^^^^^^^^^^^^^^^^^^^^^^\n  File \"E:\\paper\\paper\\venv\\Lib\\site-packages\\requests\\api.py\", line 59, in request\n    return session.request(method=method, url=url, **kwargs)\n           ^^^^^^^^^^^^^^^^^^^^^^^^^^^^^^^^^^^^^^^^^^^^^^^^^\n  File \"E:\\paper\\paper\\venv\\Lib\\site-packages\\requests\\sessions.py\", line 589, in request\n    resp = self.send(prep, **send_kwargs)\n           ^^^^^^^^^^^^^^^^^^^^^^^^^^^^^^\n  File \"E:\\paper\\paper\\venv\\Lib\\site-packages\\requests\\sessions.py\", line 703, in send\n    r = adapter.send(request, **kwargs)\n        ^^^^^^^^^^^^^^^^^^^^^^^^^^^^^^^\n  File \"E:\\paper\\paper\\venv\\Lib\\site-packages\\requests\\adapters.py\", line 519, in send\n    raise ConnectionError(e, request=request)\nrequests.exceptions.ConnectionError: HTTPSConnectionPool(host='api-t1.fyers.in', port=443): Max retries exceeded with url: /data/symbol-token (Caused by NewConnectionError('<urllib3.connection.HTTPSConnection object at 0x0000027B4E74D6D0>: Failed to establish a new connection: [Errno 11001] getaddrinfo failed'))","exception_name":"ConnectionError"}
{"level":"ERROR","location":"[__symbol_conversion:1374] data_ws","message":"'NoneType' object is not subscriptable","timestamp":"2025-10-19 23:14:50,313+0530","service":"FyersDataSocket","exception":"Traceback (most recent call last):\n  File \"E:\\paper\\paper\\venv\\Lib\\site-packages\\websocket\\_app.py\", line 428, in setSock\n    dispatcher.read(self.sock.sock, read, check)\n  File \"E:\\paper\\paper\\venv\\Lib\\site-packages\\websocket\\_app.py\", line 99, in read\n    if not read_callback():\n           ^^^^^^^^^^^^^^^\n  File \"E:\\paper\\paper\\venv\\Lib\\site-packages\\websocket\\_app.py\", line 442, in read\n    raise e\n  File \"E:\\paper\\paper\\venv\\Lib\\site-packages\\websocket\\_app.py\", line 437, in read\n    op_code, frame = self.sock.recv_data_frame(True)\n                     ^^^^^^^^^^^^^^^^^^^^^^^^^^^^^^^\n  File \"E:\\paper\\paper\\venv\\Lib\\site-packages\\websocket\\_core.py\", line 406, in recv_data_frame\n    frame = self.recv_frame()\n            ^^^^^^^^^^^^^^^^^\n  File \"E:\\paper\\paper\\venv\\Lib\\site-packages\\websocket\\_core.py\", line 445, in recv_frame\n    return self.frame_buffer.recv_frame()\n           ^^^^^^^^^^^^^^^^^^^^^^^^^^^^^^\n  File \"E:\\paper\\paper\\venv\\Lib\\site-packages\\websocket\\_abnf.py\", line 338, in recv_frame\n    self.recv_header()\n  File \"E:\\paper\\paper\\venv\\Lib\\site-packages\\websocket\\_abnf.py\", line 294, in recv_header\n    header = self.recv_strict(2)\n             ^^^^^^^^^^^^^^^^^^^\n  File \"E:\\paper\\paper\\venv\\Lib\\site-packages\\websocket\\_abnf.py\", line 373, in recv_strict\n    bytes_ = self.recv(min(16384, shortage))\n             ^^^^^^^^^^^^^^^^^^^^^^^^^^^^^^^\n  File \"E:\\paper\\paper\\venv\\Lib\\site-packages\\websocket\\_core.py\", line 529, in _recv\n    return recv(self.sock, bufsize)\n           ^^^^^^^^^^^^^^^^^^^^^^^^\n  File \"E:\\paper\\paper\\venv\\Lib\\site-packages\\websocket\\_socket.py\", line 122, in recv\n    raise WebSocketConnectionClosedException(\nwebsocket._exceptions.WebSocketConnectionClosedException: Connection to remote host was lost.\n\nDuring handling of the above exception, another exception occurred:\n\nTraceback (most recent call last):\n  File \"E:\\paper\\paper\\venv\\Lib\\site-packages\\fyers_apiv3\\FyersWebsocket\\data_ws.py\", line 1333, in __symbol_conversion\n    if symbol_value[3] != \"\":\n       ~~~~~~~~~~~~^^^\nTypeError: 'NoneType' object is not subscriptable","exception_name":"TypeError"}
{"level":"ERROR","location":"[<lambda>:1663] data_ws","message":"[Errno 11001] getaddrinfo failed","timestamp":"2025-10-19 23:14:53,170+0530","service":"FyersDataSocket"}
{"level":"ERROR","location":"[symbol_to_hsmtoken:126] data_ws","message":"HTTPSConnectionPool(host='api-t1.fyers.in', port=443): Max retries exceeded with url: /data/symbol-token (Caused by NewConnectionError('<urllib3.connection.HTTPSConnection object at 0x0000027B4E74D9A0>: Failed to establish a new connection: [Errno 11001] getaddrinfo failed'))","timestamp":"2025-10-19 23:14:55,173+0530","service":"FyersDataSocket","exception":"Traceback (most recent call last):\n  File \"E:\\paper\\paper\\venv\\Lib\\site-packages\\websocket\\_http.py\", line 155, in _get_addrinfo_list\n    addrinfo_list = socket.getaddrinfo(\n                    ^^^^^^^^^^^^^^^^^^^\n  File \"C:\\Users\\hp\\AppData\\Local\\Programs\\Python\\Python312\\Lib\\socket.py\", line 963, in getaddrinfo\n    for res in _socket.getaddrinfo(host, port, family, type, proto, flags):\n               ^^^^^^^^^^^^^^^^^^^^^^^^^^^^^^^^^^^^^^^^^^^^^^^^^^^^^^^^^^^\nsocket.gaierror: [Errno 11001] getaddrinfo failed\n\nDuring handling of the above exception, another exception occurred:\n\nTraceback (most recent call last):\n  File \"E:\\paper\\paper\\venv\\Lib\\site-packages\\websocket\\_app.py\", line 412, in setSock\n    self.sock.connect(\n  File \"E:\\paper\\paper\\venv\\Lib\\site-packages\\websocket\\_core.py\", line 249, in connect\n    self.sock, addrs = connect(url, self.sock_opt, proxy_info(**options),\n                       ^^^^^^^^^^^^^^^^^^^^^^^^^^^^^^^^^^^^^^^^^^^^^^^^^^\n  File \"E:\\paper\\paper\\venv\\Lib\\site-packages\\websocket\\_http.py\", line 122, in connect\n    addrinfo_list, need_tunnel, auth = _get_addrinfo_list(\n                                       ^^^^^^^^^^^^^^^^^^^\n  File \"E:\\paper\\paper\\venv\\Lib\\site-packages\\websocket\\_http.py\", line 167, in _get_addrinfo_list\n    raise WebSocketAddressException(e)\nwebsocket._exceptions.WebSocketAddressException: [Errno 11001] getaddrinfo failed\n\nDuring handling of the above exception, another exception occurred:\n\nTraceback (most recent call last):\n  File \"E:\\paper\\paper\\venv\\Lib\\site-packages\\urllib3\\connection.py\", line 174, in _new_conn\n    conn = connection.create_connection(\n           ^^^^^^^^^^^^^^^^^^^^^^^^^^^^^\n  File \"E:\\paper\\paper\\venv\\Lib\\site-packages\\urllib3\\util\\connection.py\", line 72, in create_connection\n    for res in socket.getaddrinfo(host, port, family, socket.SOCK_STREAM):\n               ^^^^^^^^^^^^^^^^^^^^^^^^^^^^^^^^^^^^^^^^^^^^^^^^^^^^^^^^^^\n  File \"C:\\Users\\hp\\AppData\\Local\\Programs\\Python\\Python312\\Lib\\socket.py\", line 963, in getaddrinfo\n    for res in _socket.getaddrinfo(host, port, family, type, proto, flags):\n               ^^^^^^^^^^^^^^^^^^^^^^^^^^^^^^^^^^^^^^^^^^^^^^^^^^^^^^^^^^^\nsocket.gaierror: [Errno 11001] getaddrinfo failed\n\nDuring handling of the above exception, another exception occurred:\n\nTraceback (most recent call last):\n  File \"E:\\paper\\paper\\venv\\Lib\\site-packages\\urllib3\\connectionpool.py\", line 716, in urlopen\n    httplib_response = self._make_request(\n                       ^^^^^^^^^^^^^^^^^^^\n  File \"E:\\paper\\paper\\venv\\Lib\\site-packages\\urllib3\\connectionpool.py\", line 404, in _make_request\n    self._validate_conn(conn)\n  File \"E:\\paper\\paper\\venv\\Lib\\site-packages\\urllib3\\connectionpool.py\", line 1061, in _validate_conn\n    conn.connect()\n  File \"E:\\paper\\paper\\venv\\Lib\\site-packages\\urllib3\\connection.py\", line 363, in connect\n    self.sock = conn = self._new_conn()\n                       ^^^^^^^^^^^^^^^^\n  File \"E:\\paper\\paper\\venv\\Lib\\site-packages\\urllib3\\connection.py\", line 186, in _new_conn\n    raise NewConnectionError(\nurllib3.exceptions.NewConnectionError: <urllib3.connection.HTTPSConnection object at 0x0000027B4E74D9A0>: Failed to establish a new connection: [Errno 11001] getaddrinfo failed\n\nDuring handling of the above exception, another exception occurred:\n\nTraceback (most recent call last):\n  File \"E:\\paper\\paper\\venv\\Lib\\site-packages\\requests\\adapters.py\", line 486, in send\n    resp = conn.urlopen(\n           ^^^^^^^^^^^^^\n  File \"E:\\paper\\paper\\venv\\Lib\\site-packages\\urllib3\\connectionpool.py\", line 802, in urlopen\n    retries = retries.increment(\n              ^^^^^^^^^^^^^^^^^^\n  File \"E:\\paper\\paper\\venv\\Lib\\site-packages\\urllib3\\util\\retry.py\", line 594, in increment\n    raise MaxRetryError(_pool, url, error or ResponseError(cause))\nurllib3.exceptions.MaxRetryError: HTTPSConnectionPool(host='api-t1.fyers.in', port=443): Max retries exceeded with url: /data/symbol-token (Caused by NewConnectionError('<urllib3.connection.HTTPSConnection object at 0x0000027B4E74D9A0>: Failed to establish a new connection: [Errno 11001] getaddrinfo failed'))\n\nDuring handling of the above exception, another exception occurred:\n\nTraceback (most recent call last):\n  File \"E:\\paper\\paper\\venv\\Lib\\site-packages\\fyers_apiv3\\FyersWebsocket\\data_ws.py\", line 63, in symbol_to_hsmtoken\n    response = requests.post(\n               ^^^^^^^^^^^^^^\n  File \"E:\\paper\\paper\\venv\\Lib\\site-packages\\requests\\api.py\", line 115, in post\n    return request(\"post\", url, data=data, json=json, **kwargs)\n           ^^^^^^^^^^^^^^^^^^^^^^^^^^^^^^^^^^^^^^^^^^^^^^^^^^^^\n  File \"E:\\paper\\paper\\venv\\Lib\\site-packages\\requests\\api.py\", line 59, in request\n    return session.request(method=method, url=url, **kwargs)\n           ^^^^^^^^^^^^^^^^^^^^^^^^^^^^^^^^^^^^^^^^^^^^^^^^^\n  File \"E:\\paper\\paper\\venv\\Lib\\site-packages\\requests\\sessions.py\", line 589, in request\n    resp = self.send(prep, **send_kwargs)\n           ^^^^^^^^^^^^^^^^^^^^^^^^^^^^^^\n  File \"E:\\paper\\paper\\venv\\Lib\\site-packages\\requests\\sessions.py\", line 703, in send\n    r = adapter.send(request, **kwargs)\n        ^^^^^^^^^^^^^^^^^^^^^^^^^^^^^^^\n  File \"E:\\paper\\paper\\venv\\Lib\\site-packages\\requests\\adapters.py\", line 519, in send\n    raise ConnectionError(e, request=request)\nrequests.exceptions.ConnectionError: HTTPSConnectionPool(host='api-t1.fyers.in', port=443): Max retries exceeded with url: /data/symbol-token (Caused by NewConnectionError('<urllib3.connection.HTTPSConnection object at 0x0000027B4E74D9A0>: Failed to establish a new connection: [Errno 11001] getaddrinfo failed'))","exception_name":"ConnectionError"}
{"level":"ERROR","location":"[__symbol_conversion:1374] data_ws","message":"'NoneType' object is not subscriptable","timestamp":"2025-10-19 23:14:55,192+0530","service":"FyersDataSocket","exception":"Traceback (most recent call last):\n  File \"E:\\paper\\paper\\venv\\Lib\\site-packages\\websocket\\_http.py\", line 155, in _get_addrinfo_list\n    addrinfo_list = socket.getaddrinfo(\n                    ^^^^^^^^^^^^^^^^^^^\n  File \"C:\\Users\\hp\\AppData\\Local\\Programs\\Python\\Python312\\Lib\\socket.py\", line 963, in getaddrinfo\n    for res in _socket.getaddrinfo(host, port, family, type, proto, flags):\n               ^^^^^^^^^^^^^^^^^^^^^^^^^^^^^^^^^^^^^^^^^^^^^^^^^^^^^^^^^^^\nsocket.gaierror: [Errno 11001] getaddrinfo failed\n\nDuring handling of the above exception, another exception occurred:\n\nTraceback (most recent call last):\n  File \"E:\\paper\\paper\\venv\\Lib\\site-packages\\websocket\\_app.py\", line 412, in setSock\n    self.sock.connect(\n  File \"E:\\paper\\paper\\venv\\Lib\\site-packages\\websocket\\_core.py\", line 249, in connect\n    self.sock, addrs = connect(url, self.sock_opt, proxy_info(**options),\n                       ^^^^^^^^^^^^^^^^^^^^^^^^^^^^^^^^^^^^^^^^^^^^^^^^^^\n  File \"E:\\paper\\paper\\venv\\Lib\\site-packages\\websocket\\_http.py\", line 122, in connect\n    addrinfo_list, need_tunnel, auth = _get_addrinfo_list(\n                                       ^^^^^^^^^^^^^^^^^^^\n  File \"E:\\paper\\paper\\venv\\Lib\\site-packages\\websocket\\_http.py\", line 167, in _get_addrinfo_list\n    raise WebSocketAddressException(e)\nwebsocket._exceptions.WebSocketAddressException: [Errno 11001] getaddrinfo failed\n\nDuring handling of the above exception, another exception occurred:\n\nTraceback (most recent call last):\n  File \"E:\\paper\\paper\\venv\\Lib\\site-packages\\fyers_apiv3\\FyersWebsocket\\data_ws.py\", line 1333, in __symbol_conversion\n    if symbol_value[3] != \"\":\n       ~~~~~~~~~~~~^^^\nTypeError: 'NoneType' object is not subscriptable","exception_name":"TypeError"}
{"level":"ERROR","location":"[<lambda>:1663] data_ws","message":"EOF occurred in violation of protocol (_ssl.c:2406)","timestamp":"2025-10-19 23:37:11,311+0530","service":"FyersDataSocket"}
{"level":"ERROR","location":"[<lambda>:1663] data_ws","message":"EOF occurred in violation of protocol (_ssl.c:2406)","timestamp":"2025-10-20 01:16:53,300+0530","service":"FyersDataSocket"}
{"level":"ERROR","location":"[<lambda>:1663] data_ws","message":"Connection to remote host was lost.","timestamp":"2025-10-20 02:02:00,983+0530","service":"FyersDataSocket"}
{"level":"ERROR","location":"[access_token_to_hsmtoken:272] data_ws","message":{"type":"cn","code":-99,"message":"Token is expired","s":"error"},"timestamp":"2025-10-20 09:45:01,258+0530","service":"FyersDataSocket"}
{"level":"ERROR","location":"[symbol_to_hsmtoken:126] data_ws","message":"HTTPSConnectionPool(host='api-t1.fyers.in', port=443): Max retries exceeded with url: /data/symbol-token (Caused by NewConnectionError('<urllib3.connection.HTTPSConnection object at 0x000002A76E8A8E30>: Failed to establish a new connection: [Errno 11001] getaddrinfo failed'))","timestamp":"2025-10-20 09:45:03,289+0530","service":"FyersDataSocket","exception":"Traceback (most recent call last):\n  File \"E:\\paper\\paper\\venv\\Lib\\site-packages\\websocket\\_app.py\", line 428, in setSock\n    dispatcher.read(self.sock.sock, read, check)\n  File \"E:\\paper\\paper\\venv\\Lib\\site-packages\\websocket\\_app.py\", line 99, in read\n    if not read_callback():\n           ^^^^^^^^^^^^^^^\n  File \"E:\\paper\\paper\\venv\\Lib\\site-packages\\websocket\\_app.py\", line 442, in read\n    raise e\n  File \"E:\\paper\\paper\\venv\\Lib\\site-packages\\websocket\\_app.py\", line 437, in read\n    op_code, frame = self.sock.recv_data_frame(True)\n                     ^^^^^^^^^^^^^^^^^^^^^^^^^^^^^^^\n  File \"E:\\paper\\paper\\venv\\Lib\\site-packages\\websocket\\_core.py\", line 406, in recv_data_frame\n    frame = self.recv_frame()\n            ^^^^^^^^^^^^^^^^^\n  File \"E:\\paper\\paper\\venv\\Lib\\site-packages\\websocket\\_core.py\", line 445, in recv_frame\n    return self.frame_buffer.recv_frame()\n           ^^^^^^^^^^^^^^^^^^^^^^^^^^^^^^\n  File \"E:\\paper\\paper\\venv\\Lib\\site-packages\\websocket\\_abnf.py\", line 338, in recv_frame\n    self.recv_header()\n  File \"E:\\paper\\paper\\venv\\Lib\\site-packages\\websocket\\_abnf.py\", line 294, in recv_header\n    header = self.recv_strict(2)\n             ^^^^^^^^^^^^^^^^^^^\n  File \"E:\\paper\\paper\\venv\\Lib\\site-packages\\websocket\\_abnf.py\", line 373, in recv_strict\n    bytes_ = self.recv(min(16384, shortage))\n             ^^^^^^^^^^^^^^^^^^^^^^^^^^^^^^^\n  File \"E:\\paper\\paper\\venv\\Lib\\site-packages\\websocket\\_core.py\", line 529, in _recv\n    return recv(self.sock, bufsize)\n           ^^^^^^^^^^^^^^^^^^^^^^^^\n  File \"E:\\paper\\paper\\venv\\Lib\\site-packages\\websocket\\_socket.py\", line 122, in recv\n    raise WebSocketConnectionClosedException(\nwebsocket._exceptions.WebSocketConnectionClosedException: Connection to remote host was lost.\n\nDuring handling of the above exception, another exception occurred:\n\nTraceback (most recent call last):\n  File \"E:\\paper\\paper\\venv\\Lib\\site-packages\\urllib3\\connection.py\", line 174, in _new_conn\n    conn = connection.create_connection(\n           ^^^^^^^^^^^^^^^^^^^^^^^^^^^^^\n  File \"E:\\paper\\paper\\venv\\Lib\\site-packages\\urllib3\\util\\connection.py\", line 72, in create_connection\n    for res in socket.getaddrinfo(host, port, family, socket.SOCK_STREAM):\n               ^^^^^^^^^^^^^^^^^^^^^^^^^^^^^^^^^^^^^^^^^^^^^^^^^^^^^^^^^^\n  File \"C:\\Users\\hp\\AppData\\Local\\Programs\\Python\\Python312\\Lib\\socket.py\", line 963, in getaddrinfo\n    for res in _socket.getaddrinfo(host, port, family, type, proto, flags):\n               ^^^^^^^^^^^^^^^^^^^^^^^^^^^^^^^^^^^^^^^^^^^^^^^^^^^^^^^^^^^\nsocket.gaierror: [Errno 11001] getaddrinfo failed\n\nDuring handling of the above exception, another exception occurred:\n\nTraceback (most recent call last):\n  File \"E:\\paper\\paper\\venv\\Lib\\site-packages\\urllib3\\connectionpool.py\", line 716, in urlopen\n    httplib_response = self._make_request(\n                       ^^^^^^^^^^^^^^^^^^^\n  File \"E:\\paper\\paper\\venv\\Lib\\site-packages\\urllib3\\connectionpool.py\", line 404, in _make_request\n    self._validate_conn(conn)\n  File \"E:\\paper\\paper\\venv\\Lib\\site-packages\\urllib3\\connectionpool.py\", line 1061, in _validate_conn\n    conn.connect()\n  File \"E:\\paper\\paper\\venv\\Lib\\site-packages\\urllib3\\connection.py\", line 363, in connect\n    self.sock = conn = self._new_conn()\n                       ^^^^^^^^^^^^^^^^\n  File \"E:\\paper\\paper\\venv\\Lib\\site-packages\\urllib3\\connection.py\", line 186, in _new_conn\n    raise NewConnectionError(\nurllib3.exceptions.NewConnectionError: <urllib3.connection.HTTPSConnection object at 0x000002A76E8A8E30>: Failed to establish a new connection: [Errno 11001] getaddrinfo failed\n\nDuring handling of the above exception, another exception occurred:\n\nTraceback (most recent call last):\n  File \"E:\\paper\\paper\\venv\\Lib\\site-packages\\requests\\adapters.py\", line 486, in send\n    resp = conn.urlopen(\n           ^^^^^^^^^^^^^\n  File \"E:\\paper\\paper\\venv\\Lib\\site-packages\\urllib3\\connectionpool.py\", line 802, in urlopen\n    retries = retries.increment(\n              ^^^^^^^^^^^^^^^^^^\n  File \"E:\\paper\\paper\\venv\\Lib\\site-packages\\urllib3\\util\\retry.py\", line 594, in increment\n    raise MaxRetryError(_pool, url, error or ResponseError(cause))\nurllib3.exceptions.MaxRetryError: HTTPSConnectionPool(host='api-t1.fyers.in', port=443): Max retries exceeded with url: /data/symbol-token (Caused by NewConnectionError('<urllib3.connection.HTTPSConnection object at 0x000002A76E8A8E30>: Failed to establish a new connection: [Errno 11001] getaddrinfo failed'))\n\nDuring handling of the above exception, another exception occurred:\n\nTraceback (most recent call last):\n  File \"E:\\paper\\paper\\venv\\Lib\\site-packages\\fyers_apiv3\\FyersWebsocket\\data_ws.py\", line 63, in symbol_to_hsmtoken\n    response = requests.post(\n               ^^^^^^^^^^^^^^\n  File \"E:\\paper\\paper\\venv\\Lib\\site-packages\\requests\\api.py\", line 115, in post\n    return request(\"post\", url, data=data, json=json, **kwargs)\n           ^^^^^^^^^^^^^^^^^^^^^^^^^^^^^^^^^^^^^^^^^^^^^^^^^^^^\n  File \"E:\\paper\\paper\\venv\\Lib\\site-packages\\requests\\api.py\", line 59, in request\n    return session.request(method=method, url=url, **kwargs)\n           ^^^^^^^^^^^^^^^^^^^^^^^^^^^^^^^^^^^^^^^^^^^^^^^^^\n  File \"E:\\paper\\paper\\venv\\Lib\\site-packages\\requests\\sessions.py\", line 589, in request\n    resp = self.send(prep, **send_kwargs)\n           ^^^^^^^^^^^^^^^^^^^^^^^^^^^^^^\n  File \"E:\\paper\\paper\\venv\\Lib\\site-packages\\requests\\sessions.py\", line 703, in send\n    r = adapter.send(request, **kwargs)\n        ^^^^^^^^^^^^^^^^^^^^^^^^^^^^^^^\n  File \"E:\\paper\\paper\\venv\\Lib\\site-packages\\requests\\adapters.py\", line 519, in send\n    raise ConnectionError(e, request=request)\nrequests.exceptions.ConnectionError: HTTPSConnectionPool(host='api-t1.fyers.in', port=443): Max retries exceeded with url: /data/symbol-token (Caused by NewConnectionError('<urllib3.connection.HTTPSConnection object at 0x000002A76E8A8E30>: Failed to establish a new connection: [Errno 11001] getaddrinfo failed'))","exception_name":"ConnectionError"}
{"level":"ERROR","location":"[__symbol_conversion:1374] data_ws","message":"'NoneType' object is not subscriptable","timestamp":"2025-10-20 09:45:03,427+0530","service":"FyersDataSocket","exception":"Traceback (most recent call last):\n  File \"E:\\paper\\paper\\venv\\Lib\\site-packages\\websocket\\_app.py\", line 428, in setSock\n    dispatcher.read(self.sock.sock, read, check)\n  File \"E:\\paper\\paper\\venv\\Lib\\site-packages\\websocket\\_app.py\", line 99, in read\n    if not read_callback():\n           ^^^^^^^^^^^^^^^\n  File \"E:\\paper\\paper\\venv\\Lib\\site-packages\\websocket\\_app.py\", line 442, in read\n    raise e\n  File \"E:\\paper\\paper\\venv\\Lib\\site-packages\\websocket\\_app.py\", line 437, in read\n    op_code, frame = self.sock.recv_data_frame(True)\n                     ^^^^^^^^^^^^^^^^^^^^^^^^^^^^^^^\n  File \"E:\\paper\\paper\\venv\\Lib\\site-packages\\websocket\\_core.py\", line 406, in recv_data_frame\n    frame = self.recv_frame()\n            ^^^^^^^^^^^^^^^^^\n  File \"E:\\paper\\paper\\venv\\Lib\\site-packages\\websocket\\_core.py\", line 445, in recv_frame\n    return self.frame_buffer.recv_frame()\n           ^^^^^^^^^^^^^^^^^^^^^^^^^^^^^^\n  File \"E:\\paper\\paper\\venv\\Lib\\site-packages\\websocket\\_abnf.py\", line 338, in recv_frame\n    self.recv_header()\n  File \"E:\\paper\\paper\\venv\\Lib\\site-packages\\websocket\\_abnf.py\", line 294, in recv_header\n    header = self.recv_strict(2)\n             ^^^^^^^^^^^^^^^^^^^\n  File \"E:\\paper\\paper\\venv\\Lib\\site-packages\\websocket\\_abnf.py\", line 373, in recv_strict\n    bytes_ = self.recv(min(16384, shortage))\n             ^^^^^^^^^^^^^^^^^^^^^^^^^^^^^^^\n  File \"E:\\paper\\paper\\venv\\Lib\\site-packages\\websocket\\_core.py\", line 529, in _recv\n    return recv(self.sock, bufsize)\n           ^^^^^^^^^^^^^^^^^^^^^^^^\n  File \"E:\\paper\\paper\\venv\\Lib\\site-packages\\websocket\\_socket.py\", line 122, in recv\n    raise WebSocketConnectionClosedException(\nwebsocket._exceptions.WebSocketConnectionClosedException: Connection to remote host was lost.\n\nDuring handling of the above exception, another exception occurred:\n\nTraceback (most recent call last):\n  File \"E:\\paper\\paper\\venv\\Lib\\site-packages\\fyers_apiv3\\FyersWebsocket\\data_ws.py\", line 1333, in __symbol_conversion\n    if symbol_value[3] != \"\":\n       ~~~~~~~~~~~~^^^\nTypeError: 'NoneType' object is not subscriptable","exception_name":"TypeError"}
