{"level":"ERROR","location":"[__symbol_conversion:1374] data_ws","message":"'set' object is not subscriptable","timestamp":"2025-10-12 00:25:24,435+0530","service":"FyersDataSocket","exception":"Traceback (most recent call last):\n  File \"E:\\paper\\paper\\venv\\Lib\\site-packages\\fyers_apiv3\\FyersWebsocket\\data_ws.py\", line 1328, in __symbol_conversion\n    symbolslst[i : i + 500] for i in range(0, total_symbols, 500)\n    ~~~~~~~~~~^^^^^^^^^^^^^\nTypeError: 'set' object is not subscriptable","exception_name":"TypeError"}
{"level":"ERROR","location":"[On_message:1446] data_ws","message":"no running event loop","timestamp":"2025-10-12 00:49:03,358+0530","service":"FyersDataSocket","exception":"Traceback (most recent call last):\n  File \"E:\\paper\\paper\\venv\\Lib\\site-packages\\fyers_apiv3\\FyersWebsocket\\data_ws.py\", line 1433, in On_message\n    self.OnMessage(message)\n  File \"E:\\paper\\paper\\app\\services\\fyerService.py\", line 362, in <lambda>\n    on_message=lambda msg: asyncio.create_task(handle_message(msg))\n                           ^^^^^^^^^^^^^^^^^^^^^^^^^^^^^^^^^^^^^^^^\n  File \"C:\\Users\\hp\\AppData\\Local\\Programs\\Python\\Python312\\Lib\\asyncio\\tasks.py\", line 417, in create_task\n    loop = events.get_running_loop()\n           ^^^^^^^^^^^^^^^^^^^^^^^^^\nRuntimeError: no running event loop","exception_name":"RuntimeError"}
{"level":"ERROR","location":"[On_message:1447] data_ws","message":"no running event loop","timestamp":"2025-10-12 00:49:03,374+0530","service":"FyersDataSocket"}
{"level":"ERROR","location":"[On_message:1446] data_ws","message":"no running event loop","timestamp":"2025-10-12 00:49:03,458+0530","service":"FyersDataSocket","exception":"Traceback (most recent call last):\n  File \"E:\\paper\\paper\\venv\\Lib\\site-packages\\fyers_apiv3\\FyersWebsocket\\data_ws.py\", line 1433, in On_message\n    self.OnMessage(message)\n  File \"E:\\paper\\paper\\app\\services\\fyerService.py\", line 362, in <lambda>\n    on_message=lambda msg: asyncio.create_task(handle_message(msg))\n                           ^^^^^^^^^^^^^^^^^^^^^^^^^^^^^^^^^^^^^^^^\n  File \"C:\\Users\\hp\\AppData\\Local\\Programs\\Python\\Python312\\Lib\\asyncio\\tasks.py\", line 417, in create_task\n    loop = events.get_running_loop()\n           ^^^^^^^^^^^^^^^^^^^^^^^^^\nRuntimeError: no running event loop","exception_name":"RuntimeError"}
{"level":"ERROR","location":"[On_message:1447] data_ws","message":"no running event loop","timestamp":"2025-10-12 00:49:03,458+0530","service":"FyersDataSocket"}
{"level":"ERROR","location":"[On_message:1446] data_ws","message":"no running event loop","timestamp":"2025-10-12 00:49:06,053+0530","service":"FyersDataSocket","exception":"Traceback (most recent call last):\n  File \"E:\\paper\\paper\\venv\\Lib\\site-packages\\fyers_apiv3\\FyersWebsocket\\data_ws.py\", line 1433, in On_message\n    self.OnMessage(message)\n  File \"E:\\paper\\paper\\app\\services\\fyerService.py\", line 362, in <lambda>\n    on_message=lambda msg: asyncio.create_task(handle_message(msg))\n                           ^^^^^^^^^^^^^^^^^^^^^^^^^^^^^^^^^^^^^^^^\n  File \"C:\\Users\\hp\\AppData\\Local\\Programs\\Python\\Python312\\Lib\\asyncio\\tasks.py\", line 417, in create_task\n    loop = events.get_running_loop()\n           ^^^^^^^^^^^^^^^^^^^^^^^^^\nRuntimeError: no running event loop","exception_name":"RuntimeError"}
{"level":"ERROR","location":"[On_message:1447] data_ws","message":"no running event loop","timestamp":"2025-10-12 00:49:06,055+0530","service":"FyersDataSocket"}
{"level":"ERROR","location":"[On_message:1446] data_ws","message":"no running event loop","timestamp":"2025-10-12 00:49:06,102+0530","service":"FyersDataSocket","exception":"Traceback (most recent call last):\n  File \"E:\\paper\\paper\\venv\\Lib\\site-packages\\fyers_apiv3\\FyersWebsocket\\data_ws.py\", line 1433, in On_message\n    self.OnMessage(message)\n  File \"E:\\paper\\paper\\app\\services\\fyerService.py\", line 362, in <lambda>\n    on_message=lambda msg: asyncio.create_task(handle_message(msg))\n                           ^^^^^^^^^^^^^^^^^^^^^^^^^^^^^^^^^^^^^^^^\n  File \"C:\\Users\\hp\\AppData\\Local\\Programs\\Python\\Python312\\Lib\\asyncio\\tasks.py\", line 417, in create_task\n    loop = events.get_running_loop()\n           ^^^^^^^^^^^^^^^^^^^^^^^^^\nRuntimeError: no running event loop","exception_name":"RuntimeError"}
{"level":"ERROR","location":"[On_message:1447] data_ws","message":"no running event loop","timestamp":"2025-10-12 00:49:06,105+0530","service":"FyersDataSocket"}
{"level":"ERROR","location":"[On_message:1446] data_ws","message":"no running event loop","timestamp":"2025-10-12 00:49:06,105+0530","service":"FyersDataSocket","exception":"Traceback (most recent call last):\n  File \"E:\\paper\\paper\\venv\\Lib\\site-packages\\fyers_apiv3\\FyersWebsocket\\data_ws.py\", line 1433, in On_message\n    self.OnMessage(message)\n  File \"E:\\paper\\paper\\app\\services\\fyerService.py\", line 362, in <lambda>\n    on_message=lambda msg: asyncio.create_task(handle_message(msg))\n                           ^^^^^^^^^^^^^^^^^^^^^^^^^^^^^^^^^^^^^^^^\n  File \"C:\\Users\\hp\\AppData\\Local\\Programs\\Python\\Python312\\Lib\\asyncio\\tasks.py\", line 417, in create_task\n    loop = events.get_running_loop()\n           ^^^^^^^^^^^^^^^^^^^^^^^^^\nRuntimeError: no running event loop","exception_name":"RuntimeError"}
{"level":"ERROR","location":"[On_message:1447] data_ws","message":"no running event loop","timestamp":"2025-10-12 00:49:06,108+0530","service":"FyersDataSocket"}
{"level":"ERROR","location":"[<lambda>:1663] data_ws","message":"Connection to remote host was lost.","timestamp":"2025-10-12 01:38:23,890+0530","service":"FyersDataSocket"}
{"level":"ERROR","location":"[<lambda>:1663] data_ws","message":"[Errno 11001] getaddrinfo failed","timestamp":"2025-10-12 05:07:14,570+0530","service":"FyersDataSocket"}
{"level":"ERROR","location":"[<lambda>:1663] data_ws","message":"Connection to remote host was lost.","timestamp":"2025-10-12 11:00:32,295+0530","service":"FyersDataSocket"}
{"level":"ERROR","location":"[access_token_to_hsmtoken:272] data_ws","message":{"type":"cn","code":-99,"message":"Token is expired","s":"error"},"timestamp":"2025-10-12 11:00:37,298+0530","service":"FyersDataSocket"}
{"level":"ERROR","location":"[__symbol_conversion:1334] data_ws","message":{"code":-300,"message":"Please provide valid token","s":"error","type":"sub"},"timestamp":"2025-10-12 11:00:41,464+0530","service":"FyersDataSocket"}
{"level":"ERROR","location":"[access_token_to_hsmtoken:272] data_ws","message":{"type":"cn","code":-99,"message":"Token is expired","s":"error"},"timestamp":"2025-10-12 11:14:00,564+0530","service":"FyersDataSocket"}
{"level":"ERROR","location":"[access_token_to_hsmtoken:272] data_ws","message":{"type":"cn","code":-99,"message":"Token is expired","s":"error"},"timestamp":"2025-10-12 11:17:11,991+0530","service":"FyersDataSocket"}
{"level":"ERROR","location":"[<lambda>:1663] data_ws","message":"Connection to remote host was lost.","timestamp":"2025-10-12 12:42:17,025+0530","service":"FyersDataSocket"}
{"level":"ERROR","location":"[__symbol_conversion:1352] data_ws","message":{"code":-300,"message":"Please provide a valid symbol","s":"error","type":"sub","invalid_symbols":["NSE:ADANITRANS-EQ","NSE:ADANITOTAL-EQ","NSE:ZOMATO-EQ","NSE:MINDTREE-EQ","NSE:SPICEJET-EQ","MCX:GOLDM","MCX:SILVERM","MCX:CRUDEOILM","MCX:NATURALGAS","MCX:ALUMINIUM","MCX:COPPER","MCX:ZINC","MCX:LEAD","MCX:NICKEL","MCX:MENTHAOIL"]},"timestamp":"2025-10-12 12:44:06,348+0530","service":"FyersDataSocket"}
{"level":"ERROR","location":"[<lambda>:1663] data_ws","message":"Connection to remote host was lost.","timestamp":"2025-10-12 12:44:53,221+0530","service":"FyersDataSocket"}
{"level":"ERROR","location":"[__symbol_conversion:1352] data_ws","message":{"code":-300,"message":"Please provide a valid symbol","s":"error","type":"sub","invalid_symbols":["NSE:ADANITRANS-EQ","NSE:ADANITOTAL-EQ","NSE:ZOMATO-EQ","NSE:MINDTREE-EQ","NSE:SPICEJET-EQ","MCX:GOLDM","MCX:SILVERM","MCX:CRUDEOILM","MCX:NATURALGAS","MCX:ALUMINIUM","MCX:COPPER","MCX:ZINC","MCX:LEAD","MCX:NICKEL","MCX:MENTHAOIL"]},"timestamp":"2025-10-12 12:45:01,168+0530","service":"FyersDataSocket"}
{"level":"ERROR","location":"[__symbol_conversion:1352] data_ws","message":{"code":-300,"message":"Please provide a valid symbol","s":"error","type":"sub","invalid_symbols":["NSE:ADANITRANS-EQ","NSE:ADANITOTAL-EQ","NSE:ZOMATO-EQ","NSE:MINDTREE-EQ","NSE:SPICEJET-EQ","MCX:GOLDM","MCX:SILVERM","MCX:CRUDEOILM","MCX:NATURALGAS","MCX:ALUMINIUM","MCX:COPPER","MCX:ZINC","MCX:LEAD","MCX:NICKEL","MCX:MENTHAOIL"]},"timestamp":"2025-10-12 12:45:28,781+0530","service":"FyersDataSocket"}
{"level":"ERROR","location":"[__symbol_conversion:1352] data_ws","message":{"code":-300,"message":"Please provide a valid symbol","s":"error","type":"sub","invalid_symbols":["NSE:ADANITRANS-EQ","NSE:ADANITOTAL-EQ","NSE:ZOMATO-EQ","NSE:MINDTREE-EQ","NSE:SPICEJET-EQ","MCX:GOLDM","MCX:SILVERM","MCX:CRUDEOILM","MCX:NATURALGAS","MCX:ALUMINIUM","MCX:COPPER","MCX:ZINC","MCX:LEAD","MCX:NICKEL","MCX:MENTHAOIL"]},"timestamp":"2025-10-12 12:46:04,674+0530","service":"FyersDataSocket"}
{"level":"ERROR","location":"[__symbol_conversion:1352] data_ws","message":{"code":-300,"message":"Please provide a valid symbol","s":"error","type":"sub","invalid_symbols":["MCX:GOLD-EQ","MCX:SILVER-EQ","MCX:CRUDEOIL-EQ","MCX:NATURALGAS-EQ","MCX:ALUMINIUM-EQ","MCX:COPPER-EQ","MCX:ZINC-EQ","MCX:LEAD-EQ","MCX:NICKEL-EQ"]},"timestamp":"2025-10-12 12:48:58,529+0530","service":"FyersDataSocket"}
{"level":"ERROR","location":"[__symbol_conversion:1352] data_ws","message":{"code":-300,"message":"Please provide a valid symbol","s":"error","type":"sub","invalid_symbols":["MCX:GOLD","MCX:SILVER-EQ","MCX:CRUDEOIL-EQ","MCX:NATURALGAS-EQ","MCX:ALUMINIUM-EQ","MCX:COPPER-EQ","MCX:ZINC-EQ","MCX:LEAD-EQ","MCX:NICKEL-EQ"]},"timestamp":"2025-10-12 12:50:47,691+0530","service":"FyersDataSocket"}
{"level":"ERROR","location":"[__symbol_conversion:1352] data_ws","message":{"code":-300,"message":"Please provide a valid symbol","s":"error","type":"sub","invalid_symbols":["MCX:GOLD1OCT24FUT"]},"timestamp":"2025-10-12 12:51:53,238+0530","service":"FyersDataSocket"}
{"level":"ERROR","location":"[<lambda>:1663] data_ws","message":"Connection to remote host was lost.","timestamp":"2025-10-12 13:15:18,223+0530","service":"FyersDataSocket"}
{"level":"ERROR","location":"[<lambda>:1663] data_ws","message":"[Errno 11001] getaddrinfo failed","timestamp":"2025-10-12 13:15:23,253+0530","service":"FyersDataSocket"}
{"level":"ERROR","location":"[symbol_to_hsmtoken:126] data_ws","message":"HTTPSConnectionPool(host='api-t1.fyers.in', port=443): Max retries exceeded with url: /data/symbol-token (Caused by NewConnectionError('<urllib3.connection.HTTPSConnection object at 0x000001EE1E2BB590>: Failed to establish a new connection: [Errno 11001] getaddrinfo failed'))","timestamp":"2025-10-12 13:15:25,242+0530","service":"FyersDataSocket","exception":"Traceback (most recent call last):\n  File \"E:\\paper\\paper\\venv\\Lib\\site-packages\\websocket\\_app.py\", line 428, in setSock\n    dispatcher.read(self.sock.sock, read, check)\n  File \"E:\\paper\\paper\\venv\\Lib\\site-packages\\websocket\\_app.py\", line 99, in read\n    if not read_callback():\n           ^^^^^^^^^^^^^^^\n  File \"E:\\paper\\paper\\venv\\Lib\\site-packages\\websocket\\_app.py\", line 442, in read\n    raise e\n  File \"E:\\paper\\paper\\venv\\Lib\\site-packages\\websocket\\_app.py\", line 437, in read\n    op_code, frame = self.sock.recv_data_frame(True)\n                     ^^^^^^^^^^^^^^^^^^^^^^^^^^^^^^^\n  File \"E:\\paper\\paper\\venv\\Lib\\site-packages\\websocket\\_core.py\", line 406, in recv_data_frame\n    frame = self.recv_frame()\n            ^^^^^^^^^^^^^^^^^\n  File \"E:\\paper\\paper\\venv\\Lib\\site-packages\\websocket\\_core.py\", line 445, in recv_frame\n    return self.frame_buffer.recv_frame()\n           ^^^^^^^^^^^^^^^^^^^^^^^^^^^^^^\n  File \"E:\\paper\\paper\\venv\\Lib\\site-packages\\websocket\\_abnf.py\", line 338, in recv_frame\n    self.recv_header()\n  File \"E:\\paper\\paper\\venv\\Lib\\site-packages\\websocket\\_abnf.py\", line 294, in recv_header\n    header = self.recv_strict(2)\n             ^^^^^^^^^^^^^^^^^^^\n  File \"E:\\paper\\paper\\venv\\Lib\\site-packages\\websocket\\_abnf.py\", line 373, in recv_strict\n    bytes_ = self.recv(min(16384, shortage))\n             ^^^^^^^^^^^^^^^^^^^^^^^^^^^^^^^\n  File \"E:\\paper\\paper\\venv\\Lib\\site-packages\\websocket\\_core.py\", line 529, in _recv\n    return recv(self.sock, bufsize)\n           ^^^^^^^^^^^^^^^^^^^^^^^^\n  File \"E:\\paper\\paper\\venv\\Lib\\site-packages\\websocket\\_socket.py\", line 122, in recv\n    raise WebSocketConnectionClosedException(\nwebsocket._exceptions.WebSocketConnectionClosedException: Connection to remote host was lost.\n\nDuring handling of the above exception, another exception occurred:\n\nTraceback (most recent call last):\n  File \"E:\\paper\\paper\\venv\\Lib\\site-packages\\urllib3\\connection.py\", line 174, in _new_conn\n    conn = connection.create_connection(\n           ^^^^^^^^^^^^^^^^^^^^^^^^^^^^^\n  File \"E:\\paper\\paper\\venv\\Lib\\site-packages\\urllib3\\util\\connection.py\", line 72, in create_connection\n    for res in socket.getaddrinfo(host, port, family, socket.SOCK_STREAM):\n               ^^^^^^^^^^^^^^^^^^^^^^^^^^^^^^^^^^^^^^^^^^^^^^^^^^^^^^^^^^\n  File \"C:\\Users\\hp\\AppData\\Local\\Programs\\Python\\Python312\\Lib\\socket.py\", line 963, in getaddrinfo\n    for res in _socket.getaddrinfo(host, port, family, type, proto, flags):\n               ^^^^^^^^^^^^^^^^^^^^^^^^^^^^^^^^^^^^^^^^^^^^^^^^^^^^^^^^^^^\nsocket.gaierror: [Errno 11001] getaddrinfo failed\n\nDuring handling of the above exception, another exception occurred:\n\nTraceback (most recent call last):\n  File \"E:\\paper\\paper\\venv\\Lib\\site-packages\\urllib3\\connectionpool.py\", line 716, in urlopen\n    httplib_response = self._make_request(\n                       ^^^^^^^^^^^^^^^^^^^\n  File \"E:\\paper\\paper\\venv\\Lib\\site-packages\\urllib3\\connectionpool.py\", line 404, in _make_request\n    self._validate_conn(conn)\n  File \"E:\\paper\\paper\\venv\\Lib\\site-packages\\urllib3\\connectionpool.py\", line 1061, in _validate_conn\n    conn.connect()\n  File \"E:\\paper\\paper\\venv\\Lib\\site-packages\\urllib3\\connection.py\", line 363, in connect\n    self.sock = conn = self._new_conn()\n                       ^^^^^^^^^^^^^^^^\n  File \"E:\\paper\\paper\\venv\\Lib\\site-packages\\urllib3\\connection.py\", line 186, in _new_conn\n    raise NewConnectionError(\nurllib3.exceptions.NewConnectionError: <urllib3.connection.HTTPSConnection object at 0x000001EE1E2BB590>: Failed to establish a new connection: [Errno 11001] getaddrinfo failed\n\nDuring handling of the above exception, another exception occurred:\n\nTraceback (most recent call last):\n  File \"E:\\paper\\paper\\venv\\Lib\\site-packages\\requests\\adapters.py\", line 486, in send\n    resp = conn.urlopen(\n           ^^^^^^^^^^^^^\n  File \"E:\\paper\\paper\\venv\\Lib\\site-packages\\urllib3\\connectionpool.py\", line 802, in urlopen\n    retries = retries.increment(\n              ^^^^^^^^^^^^^^^^^^\n  File \"E:\\paper\\paper\\venv\\Lib\\site-packages\\urllib3\\util\\retry.py\", line 594, in increment\n    raise MaxRetryError(_pool, url, error or ResponseError(cause))\nurllib3.exceptions.MaxRetryError: HTTPSConnectionPool(host='api-t1.fyers.in', port=443): Max retries exceeded with url: /data/symbol-token (Caused by NewConnectionError('<urllib3.connection.HTTPSConnection object at 0x000001EE1E2BB590>: Failed to establish a new connection: [Errno 11001] getaddrinfo failed'))\n\nDuring handling of the above exception, another exception occurred:\n\nTraceback (most recent call last):\n  File \"E:\\paper\\paper\\venv\\Lib\\site-packages\\fyers_apiv3\\FyersWebsocket\\data_ws.py\", line 63, in symbol_to_hsmtoken\n    response = requests.post(\n               ^^^^^^^^^^^^^^\n  File \"E:\\paper\\paper\\venv\\Lib\\site-packages\\requests\\api.py\", line 115, in post\n    return request(\"post\", url, data=data, json=json, **kwargs)\n           ^^^^^^^^^^^^^^^^^^^^^^^^^^^^^^^^^^^^^^^^^^^^^^^^^^^^\n  File \"E:\\paper\\paper\\venv\\Lib\\site-packages\\requests\\api.py\", line 59, in request\n    return session.request(method=method, url=url, **kwargs)\n           ^^^^^^^^^^^^^^^^^^^^^^^^^^^^^^^^^^^^^^^^^^^^^^^^^\n  File \"E:\\paper\\paper\\venv\\Lib\\site-packages\\requests\\sessions.py\", line 589, in request\n    resp = self.send(prep, **send_kwargs)\n           ^^^^^^^^^^^^^^^^^^^^^^^^^^^^^^\n  File \"E:\\paper\\paper\\venv\\Lib\\site-packages\\requests\\sessions.py\", line 703, in send\n    r = adapter.send(request, **kwargs)\n        ^^^^^^^^^^^^^^^^^^^^^^^^^^^^^^^\n  File \"E:\\paper\\paper\\venv\\Lib\\site-packages\\requests\\adapters.py\", line 519, in send\n    raise ConnectionError(e, request=request)\nrequests.exceptions.ConnectionError: HTTPSConnectionPool(host='api-t1.fyers.in', port=443): Max retries exceeded with url: /data/symbol-token (Caused by NewConnectionError('<urllib3.connection.HTTPSConnection object at 0x000001EE1E2BB590>: Failed to establish a new connection: [Errno 11001] getaddrinfo failed'))","exception_name":"ConnectionError"}
{"level":"ERROR","location":"[__symbol_conversion:1374] data_ws","message":"'NoneType' object is not subscriptable","timestamp":"2025-10-12 13:15:25,775+0530","service":"FyersDataSocket","exception":"Traceback (most recent call last):\n  File \"E:\\paper\\paper\\venv\\Lib\\site-packages\\websocket\\_app.py\", line 428, in setSock\n    dispatcher.read(self.sock.sock, read, check)\n  File \"E:\\paper\\paper\\venv\\Lib\\site-packages\\websocket\\_app.py\", line 99, in read\n    if not read_callback():\n           ^^^^^^^^^^^^^^^\n  File \"E:\\paper\\paper\\venv\\Lib\\site-packages\\websocket\\_app.py\", line 442, in read\n    raise e\n  File \"E:\\paper\\paper\\venv\\Lib\\site-packages\\websocket\\_app.py\", line 437, in read\n    op_code, frame = self.sock.recv_data_frame(True)\n                     ^^^^^^^^^^^^^^^^^^^^^^^^^^^^^^^\n  File \"E:\\paper\\paper\\venv\\Lib\\site-packages\\websocket\\_core.py\", line 406, in recv_data_frame\n    frame = self.recv_frame()\n            ^^^^^^^^^^^^^^^^^\n  File \"E:\\paper\\paper\\venv\\Lib\\site-packages\\websocket\\_core.py\", line 445, in recv_frame\n    return self.frame_buffer.recv_frame()\n           ^^^^^^^^^^^^^^^^^^^^^^^^^^^^^^\n  File \"E:\\paper\\paper\\venv\\Lib\\site-packages\\websocket\\_abnf.py\", line 338, in recv_frame\n    self.recv_header()\n  File \"E:\\paper\\paper\\venv\\Lib\\site-packages\\websocket\\_abnf.py\", line 294, in recv_header\n    header = self.recv_strict(2)\n             ^^^^^^^^^^^^^^^^^^^\n  File \"E:\\paper\\paper\\venv\\Lib\\site-packages\\websocket\\_abnf.py\", line 373, in recv_strict\n    bytes_ = self.recv(min(16384, shortage))\n             ^^^^^^^^^^^^^^^^^^^^^^^^^^^^^^^\n  File \"E:\\paper\\paper\\venv\\Lib\\site-packages\\websocket\\_core.py\", line 529, in _recv\n    return recv(self.sock, bufsize)\n           ^^^^^^^^^^^^^^^^^^^^^^^^\n  File \"E:\\paper\\paper\\venv\\Lib\\site-packages\\websocket\\_socket.py\", line 122, in recv\n    raise WebSocketConnectionClosedException(\nwebsocket._exceptions.WebSocketConnectionClosedException: Connection to remote host was lost.\n\nDuring handling of the above exception, another exception occurred:\n\nTraceback (most recent call last):\n  File \"E:\\paper\\paper\\venv\\Lib\\site-packages\\fyers_apiv3\\FyersWebsocket\\data_ws.py\", line 1333, in __symbol_conversion\n    if symbol_value[3] != \"\":\n       ~~~~~~~~~~~~^^^\nTypeError: 'NoneType' object is not subscriptable","exception_name":"TypeError"}
{"level":"ERROR","location":"[<lambda>:1663] data_ws","message":"[Errno 11001] getaddrinfo failed","timestamp":"2025-10-12 13:15:28,287+0530","service":"FyersDataSocket"}
{"level":"ERROR","location":"[symbol_to_hsmtoken:126] data_ws","message":"HTTPSConnectionPool(host='api-t1.fyers.in', port=443): Max retries exceeded with url: /data/symbol-token (Caused by NewConnectionError('<urllib3.connection.HTTPSConnection object at 0x000001EE1E2E2390>: Failed to establish a new connection: [Errno 11001] getaddrinfo failed'))","timestamp":"2025-10-12 13:15:30,268+0530","service":"FyersDataSocket","exception":"Traceback (most recent call last):\n  File \"E:\\paper\\paper\\venv\\Lib\\site-packages\\websocket\\_http.py\", line 155, in _get_addrinfo_list\n    addrinfo_list = socket.getaddrinfo(\n                    ^^^^^^^^^^^^^^^^^^^\n  File \"C:\\Users\\hp\\AppData\\Local\\Programs\\Python\\Python312\\Lib\\socket.py\", line 963, in getaddrinfo\n    for res in _socket.getaddrinfo(host, port, family, type, proto, flags):\n               ^^^^^^^^^^^^^^^^^^^^^^^^^^^^^^^^^^^^^^^^^^^^^^^^^^^^^^^^^^^\nsocket.gaierror: [Errno 11001] getaddrinfo failed\n\nDuring handling of the above exception, another exception occurred:\n\nTraceback (most recent call last):\n  File \"E:\\paper\\paper\\venv\\Lib\\site-packages\\websocket\\_app.py\", line 412, in setSock\n    self.sock.connect(\n  File \"E:\\paper\\paper\\venv\\Lib\\site-packages\\websocket\\_core.py\", line 249, in connect\n    self.sock, addrs = connect(url, self.sock_opt, proxy_info(**options),\n                       ^^^^^^^^^^^^^^^^^^^^^^^^^^^^^^^^^^^^^^^^^^^^^^^^^^\n  File \"E:\\paper\\paper\\venv\\Lib\\site-packages\\websocket\\_http.py\", line 122, in connect\n    addrinfo_list, need_tunnel, auth = _get_addrinfo_list(\n                                       ^^^^^^^^^^^^^^^^^^^\n  File \"E:\\paper\\paper\\venv\\Lib\\site-packages\\websocket\\_http.py\", line 167, in _get_addrinfo_list\n    raise WebSocketAddressException(e)\nwebsocket._exceptions.WebSocketAddressException: [Errno 11001] getaddrinfo failed\n\nDuring handling of the above exception, another exception occurred:\n\nTraceback (most recent call last):\n  File \"E:\\paper\\paper\\venv\\Lib\\site-packages\\urllib3\\connection.py\", line 174, in _new_conn\n    conn = connection.create_connection(\n           ^^^^^^^^^^^^^^^^^^^^^^^^^^^^^\n  File \"E:\\paper\\paper\\venv\\Lib\\site-packages\\urllib3\\util\\connection.py\", line 72, in create_connection\n    for res in socket.getaddrinfo(host, port, family, socket.SOCK_STREAM):\n               ^^^^^^^^^^^^^^^^^^^^^^^^^^^^^^^^^^^^^^^^^^^^^^^^^^^^^^^^^^\n  File \"C:\\Users\\hp\\AppData\\Local\\Programs\\Python\\Python312\\Lib\\socket.py\", line 963, in getaddrinfo\n    for res in _socket.getaddrinfo(host, port, family, type, proto, flags):\n               ^^^^^^^^^^^^^^^^^^^^^^^^^^^^^^^^^^^^^^^^^^^^^^^^^^^^^^^^^^^\nsocket.gaierror: [Errno 11001] getaddrinfo failed\n\nDuring handling of the above exception, another exception occurred:\n\nTraceback (most recent call last):\n  File \"E:\\paper\\paper\\venv\\Lib\\site-packages\\urllib3\\connectionpool.py\", line 716, in urlopen\n    httplib_response = self._make_request(\n                       ^^^^^^^^^^^^^^^^^^^\n  File \"E:\\paper\\paper\\venv\\Lib\\site-packages\\urllib3\\connectionpool.py\", line 404, in _make_request\n    self._validate_conn(conn)\n  File \"E:\\paper\\paper\\venv\\Lib\\site-packages\\urllib3\\connectionpool.py\", line 1061, in _validate_conn\n    conn.connect()\n  File \"E:\\paper\\paper\\venv\\Lib\\site-packages\\urllib3\\connection.py\", line 363, in connect\n    self.sock = conn = self._new_conn()\n                       ^^^^^^^^^^^^^^^^\n  File \"E:\\paper\\paper\\venv\\Lib\\site-packages\\urllib3\\connection.py\", line 186, in _new_conn\n    raise NewConnectionError(\nurllib3.exceptions.NewConnectionError: <urllib3.connection.HTTPSConnection object at 0x000001EE1E2E2390>: Failed to establish a new connection: [Errno 11001] getaddrinfo failed\n\nDuring handling of the above exception, another exception occurred:\n\nTraceback (most recent call last):\n  File \"E:\\paper\\paper\\venv\\Lib\\site-packages\\requests\\adapters.py\", line 486, in send\n    resp = conn.urlopen(\n           ^^^^^^^^^^^^^\n  File \"E:\\paper\\paper\\venv\\Lib\\site-packages\\urllib3\\connectionpool.py\", line 802, in urlopen\n    retries = retries.increment(\n              ^^^^^^^^^^^^^^^^^^\n  File \"E:\\paper\\paper\\venv\\Lib\\site-packages\\urllib3\\util\\retry.py\", line 594, in increment\n    raise MaxRetryError(_pool, url, error or ResponseError(cause))\nurllib3.exceptions.MaxRetryError: HTTPSConnectionPool(host='api-t1.fyers.in', port=443): Max retries exceeded with url: /data/symbol-token (Caused by NewConnectionError('<urllib3.connection.HTTPSConnection object at 0x000001EE1E2E2390>: Failed to establish a new connection: [Errno 11001] getaddrinfo failed'))\n\nDuring handling of the above exception, another exception occurred:\n\nTraceback (most recent call last):\n  File \"E:\\paper\\paper\\venv\\Lib\\site-packages\\fyers_apiv3\\FyersWebsocket\\data_ws.py\", line 63, in symbol_to_hsmtoken\n    response = requests.post(\n               ^^^^^^^^^^^^^^\n  File \"E:\\paper\\paper\\venv\\Lib\\site-packages\\requests\\api.py\", line 115, in post\n    return request(\"post\", url, data=data, json=json, **kwargs)\n           ^^^^^^^^^^^^^^^^^^^^^^^^^^^^^^^^^^^^^^^^^^^^^^^^^^^^\n  File \"E:\\paper\\paper\\venv\\Lib\\site-packages\\requests\\api.py\", line 59, in request\n    return session.request(method=method, url=url, **kwargs)\n           ^^^^^^^^^^^^^^^^^^^^^^^^^^^^^^^^^^^^^^^^^^^^^^^^^\n  File \"E:\\paper\\paper\\venv\\Lib\\site-packages\\requests\\sessions.py\", line 589, in request\n    resp = self.send(prep, **send_kwargs)\n           ^^^^^^^^^^^^^^^^^^^^^^^^^^^^^^\n  File \"E:\\paper\\paper\\venv\\Lib\\site-packages\\requests\\sessions.py\", line 703, in send\n    r = adapter.send(request, **kwargs)\n        ^^^^^^^^^^^^^^^^^^^^^^^^^^^^^^^\n  File \"E:\\paper\\paper\\venv\\Lib\\site-packages\\requests\\adapters.py\", line 519, in send\n    raise ConnectionError(e, request=request)\nrequests.exceptions.ConnectionError: HTTPSConnectionPool(host='api-t1.fyers.in', port=443): Max retries exceeded with url: /data/symbol-token (Caused by NewConnectionError('<urllib3.connection.HTTPSConnection object at 0x000001EE1E2E2390>: Failed to establish a new connection: [Errno 11001] getaddrinfo failed'))","exception_name":"ConnectionError"}
{"level":"ERROR","location":"[__symbol_conversion:1374] data_ws","message":"'NoneType' object is not subscriptable","timestamp":"2025-10-12 13:15:30,345+0530","service":"FyersDataSocket","exception":"Traceback (most recent call last):\n  File \"E:\\paper\\paper\\venv\\Lib\\site-packages\\websocket\\_http.py\", line 155, in _get_addrinfo_list\n    addrinfo_list = socket.getaddrinfo(\n                    ^^^^^^^^^^^^^^^^^^^\n  File \"C:\\Users\\hp\\AppData\\Local\\Programs\\Python\\Python312\\Lib\\socket.py\", line 963, in getaddrinfo\n    for res in _socket.getaddrinfo(host, port, family, type, proto, flags):\n               ^^^^^^^^^^^^^^^^^^^^^^^^^^^^^^^^^^^^^^^^^^^^^^^^^^^^^^^^^^^\nsocket.gaierror: [Errno 11001] getaddrinfo failed\n\nDuring handling of the above exception, another exception occurred:\n\nTraceback (most recent call last):\n  File \"E:\\paper\\paper\\venv\\Lib\\site-packages\\websocket\\_app.py\", line 412, in setSock\n    self.sock.connect(\n  File \"E:\\paper\\paper\\venv\\Lib\\site-packages\\websocket\\_core.py\", line 249, in connect\n    self.sock, addrs = connect(url, self.sock_opt, proxy_info(**options),\n                       ^^^^^^^^^^^^^^^^^^^^^^^^^^^^^^^^^^^^^^^^^^^^^^^^^^\n  File \"E:\\paper\\paper\\venv\\Lib\\site-packages\\websocket\\_http.py\", line 122, in connect\n    addrinfo_list, need_tunnel, auth = _get_addrinfo_list(\n                                       ^^^^^^^^^^^^^^^^^^^\n  File \"E:\\paper\\paper\\venv\\Lib\\site-packages\\websocket\\_http.py\", line 167, in _get_addrinfo_list\n    raise WebSocketAddressException(e)\nwebsocket._exceptions.WebSocketAddressException: [Errno 11001] getaddrinfo failed\n\nDuring handling of the above exception, another exception occurred:\n\nTraceback (most recent call last):\n  File \"E:\\paper\\paper\\venv\\Lib\\site-packages\\fyers_apiv3\\FyersWebsocket\\data_ws.py\", line 1333, in __symbol_conversion\n    if symbol_value[3] != \"\":\n       ~~~~~~~~~~~~^^^\nTypeError: 'NoneType' object is not subscriptable","exception_name":"TypeError"}
{"level":"ERROR","location":"[<lambda>:1663] data_ws","message":"[Errno 11001] getaddrinfo failed","timestamp":"2025-10-12 13:15:33,294+0530","service":"FyersDataSocket"}
{"level":"ERROR","location":"[symbol_to_hsmtoken:126] data_ws","message":"HTTPSConnectionPool(host='api-t1.fyers.in', port=443): Max retries exceeded with url: /data/symbol-token (Caused by NewConnectionError('<urllib3.connection.HTTPSConnection object at 0x000001EE1E2E12B0>: Failed to establish a new connection: [Errno 11001] getaddrinfo failed'))","timestamp":"2025-10-12 13:15:35,296+0530","service":"FyersDataSocket","exception":"Traceback (most recent call last):\n  File \"E:\\paper\\paper\\venv\\Lib\\site-packages\\websocket\\_http.py\", line 155, in _get_addrinfo_list\n    addrinfo_list = socket.getaddrinfo(\n                    ^^^^^^^^^^^^^^^^^^^\n  File \"C:\\Users\\hp\\AppData\\Local\\Programs\\Python\\Python312\\Lib\\socket.py\", line 963, in getaddrinfo\n    for res in _socket.getaddrinfo(host, port, family, type, proto, flags):\n               ^^^^^^^^^^^^^^^^^^^^^^^^^^^^^^^^^^^^^^^^^^^^^^^^^^^^^^^^^^^\nsocket.gaierror: [Errno 11001] getaddrinfo failed\n\nDuring handling of the above exception, another exception occurred:\n\nTraceback (most recent call last):\n  File \"E:\\paper\\paper\\venv\\Lib\\site-packages\\websocket\\_app.py\", line 412, in setSock\n    self.sock.connect(\n  File \"E:\\paper\\paper\\venv\\Lib\\site-packages\\websocket\\_core.py\", line 249, in connect\n    self.sock, addrs = connect(url, self.sock_opt, proxy_info(**options),\n                       ^^^^^^^^^^^^^^^^^^^^^^^^^^^^^^^^^^^^^^^^^^^^^^^^^^\n  File \"E:\\paper\\paper\\venv\\Lib\\site-packages\\websocket\\_http.py\", line 122, in connect\n    addrinfo_list, need_tunnel, auth = _get_addrinfo_list(\n                                       ^^^^^^^^^^^^^^^^^^^\n  File \"E:\\paper\\paper\\venv\\Lib\\site-packages\\websocket\\_http.py\", line 167, in _get_addrinfo_list\n    raise WebSocketAddressException(e)\nwebsocket._exceptions.WebSocketAddressException: [Errno 11001] getaddrinfo failed\n\nDuring handling of the above exception, another exception occurred:\n\nTraceback (most recent call last):\n  File \"E:\\paper\\paper\\venv\\Lib\\site-packages\\urllib3\\connection.py\", line 174, in _new_conn\n    conn = connection.create_connection(\n           ^^^^^^^^^^^^^^^^^^^^^^^^^^^^^\n  File \"E:\\paper\\paper\\venv\\Lib\\site-packages\\urllib3\\util\\connection.py\", line 72, in create_connection\n    for res in socket.getaddrinfo(host, port, family, socket.SOCK_STREAM):\n               ^^^^^^^^^^^^^^^^^^^^^^^^^^^^^^^^^^^^^^^^^^^^^^^^^^^^^^^^^^\n  File \"C:\\Users\\hp\\AppData\\Local\\Programs\\Python\\Python312\\Lib\\socket.py\", line 963, in getaddrinfo\n    for res in _socket.getaddrinfo(host, port, family, type, proto, flags):\n               ^^^^^^^^^^^^^^^^^^^^^^^^^^^^^^^^^^^^^^^^^^^^^^^^^^^^^^^^^^^\nsocket.gaierror: [Errno 11001] getaddrinfo failed\n\nDuring handling of the above exception, another exception occurred:\n\nTraceback (most recent call last):\n  File \"E:\\paper\\paper\\venv\\Lib\\site-packages\\urllib3\\connectionpool.py\", line 716, in urlopen\n    httplib_response = self._make_request(\n                       ^^^^^^^^^^^^^^^^^^^\n  File \"E:\\paper\\paper\\venv\\Lib\\site-packages\\urllib3\\connectionpool.py\", line 404, in _make_request\n    self._validate_conn(conn)\n  File \"E:\\paper\\paper\\venv\\Lib\\site-packages\\urllib3\\connectionpool.py\", line 1061, in _validate_conn\n    conn.connect()\n  File \"E:\\paper\\paper\\venv\\Lib\\site-packages\\urllib3\\connection.py\", line 363, in connect\n    self.sock = conn = self._new_conn()\n                       ^^^^^^^^^^^^^^^^\n  File \"E:\\paper\\paper\\venv\\Lib\\site-packages\\urllib3\\connection.py\", line 186, in _new_conn\n    raise NewConnectionError(\nurllib3.exceptions.NewConnectionError: <urllib3.connection.HTTPSConnection object at 0x000001EE1E2E12B0>: Failed to establish a new connection: [Errno 11001] getaddrinfo failed\n\nDuring handling of the above exception, another exception occurred:\n\nTraceback (most recent call last):\n  File \"E:\\paper\\paper\\venv\\Lib\\site-packages\\requests\\adapters.py\", line 486, in send\n    resp = conn.urlopen(\n           ^^^^^^^^^^^^^\n  File \"E:\\paper\\paper\\venv\\Lib\\site-packages\\urllib3\\connectionpool.py\", line 802, in urlopen\n    retries = retries.increment(\n              ^^^^^^^^^^^^^^^^^^\n  File \"E:\\paper\\paper\\venv\\Lib\\site-packages\\urllib3\\util\\retry.py\", line 594, in increment\n    raise MaxRetryError(_pool, url, error or ResponseError(cause))\nurllib3.exceptions.MaxRetryError: HTTPSConnectionPool(host='api-t1.fyers.in', port=443): Max retries exceeded with url: /data/symbol-token (Caused by NewConnectionError('<urllib3.connection.HTTPSConnection object at 0x000001EE1E2E12B0>: Failed to establish a new connection: [Errno 11001] getaddrinfo failed'))\n\nDuring handling of the above exception, another exception occurred:\n\nTraceback (most recent call last):\n  File \"E:\\paper\\paper\\venv\\Lib\\site-packages\\fyers_apiv3\\FyersWebsocket\\data_ws.py\", line 63, in symbol_to_hsmtoken\n    response = requests.post(\n               ^^^^^^^^^^^^^^\n  File \"E:\\paper\\paper\\venv\\Lib\\site-packages\\requests\\api.py\", line 115, in post\n    return request(\"post\", url, data=data, json=json, **kwargs)\n           ^^^^^^^^^^^^^^^^^^^^^^^^^^^^^^^^^^^^^^^^^^^^^^^^^^^^\n  File \"E:\\paper\\paper\\venv\\Lib\\site-packages\\requests\\api.py\", line 59, in request\n    return session.request(method=method, url=url, **kwargs)\n           ^^^^^^^^^^^^^^^^^^^^^^^^^^^^^^^^^^^^^^^^^^^^^^^^^\n  File \"E:\\paper\\paper\\venv\\Lib\\site-packages\\requests\\sessions.py\", line 589, in request\n    resp = self.send(prep, **send_kwargs)\n           ^^^^^^^^^^^^^^^^^^^^^^^^^^^^^^\n  File \"E:\\paper\\paper\\venv\\Lib\\site-packages\\requests\\sessions.py\", line 703, in send\n    r = adapter.send(request, **kwargs)\n        ^^^^^^^^^^^^^^^^^^^^^^^^^^^^^^^\n  File \"E:\\paper\\paper\\venv\\Lib\\site-packages\\requests\\adapters.py\", line 519, in send\n    raise ConnectionError(e, request=request)\nrequests.exceptions.ConnectionError: HTTPSConnectionPool(host='api-t1.fyers.in', port=443): Max retries exceeded with url: /data/symbol-token (Caused by NewConnectionError('<urllib3.connection.HTTPSConnection object at 0x000001EE1E2E12B0>: Failed to establish a new connection: [Errno 11001] getaddrinfo failed'))","exception_name":"ConnectionError"}
{"level":"ERROR","location":"[__symbol_conversion:1374] data_ws","message":"'NoneType' object is not subscriptable","timestamp":"2025-10-12 13:15:35,309+0530","service":"FyersDataSocket","exception":"Traceback (most recent call last):\n  File \"E:\\paper\\paper\\venv\\Lib\\site-packages\\websocket\\_http.py\", line 155, in _get_addrinfo_list\n    addrinfo_list = socket.getaddrinfo(\n                    ^^^^^^^^^^^^^^^^^^^\n  File \"C:\\Users\\hp\\AppData\\Local\\Programs\\Python\\Python312\\Lib\\socket.py\", line 963, in getaddrinfo\n    for res in _socket.getaddrinfo(host, port, family, type, proto, flags):\n               ^^^^^^^^^^^^^^^^^^^^^^^^^^^^^^^^^^^^^^^^^^^^^^^^^^^^^^^^^^^\nsocket.gaierror: [Errno 11001] getaddrinfo failed\n\nDuring handling of the above exception, another exception occurred:\n\nTraceback (most recent call last):\n  File \"E:\\paper\\paper\\venv\\Lib\\site-packages\\websocket\\_app.py\", line 412, in setSock\n    self.sock.connect(\n  File \"E:\\paper\\paper\\venv\\Lib\\site-packages\\websocket\\_core.py\", line 249, in connect\n    self.sock, addrs = connect(url, self.sock_opt, proxy_info(**options),\n                       ^^^^^^^^^^^^^^^^^^^^^^^^^^^^^^^^^^^^^^^^^^^^^^^^^^\n  File \"E:\\paper\\paper\\venv\\Lib\\site-packages\\websocket\\_http.py\", line 122, in connect\n    addrinfo_list, need_tunnel, auth = _get_addrinfo_list(\n                                       ^^^^^^^^^^^^^^^^^^^\n  File \"E:\\paper\\paper\\venv\\Lib\\site-packages\\websocket\\_http.py\", line 167, in _get_addrinfo_list\n    raise WebSocketAddressException(e)\nwebsocket._exceptions.WebSocketAddressException: [Errno 11001] getaddrinfo failed\n\nDuring handling of the above exception, another exception occurred:\n\nTraceback (most recent call last):\n  File \"E:\\paper\\paper\\venv\\Lib\\site-packages\\fyers_apiv3\\FyersWebsocket\\data_ws.py\", line 1333, in __symbol_conversion\n    if symbol_value[3] != \"\":\n       ~~~~~~~~~~~~^^^\nTypeError: 'NoneType' object is not subscriptable","exception_name":"TypeError"}
{"level":"ERROR","location":"[<lambda>:1663] data_ws","message":"[Errno 11001] getaddrinfo failed","timestamp":"2025-10-12 13:15:38,299+0530","service":"FyersDataSocket"}
{"level":"ERROR","location":"[symbol_to_hsmtoken:126] data_ws","message":"HTTPSConnectionPool(host='api-t1.fyers.in', port=443): Max retries exceeded with url: /data/symbol-token (Caused by NewConnectionError('<urllib3.connection.HTTPSConnection object at 0x000001EE1E2E1670>: Failed to establish a new connection: [Errno 11001] getaddrinfo failed'))","timestamp":"2025-10-12 13:15:40,305+0530","service":"FyersDataSocket","exception":"Traceback (most recent call last):\n  File \"E:\\paper\\paper\\venv\\Lib\\site-packages\\websocket\\_http.py\", line 155, in _get_addrinfo_list\n    addrinfo_list = socket.getaddrinfo(\n                    ^^^^^^^^^^^^^^^^^^^\n  File \"C:\\Users\\hp\\AppData\\Local\\Programs\\Python\\Python312\\Lib\\socket.py\", line 963, in getaddrinfo\n    for res in _socket.getaddrinfo(host, port, family, type, proto, flags):\n               ^^^^^^^^^^^^^^^^^^^^^^^^^^^^^^^^^^^^^^^^^^^^^^^^^^^^^^^^^^^\nsocket.gaierror: [Errno 11001] getaddrinfo failed\n\nDuring handling of the above exception, another exception occurred:\n\nTraceback (most recent call last):\n  File \"E:\\paper\\paper\\venv\\Lib\\site-packages\\websocket\\_app.py\", line 412, in setSock\n    self.sock.connect(\n  File \"E:\\paper\\paper\\venv\\Lib\\site-packages\\websocket\\_core.py\", line 249, in connect\n    self.sock, addrs = connect(url, self.sock_opt, proxy_info(**options),\n                       ^^^^^^^^^^^^^^^^^^^^^^^^^^^^^^^^^^^^^^^^^^^^^^^^^^\n  File \"E:\\paper\\paper\\venv\\Lib\\site-packages\\websocket\\_http.py\", line 122, in connect\n    addrinfo_list, need_tunnel, auth = _get_addrinfo_list(\n                                       ^^^^^^^^^^^^^^^^^^^\n  File \"E:\\paper\\paper\\venv\\Lib\\site-packages\\websocket\\_http.py\", line 167, in _get_addrinfo_list\n    raise WebSocketAddressException(e)\nwebsocket._exceptions.WebSocketAddressException: [Errno 11001] getaddrinfo failed\n\nDuring handling of the above exception, another exception occurred:\n\nTraceback (most recent call last):\n  File \"E:\\paper\\paper\\venv\\Lib\\site-packages\\urllib3\\connection.py\", line 174, in _new_conn\n    conn = connection.create_connection(\n           ^^^^^^^^^^^^^^^^^^^^^^^^^^^^^\n  File \"E:\\paper\\paper\\venv\\Lib\\site-packages\\urllib3\\util\\connection.py\", line 72, in create_connection\n    for res in socket.getaddrinfo(host, port, family, socket.SOCK_STREAM):\n               ^^^^^^^^^^^^^^^^^^^^^^^^^^^^^^^^^^^^^^^^^^^^^^^^^^^^^^^^^^\n  File \"C:\\Users\\hp\\AppData\\Local\\Programs\\Python\\Python312\\Lib\\socket.py\", line 963, in getaddrinfo\n    for res in _socket.getaddrinfo(host, port, family, type, proto, flags):\n               ^^^^^^^^^^^^^^^^^^^^^^^^^^^^^^^^^^^^^^^^^^^^^^^^^^^^^^^^^^^\nsocket.gaierror: [Errno 11001] getaddrinfo failed\n\nDuring handling of the above exception, another exception occurred:\n\nTraceback (most recent call last):\n  File \"E:\\paper\\paper\\venv\\Lib\\site-packages\\urllib3\\connectionpool.py\", line 716, in urlopen\n    httplib_response = self._make_request(\n                       ^^^^^^^^^^^^^^^^^^^\n  File \"E:\\paper\\paper\\venv\\Lib\\site-packages\\urllib3\\connectionpool.py\", line 404, in _make_request\n    self._validate_conn(conn)\n  File \"E:\\paper\\paper\\venv\\Lib\\site-packages\\urllib3\\connectionpool.py\", line 1061, in _validate_conn\n    conn.connect()\n  File \"E:\\paper\\paper\\venv\\Lib\\site-packages\\urllib3\\connection.py\", line 363, in connect\n    self.sock = conn = self._new_conn()\n                       ^^^^^^^^^^^^^^^^\n  File \"E:\\paper\\paper\\venv\\Lib\\site-packages\\urllib3\\connection.py\", line 186, in _new_conn\n    raise NewConnectionError(\nurllib3.exceptions.NewConnectionError: <urllib3.connection.HTTPSConnection object at 0x000001EE1E2E1670>: Failed to establish a new connection: [Errno 11001] getaddrinfo failed\n\nDuring handling of the above exception, another exception occurred:\n\nTraceback (most recent call last):\n  File \"E:\\paper\\paper\\venv\\Lib\\site-packages\\requests\\adapters.py\", line 486, in send\n    resp = conn.urlopen(\n           ^^^^^^^^^^^^^\n  File \"E:\\paper\\paper\\venv\\Lib\\site-packages\\urllib3\\connectionpool.py\", line 802, in urlopen\n    retries = retries.increment(\n              ^^^^^^^^^^^^^^^^^^\n  File \"E:\\paper\\paper\\venv\\Lib\\site-packages\\urllib3\\util\\retry.py\", line 594, in increment\n    raise MaxRetryError(_pool, url, error or ResponseError(cause))\nurllib3.exceptions.MaxRetryError: HTTPSConnectionPool(host='api-t1.fyers.in', port=443): Max retries exceeded with url: /data/symbol-token (Caused by NewConnectionError('<urllib3.connection.HTTPSConnection object at 0x000001EE1E2E1670>: Failed to establish a new connection: [Errno 11001] getaddrinfo failed'))\n\nDuring handling of the above exception, another exception occurred:\n\nTraceback (most recent call last):\n  File \"E:\\paper\\paper\\venv\\Lib\\site-packages\\fyers_apiv3\\FyersWebsocket\\data_ws.py\", line 63, in symbol_to_hsmtoken\n    response = requests.post(\n               ^^^^^^^^^^^^^^\n  File \"E:\\paper\\paper\\venv\\Lib\\site-packages\\requests\\api.py\", line 115, in post\n    return request(\"post\", url, data=data, json=json, **kwargs)\n           ^^^^^^^^^^^^^^^^^^^^^^^^^^^^^^^^^^^^^^^^^^^^^^^^^^^^\n  File \"E:\\paper\\paper\\venv\\Lib\\site-packages\\requests\\api.py\", line 59, in request\n    return session.request(method=method, url=url, **kwargs)\n           ^^^^^^^^^^^^^^^^^^^^^^^^^^^^^^^^^^^^^^^^^^^^^^^^^\n  File \"E:\\paper\\paper\\venv\\Lib\\site-packages\\requests\\sessions.py\", line 589, in request\n    resp = self.send(prep, **send_kwargs)\n           ^^^^^^^^^^^^^^^^^^^^^^^^^^^^^^\n  File \"E:\\paper\\paper\\venv\\Lib\\site-packages\\requests\\sessions.py\", line 703, in send\n    r = adapter.send(request, **kwargs)\n        ^^^^^^^^^^^^^^^^^^^^^^^^^^^^^^^\n  File \"E:\\paper\\paper\\venv\\Lib\\site-packages\\requests\\adapters.py\", line 519, in send\n    raise ConnectionError(e, request=request)\nrequests.exceptions.ConnectionError: HTTPSConnectionPool(host='api-t1.fyers.in', port=443): Max retries exceeded with url: /data/symbol-token (Caused by NewConnectionError('<urllib3.connection.HTTPSConnection object at 0x000001EE1E2E1670>: Failed to establish a new connection: [Errno 11001] getaddrinfo failed'))","exception_name":"ConnectionError"}
{"level":"ERROR","location":"[__symbol_conversion:1374] data_ws","message":"'NoneType' object is not subscriptable","timestamp":"2025-10-12 13:15:40,315+0530","service":"FyersDataSocket","exception":"Traceback (most recent call last):\n  File \"E:\\paper\\paper\\venv\\Lib\\site-packages\\websocket\\_http.py\", line 155, in _get_addrinfo_list\n    addrinfo_list = socket.getaddrinfo(\n                    ^^^^^^^^^^^^^^^^^^^\n  File \"C:\\Users\\hp\\AppData\\Local\\Programs\\Python\\Python312\\Lib\\socket.py\", line 963, in getaddrinfo\n    for res in _socket.getaddrinfo(host, port, family, type, proto, flags):\n               ^^^^^^^^^^^^^^^^^^^^^^^^^^^^^^^^^^^^^^^^^^^^^^^^^^^^^^^^^^^\nsocket.gaierror: [Errno 11001] getaddrinfo failed\n\nDuring handling of the above exception, another exception occurred:\n\nTraceback (most recent call last):\n  File \"E:\\paper\\paper\\venv\\Lib\\site-packages\\websocket\\_app.py\", line 412, in setSock\n    self.sock.connect(\n  File \"E:\\paper\\paper\\venv\\Lib\\site-packages\\websocket\\_core.py\", line 249, in connect\n    self.sock, addrs = connect(url, self.sock_opt, proxy_info(**options),\n                       ^^^^^^^^^^^^^^^^^^^^^^^^^^^^^^^^^^^^^^^^^^^^^^^^^^\n  File \"E:\\paper\\paper\\venv\\Lib\\site-packages\\websocket\\_http.py\", line 122, in connect\n    addrinfo_list, need_tunnel, auth = _get_addrinfo_list(\n                                       ^^^^^^^^^^^^^^^^^^^\n  File \"E:\\paper\\paper\\venv\\Lib\\site-packages\\websocket\\_http.py\", line 167, in _get_addrinfo_list\n    raise WebSocketAddressException(e)\nwebsocket._exceptions.WebSocketAddressException: [Errno 11001] getaddrinfo failed\n\nDuring handling of the above exception, another exception occurred:\n\nTraceback (most recent call last):\n  File \"E:\\paper\\paper\\venv\\Lib\\site-packages\\fyers_apiv3\\FyersWebsocket\\data_ws.py\", line 1333, in __symbol_conversion\n    if symbol_value[3] != \"\":\n       ~~~~~~~~~~~~^^^\nTypeError: 'NoneType' object is not subscriptable","exception_name":"TypeError"}
{"level":"ERROR","location":"[<lambda>:1663] data_ws","message":"[Errno 11001] getaddrinfo failed","timestamp":"2025-10-12 13:15:43,326+0530","service":"FyersDataSocket"}
{"level":"ERROR","location":"[symbol_to_hsmtoken:126] data_ws","message":"HTTPSConnectionPool(host='api-t1.fyers.in', port=443): Max retries exceeded with url: /data/symbol-token (Caused by NewConnectionError('<urllib3.connection.HTTPSConnection object at 0x000001EE1E2E3800>: Failed to establish a new connection: [Errno 11001] getaddrinfo failed'))","timestamp":"2025-10-12 13:15:45,371+0530","service":"FyersDataSocket","exception":"Traceback (most recent call last):\n  File \"E:\\paper\\paper\\venv\\Lib\\site-packages\\websocket\\_http.py\", line 155, in _get_addrinfo_list\n    addrinfo_list = socket.getaddrinfo(\n                    ^^^^^^^^^^^^^^^^^^^\n  File \"C:\\Users\\hp\\AppData\\Local\\Programs\\Python\\Python312\\Lib\\socket.py\", line 963, in getaddrinfo\n    for res in _socket.getaddrinfo(host, port, family, type, proto, flags):\n               ^^^^^^^^^^^^^^^^^^^^^^^^^^^^^^^^^^^^^^^^^^^^^^^^^^^^^^^^^^^\nsocket.gaierror: [Errno 11001] getaddrinfo failed\n\nDuring handling of the above exception, another exception occurred:\n\nTraceback (most recent call last):\n  File \"E:\\paper\\paper\\venv\\Lib\\site-packages\\websocket\\_app.py\", line 412, in setSock\n    self.sock.connect(\n  File \"E:\\paper\\paper\\venv\\Lib\\site-packages\\websocket\\_core.py\", line 249, in connect\n    self.sock, addrs = connect(url, self.sock_opt, proxy_info(**options),\n                       ^^^^^^^^^^^^^^^^^^^^^^^^^^^^^^^^^^^^^^^^^^^^^^^^^^\n  File \"E:\\paper\\paper\\venv\\Lib\\site-packages\\websocket\\_http.py\", line 122, in connect\n    addrinfo_list, need_tunnel, auth = _get_addrinfo_list(\n                                       ^^^^^^^^^^^^^^^^^^^\n  File \"E:\\paper\\paper\\venv\\Lib\\site-packages\\websocket\\_http.py\", line 167, in _get_addrinfo_list\n    raise WebSocketAddressException(e)\nwebsocket._exceptions.WebSocketAddressException: [Errno 11001] getaddrinfo failed\n\nDuring handling of the above exception, another exception occurred:\n\nTraceback (most recent call last):\n  File \"E:\\paper\\paper\\venv\\Lib\\site-packages\\urllib3\\connection.py\", line 174, in _new_conn\n    conn = connection.create_connection(\n           ^^^^^^^^^^^^^^^^^^^^^^^^^^^^^\n  File \"E:\\paper\\paper\\venv\\Lib\\site-packages\\urllib3\\util\\connection.py\", line 72, in create_connection\n    for res in socket.getaddrinfo(host, port, family, socket.SOCK_STREAM):\n               ^^^^^^^^^^^^^^^^^^^^^^^^^^^^^^^^^^^^^^^^^^^^^^^^^^^^^^^^^^\n  File \"C:\\Users\\hp\\AppData\\Local\\Programs\\Python\\Python312\\Lib\\socket.py\", line 963, in getaddrinfo\n    for res in _socket.getaddrinfo(host, port, family, type, proto, flags):\n               ^^^^^^^^^^^^^^^^^^^^^^^^^^^^^^^^^^^^^^^^^^^^^^^^^^^^^^^^^^^\nsocket.gaierror: [Errno 11001] getaddrinfo failed\n\nDuring handling of the above exception, another exception occurred:\n\nTraceback (most recent call last):\n  File \"E:\\paper\\paper\\venv\\Lib\\site-packages\\urllib3\\connectionpool.py\", line 716, in urlopen\n    httplib_response = self._make_request(\n                       ^^^^^^^^^^^^^^^^^^^\n  File \"E:\\paper\\paper\\venv\\Lib\\site-packages\\urllib3\\connectionpool.py\", line 404, in _make_request\n    self._validate_conn(conn)\n  File \"E:\\paper\\paper\\venv\\Lib\\site-packages\\urllib3\\connectionpool.py\", line 1061, in _validate_conn\n    conn.connect()\n  File \"E:\\paper\\paper\\venv\\Lib\\site-packages\\urllib3\\connection.py\", line 363, in connect\n    self.sock = conn = self._new_conn()\n                       ^^^^^^^^^^^^^^^^\n  File \"E:\\paper\\paper\\venv\\Lib\\site-packages\\urllib3\\connection.py\", line 186, in _new_conn\n    raise NewConnectionError(\nurllib3.exceptions.NewConnectionError: <urllib3.connection.HTTPSConnection object at 0x000001EE1E2E3800>: Failed to establish a new connection: [Errno 11001] getaddrinfo failed\n\nDuring handling of the above exception, another exception occurred:\n\nTraceback (most recent call last):\n  File \"E:\\paper\\paper\\venv\\Lib\\site-packages\\requests\\adapters.py\", line 486, in send\n    resp = conn.urlopen(\n           ^^^^^^^^^^^^^\n  File \"E:\\paper\\paper\\venv\\Lib\\site-packages\\urllib3\\connectionpool.py\", line 802, in urlopen\n    retries = retries.increment(\n              ^^^^^^^^^^^^^^^^^^\n  File \"E:\\paper\\paper\\venv\\Lib\\site-packages\\urllib3\\util\\retry.py\", line 594, in increment\n    raise MaxRetryError(_pool, url, error or ResponseError(cause))\nurllib3.exceptions.MaxRetryError: HTTPSConnectionPool(host='api-t1.fyers.in', port=443): Max retries exceeded with url: /data/symbol-token (Caused by NewConnectionError('<urllib3.connection.HTTPSConnection object at 0x000001EE1E2E3800>: Failed to establish a new connection: [Errno 11001] getaddrinfo failed'))\n\nDuring handling of the above exception, another exception occurred:\n\nTraceback (most recent call last):\n  File \"E:\\paper\\paper\\venv\\Lib\\site-packages\\fyers_apiv3\\FyersWebsocket\\data_ws.py\", line 63, in symbol_to_hsmtoken\n    response = requests.post(\n               ^^^^^^^^^^^^^^\n  File \"E:\\paper\\paper\\venv\\Lib\\site-packages\\requests\\api.py\", line 115, in post\n    return request(\"post\", url, data=data, json=json, **kwargs)\n           ^^^^^^^^^^^^^^^^^^^^^^^^^^^^^^^^^^^^^^^^^^^^^^^^^^^^\n  File \"E:\\paper\\paper\\venv\\Lib\\site-packages\\requests\\api.py\", line 59, in request\n    return session.request(method=method, url=url, **kwargs)\n           ^^^^^^^^^^^^^^^^^^^^^^^^^^^^^^^^^^^^^^^^^^^^^^^^^\n  File \"E:\\paper\\paper\\venv\\Lib\\site-packages\\requests\\sessions.py\", line 589, in request\n    resp = self.send(prep, **send_kwargs)\n           ^^^^^^^^^^^^^^^^^^^^^^^^^^^^^^\n  File \"E:\\paper\\paper\\venv\\Lib\\site-packages\\requests\\sessions.py\", line 703, in send\n    r = adapter.send(request, **kwargs)\n        ^^^^^^^^^^^^^^^^^^^^^^^^^^^^^^^\n  File \"E:\\paper\\paper\\venv\\Lib\\site-packages\\requests\\adapters.py\", line 519, in send\n    raise ConnectionError(e, request=request)\nrequests.exceptions.ConnectionError: HTTPSConnectionPool(host='api-t1.fyers.in', port=443): Max retries exceeded with url: /data/symbol-token (Caused by NewConnectionError('<urllib3.connection.HTTPSConnection object at 0x000001EE1E2E3800>: Failed to establish a new connection: [Errno 11001] getaddrinfo failed'))","exception_name":"ConnectionError"}
{"level":"ERROR","location":"[__symbol_conversion:1374] data_ws","message":"'NoneType' object is not subscriptable","timestamp":"2025-10-12 13:15:45,430+0530","service":"FyersDataSocket","exception":"Traceback (most recent call last):\n  File \"E:\\paper\\paper\\venv\\Lib\\site-packages\\websocket\\_http.py\", line 155, in _get_addrinfo_list\n    addrinfo_list = socket.getaddrinfo(\n                    ^^^^^^^^^^^^^^^^^^^\n  File \"C:\\Users\\hp\\AppData\\Local\\Programs\\Python\\Python312\\Lib\\socket.py\", line 963, in getaddrinfo\n    for res in _socket.getaddrinfo(host, port, family, type, proto, flags):\n               ^^^^^^^^^^^^^^^^^^^^^^^^^^^^^^^^^^^^^^^^^^^^^^^^^^^^^^^^^^^\nsocket.gaierror: [Errno 11001] getaddrinfo failed\n\nDuring handling of the above exception, another exception occurred:\n\nTraceback (most recent call last):\n  File \"E:\\paper\\paper\\venv\\Lib\\site-packages\\websocket\\_app.py\", line 412, in setSock\n    self.sock.connect(\n  File \"E:\\paper\\paper\\venv\\Lib\\site-packages\\websocket\\_core.py\", line 249, in connect\n    self.sock, addrs = connect(url, self.sock_opt, proxy_info(**options),\n                       ^^^^^^^^^^^^^^^^^^^^^^^^^^^^^^^^^^^^^^^^^^^^^^^^^^\n  File \"E:\\paper\\paper\\venv\\Lib\\site-packages\\websocket\\_http.py\", line 122, in connect\n    addrinfo_list, need_tunnel, auth = _get_addrinfo_list(\n                                       ^^^^^^^^^^^^^^^^^^^\n  File \"E:\\paper\\paper\\venv\\Lib\\site-packages\\websocket\\_http.py\", line 167, in _get_addrinfo_list\n    raise WebSocketAddressException(e)\nwebsocket._exceptions.WebSocketAddressException: [Errno 11001] getaddrinfo failed\n\nDuring handling of the above exception, another exception occurred:\n\nTraceback (most recent call last):\n  File \"E:\\paper\\paper\\venv\\Lib\\site-packages\\fyers_apiv3\\FyersWebsocket\\data_ws.py\", line 1333, in __symbol_conversion\n    if symbol_value[3] != \"\":\n       ~~~~~~~~~~~~^^^\nTypeError: 'NoneType' object is not subscriptable","exception_name":"TypeError"}
